Workbook

Sheet Bank_Cover
B2: BIN AMER REAL ESTATE SPV — Senior Debt Financing Memorandum
B3: Prepared for: Senior Lender Underwriting Committee
B4: Status: For bank review
B6: EXECUTIVE SUMMARY
B7: Bin Amer Holding seeks senior secured financing for the acquisition of a stabilised income real-estate asset in the Kingdom of Saudi Arabia. The proposed structure is 50% LTV / 50% sponsor equity, 10-year tenor, amortising on a 25-year profile with a balloon at maturity (or refinanced at Y5 / Y7). Sources & Uses tie at closing including funded reserve stack (DSRA, OpEx, CapEx, contingency). The base-case underwriting clears DSCR, LLCR, debt-yield and LTV covenants. The Downside scenario maintains DSCR above 1.20x and remains NPV-positive at Project level.
B9: DEAL TERMS (proposed)
B10: ="Senior debt amount: " & TEXT(Assumptions!$D$47,"#,##0")&" SAR"
B11: ="LTV / LTC: " & TEXT(Assumptions!$D$47/Assumptions!$D$11,"0.0%")&" / "&TEXT(Assumptions!$D$47/Sources_Uses!$C$15,"0.0%")
B12: ="Cost of debt: " & TEXT(Assumptions!$D$42,"0.00%")&" (SAIBOR + 175bps blended)"
B13: ="Tenor: " & TEXT(Assumptions!$D$45,"0")&" years"
B14: ="Amortisation: " & IF(Assumptions!$D$44=1,"Yes (25-yr profile, balloon at maturity)","Bullet at maturity — refinance commitment required")
B15: ="DSRA: " & TEXT(Assumptions!$D$89,"0")&" months of debt service"
B16: ="Min DSCR covenant: " & TEXT(Assumptions!$D$73,"0.00\x")
B17: ="Cash sweep: " & "Trigger: DSCR < 1.45x ; sweep 100% excess CF to debt"
B18: ="LLCR test: " & "≥ 1.40x annually"
B19: ="Recourse: " & "Limited to completion + 24-mo debt service guarantee"
B20: ="Reporting: " & "Quarterly compliance certificate + audited financials"
B23: KEY RISKS AND MITIGANTS
B24: • Refinancing risk at maturity — Sponsor pre-arrangement of refinance; LLCR ≥ 1.40x; conservative exit cap.
B25: • Cap-rate expansion at exit — Stress test at +150bps cap (8.5% → 10%); remains positive in Severe.
B26: • Interest-rate exposure — Rate-cap hedge required on ≥ 50% of debt for first 5 years.
B27: • Concentration / single-asset — Cross-collateralisation with sponsor's broader portfolio.
B28: • Tenant credit / lease roll — Lease roll schedule (Asset_Profile sheet); weighted average lease term.
B29: • Saudi tax regime (Zakat, WHT) — Big-4 opinion at closing; 70% property shelter applied.
B30: • Operational underperformance — Operating reserve (3mo OpEx); cap-ex reserve (12mo CapEx).
B31: • Sponsor liquidity — Sponsor recourse for first 24 months DS; clean balance-sheet test.
B34: MODEL SECTIONS REFERENCED
B35: → Sources_Uses — closing day capital stack tie-out
B36: → Bank_Underwrite — single-page credit memo & DSCR/LLCR/DY trajectory
... B43: → Audit — model integrity checks (must be all OK or REVIEW)

Sheet Bank_Underwrite
B2: BANK UNDERWRITING SUMMARY — Bin Amer Real Estate SPV
B3: Single-page credit memo for senior lender review.
B5: DEAL SUMMARY
B6: Sponsor | C6: =Assumptions!$D$120
B7: Borrower (SPV) | C7: =Assumptions!$D$121
B8: Asset class | C8: =Assumptions!$D$122
B9: Geography | C9: =Assumptions!$D$123
B10: Acquisition price (SAR) | C10: =Assumptions!$D$11
B11: Total project cost (SAR) | C11: =Assumptions!$D$16
B12: Senior debt (SAR) | C12: =Assumptions!$D$47
B13: Sponsor equity (SAR) | C13: =Assumptions!$D$48
B14: Holding period | C14: =Assumptions!$D$7
B15: Closing year | C15: =Assumptions!$D$6
B16: Exit year | C16: =Assumptions!$D$8
B19: TRAJECTORY (operating years Y1–Y10)
B20: Metric | C20: Y1 | D20: Y2 | E20: Y3 | F20: Y4 | G20: Y5 | H20: Y6 | I20: Y7 | J20: Y8 | K20: Y9 | L20: Y10
B21: NOI (SAR M) | C21: =OpEx_CapEx!E9/1000000 | D21: =OpEx_CapEx!F9/1000000 | E21: =OpEx_CapEx!G9/1000000 | F21: =OpEx_CapEx!H9/1000000 | G21: =OpEx_CapEx!I9/1000000 | H21: =OpEx_CapEx!J9/1000000 | I21: =OpEx_CapEx!K9/1000000 | J21: =OpEx_CapEx!L9/1000000 | ... L21: =OpEx_CapEx!N9/1000000
B22: CFADS (SAR M) | C22: =Lender_Metrics!E6/1000000 | D22: =Lender_Metrics!F6/1000000 | E22: =Lender_Metrics!G6/1000000 | F22: =Lender_Metrics!H6/1000000 | G22: =Lender_Metrics!I6/1000000 | H22: =Lender_Metrics!J6/1000000 | I22: =Lender_Metrics!K6/1000000 | J22: =Lender_Metrics!L6/1000000 | ... L22: =Lender_Metrics!N6/1000000
B23: Debt service (SAR M) | C23: =Lender_Metrics!E7/1000000 | D23: =Lender_Metrics!F7/1000000 | E23: =Lender_Metrics!G7/1000000 | F23: =Lender_Metrics!H7/1000000 | G23: =Lender_Metrics!I7/1000000 | H23: =Lender_Metrics!J7/1000000 | I23: =Lender_Metrics!K7/1000000 | J23: =Lender_Metrics!L7/1000000 | ... L23: =Lender_Metrics!N7/1000000
B24: DSCR (x) | C24: =Lender_Metrics!E8 | D24: =Lender_Metrics!F8 | E24: =Lender_Metrics!G8 | F24: =Lender_Metrics!H8 | G24: =Lender_Metrics!I8 | H24: =Lender_Metrics!J8 | I24: =Lender_Metrics!K8 | J24: =Lender_Metrics!L8 | ... L24: =Lender_Metrics!N8
B25: Debt outstanding (SAR M) | C25: =Debt!E9/1000000 | D25: =Debt!F9/1000000 | E25: =Debt!G9/1000000 | F25: =Debt!H9/1000000 | G25: =Debt!I9/1000000 | H25: =Debt!J9/1000000 | I25: =Debt!K9/1000000 | J25: =Debt!L9/1000000 | ... L25: =Debt!N9/1000000
B26: LTV (vs market value at Y_t) | C26: =IFERROR(Debt!E9/(OpEx_CapEx!E9/(Assumptions!$D$51+0.01)),0) | D26: =IFERROR(Debt!F9/(OpEx_CapEx!F9/(Assumptions!$D$51+0.01)),0) | E26: =IFERROR(Debt!G9/(OpEx_CapEx!G9/(Assumptions!$D$51+0.01)),0) | F26: =IFERROR(Debt!H9/(OpEx_CapEx!H9/(Assumptions!$D$51+0.01)),0) | G26: =IFERROR(Debt!I9/(OpEx_CapEx!I9/(Assumptions!$D$51+0.01)),0) | H26: =IFERROR(Debt!J9/(OpEx_CapEx!J9/(Assumptions!$D$51+0.01)),0) | I26: =IFERROR(Debt!K9/(OpEx_CapEx!K9/(Assumptions!$D$51+0.01)),0) | J26: =IFERROR(Debt!L9/(OpEx_CapEx!L9/(Assumptions!$D$51+0.01)),0) | ... L26: =IFERROR(Debt!N9/(OpEx_CapEx!N9/(Assumptions!$D$51+0.01)),0)
B27: Debt yield (NOI / Debt) | C27: =Lender_Metrics!E13 | D27: =Lender_Metrics!F13 | E27: =Lender_Metrics!G13 | F27: =Lender_Metrics!H13 | G27: =Lender_Metrics!I13 | H27: =Lender_Metrics!J13 | I27: =Lender_Metrics!K13 | J27: =Lender_Metrics!L13 | ... L27: =Lender_Metrics!N13
B28: LLCR (x) | C28: =IFERROR(Lender_Metrics!E10,0) | D28: =IFERROR(Lender_Metrics!F10,0) | E28: =IFERROR(Lender_Metrics!G10,0) | F28: =IFERROR(Lender_Metrics!H10,0) | G28: =IFERROR(Lender_Metrics!I10,0) | H28: =IFERROR(Lender_Metrics!J10,0) | I28: =IFERROR(Lender_Metrics!K10,0) | J28: =IFERROR(Lender_Metrics!L10,0) | ... L28: =IFERROR(Lender_Metrics!N10,0)
B29: PLCR (x) | C29: =IFERROR(Lender_Metrics!E11,0) | D29: =IFERROR(Lender_Metrics!F11,0) | E29: =IFERROR(Lender_Metrics!G11,0) | F29: =IFERROR(Lender_Metrics!H11,0) | G29: =IFERROR(Lender_Metrics!I11,0) | H29: =IFERROR(Lender_Metrics!J11,0) | I29: =IFERROR(Lender_Metrics!K11,0) | J29: =IFERROR(Lender_Metrics!L11,0) | ... L29: =IFERROR(Lender_Metrics!N11,0)
B30: Break-even occupancy | C30: =IFERROR(Lender_Metrics!E14,0) | D30: =IFERROR(Lender_Metrics!F14,0) | E30: =IFERROR(Lender_Metrics!G14,0) | F30: =IFERROR(Lender_Metrics!H14,0) | G30: =IFERROR(Lender_Metrics!I14,0) | H30: =IFERROR(Lender_Metrics!J14,0) | I30: =IFERROR(Lender_Metrics!K14,0) | J30: =IFERROR(Lender_Metrics!L14,0) | ... L30: =IFERROR(Lender_Metrics!N14,0)
B33: HEADLINE CREDIT METRICS
B34: Metric | C34: Value | D34: Threshold
B35: Min DSCR (excl. bullet year) | C35: =Lender_Metrics!$D$20 | D35: ≥ 1.35x
B36: Avg DSCR (excl. bullet year) | C36: =Lender_Metrics!$D$19
B37: Min LLCR | C37: =Lender_Metrics!$D$21 | D37: ≥ 1.40x
B38: Min debt yield | C38: =Lender_Metrics!$D$22 | D38: ≥ Assumptions!$D$75
B39: Max break-even occupancy | C39: =Lender_Metrics!$D$23
B40: Initial LTV | C40: =Assumptions!$D$47/Assumptions!$D$11 | D40: ≤ Assumptions!$D$74
B41: Initial LTC | C41: =Assumptions!$D$47/Sources_Uses!$C$15 | D41: ≤ 65%
B42: Bankability score | C42: =Lender_Metrics!$D$24
B45: LENDER RECOMMENDATION
B46: =IF(AND(Lender_Metrics!$D$20>=Assumptions!$D$73,Lender_Metrics!$D$21>=1.4,Assumptions!$D$47/Assumptions!$D$11<=Assumptions!$D$74,Audit!$D$36=0),"APPROVE — meets all bank gates",IF(Lender_Metrics!$D$24="BANKABLE","CONDITIONAL APPROVAL — see term sheet conditions","REJECT — covenant breaches, restructure required"))

Sheet IC_Memo
B2: INVESTMENT COMMITTEE MEMO — Bin Amer Holding Investment Underwriting v5
B3: Date: as of issuance | Reviewer: Independent Institutional Underwriting
B5: 1. EXECUTIVE RECOMMENDATION
B6: REJECT (deal as-presented) — RESTRUCTURE REQUIRED to reach institutional bankability.
B7: The proposed transaction does not clear any of the four institutional gates: Project IRR < WACC (5.11% vs 8.50%); Equity IRR < hurdle (0.31% vs 10%); NPV negative at both project and equity levels (-SAR 47M / -SAR 61M); MOIC 1.03x vs 1.75x target. Six of sixteen audit checks fail. Deal is not financeable as structured.
B9: 2. KEY RED FLAGS
B10: (a) Negative spread between project IRR and WACC of -339 bps: the asset is being acquired ABOVE its risk-adjusted intrinsic value. Either renegotiate price or improve operations — the cap-rate gap cannot be closed by leverage alone.
B11: (b) Negative spread between equity IRR and hurdle of -969 bps: equity is destroying value vs the 10% hurdle. After zakat and WHT, equity returns approach zero. Levered IRR < unlevered IRR is a structural sign of overpriced debt or excessive non-deductible taxes.
B12: (c) Bullet repayment at maturity creates exit-year DSCR of 0.13x with no refinance plan modelled. This is unbankable: lenders will not underwrite a non-amortizing structure without a binding take-out.
B13: (d) Zakat charge in v4 is SAR 2.69M flat every year (2.5% × initial equity), absorbing ~22% of EBITDA. Under KSA practice the Zakat base for a property-holding SPV is largely sheltered by net book value; v5 applies an 80% shelter haircut (subject to Big-4 confirmation), which materially improves equity IRR.
B14: (e) Exit cap of 7.50% vs entry cap of 6.77% bakes in 75 bps of cap expansion over 10 years — plausible but compounds with low income growth (1.5% effective). The deal relies on terminal value: removing the exit value drops NPV by SAR 87M.
B15: (f) No reserve accounts (DSRA, OpEx, CapEx, contingency) — first cash shortfall or capex surprise forces an equity call.
... B54: All assumptions require third-party validation: market valuer, Big-4 tax (Zakat & WHT), legal counsel (KSA RETT, structure), and lender term sheet before financing close.

Sheet Dashboard
B2: EXECUTIVE DASHBOARD — Bin Amer Holding Investment Committee
B4: CREDIT METRICS
B5: Closing year (Y0) | D5: =Assumptions!$D$6
B6: Exit year (Y_exit) | D6: =Assumptions!$D$8
B7: Holding period | D7: =Assumptions!$D$7
B8: Asset purchase price | D8: =Assumptions!$D$11
B9: Total project cost | D9: =Assumptions!$D$16
B10: Equity required | D10: =Assumptions!$D$48
B11: Debt required | D11: =Assumptions!$D$47
B12: Initial LTV | D12: =Assumptions!$D$47/Assumptions!$D$16
B14: RETURN METRICS
B15: Project IRR (unlevered) | D15: =Returns!D5
B16: Equity IRR (levered, post-tax) | D16: =Returns!D6
B17: WACC | D17: =Assumptions!$D$68
B18: Hurdle rate | D18: =Assumptions!$D$71
B19: NPV @ WACC (Project) | D19: =DCF!D17
B20: NPV @ Ke (Equity) | D20: =DCF!D25
B21: MOIC | D21: =Returns!D17
B22: Payback period | D22: =Returns!D19
B23: Cash-on-Cash (Y1) | D23: =Returns!D22
B24: Yield on cost (Y1) | D24: =Returns!D23
B26: CREDIT METRICS
B27: Min DSCR over life | D27: =Returns!D28
B28: Avg DSCR | D28: =Returns!D29
B29: Avg Debt Yield | D29: =Returns!D30
B30: Min Interest Coverage | D30: =Returns!D31
B31: Min DSCR threshold | D31: =Assumptions!$D$73
B32: Initial LTV vs Max LTV | D32: =Returns!D27 & " / " & TEXT(Assumptions!$D$74,"0.0%")
B34: AUDIT STATUS
B35: Number of audit checks passed | D35: =COUNTIF(Audit!E6:E25,"OK")
B36: Number of audit checks failed | D36: =COUNTIF(Audit!E6:E25,"ERROR")
B37: Checks requiring review | D37: =COUNTIF(Audit!E6:E25,"REVIEW")
B39: INVESTMENT COMMITTEE RECOMMENDATION
B40: Decision logic: Equity IRR ≥ Hurdle, NPV(Project) > 0, Min DSCR ≥ threshold, LTV ≤ Max, Audit clean
B41: RECOMMENDATION | D41: =IF(AND(Returns!D6>=Assumptions!$D$71,DCF!D17>0,Audit!E14="OK",Audit!E18="OK"),"PROCEED (base case meets all gates)",IF(D54="PASS","CONDITIONAL — Adopt Restructured Deal Terms (see Restructured_Deal sheet)","REJECT — Base case fails; Restructured Deal does not meet thresholds"))
B43: KEY DEAL DRIVERS (interpret with caution)
B44: • Outcome is most sensitive to: exit cap rate, Y1 vacancy, OpEx, cost of debt.
B45: • DSCR collapses at exit year if bullet repayment + interest exceed NOI — check Debt!N16.
B46: • Zakat & withholding tax reduce equity IRR by ~30–80 bps depending on structure.
B47: • Forward NOI used in exit value reflects 1-period escalation — verify with broker comps.
...

Sheet Sources_Uses
B2: SOURCES & USES OF FUNDS — closing day (Y0)
B3: All values in SAR. Tie-out must net to zero (sources = uses).
B5: USES | C5: SAR | D5: % of cost
B6: Asset purchase price | C6: =Assumptions!$D$11 | D6: =C6/$C$15
B7: RETT (Real Estate Transaction Tax) | C7: =Assumptions!$D$11*Assumptions!$D$12 | D7: =C7/$C$15
B8: Acquisition broker / agency | C8: =Assumptions!$D$11*Assumptions!$D$13 | D8: =C8/$C$15
B9: Acquisition / DD / legal fees | C9: =Assumptions!$D$11*Assumptions!$D$14 | D9: =C9/$C$15
B10: Debt arrangement fee | C10: =-Debt!$D$11 | D10: =C10/$C$15
B11: DSRA funded at closing | C11: =Reserves!$D$7 | D11: =C11/$C$15
B12: Operating reserve funded at closing | C12: =Reserves!$D$10 | D12: =C12/$C$15
B13: CapEx reserve funded at closing | C13: =Reserves!$D$12 | D13: =C13/$C$15
B14: Contingency reserve funded at closing | C14: =Reserves!$D$13 | D14: =C14/$C$15
B15: TOTAL USES | C15: =SUM(C6:C14)
B18: SOURCES | C18: SAR | D18: % of total
B19: Senior debt — initial draw | C19: =Assumptions!$D$47 | D19: =C19/$C$21
B20: Sponsor equity | C20: =C15-C19 | D20: =C20/$C$21
B21: TOTAL SOURCES | C21: =SUM(C19:C20)
B23: Sources − Uses (must equal 0) | C23: =C21-C15 | D23: =IF(ABS(C23)<10,"BALANCED","REVIEW")
B26: CAPITAL STACK SUMMARY
B27: Loan-to-Value (LTV) | C27: =Assumptions!$D$47/Assumptions!$D$11
B28: Loan-to-Cost (LTC) | C28: =Assumptions!$D$47/C15
B29: Senior debt / Equity (D/E) | C29: =Assumptions!$D$47/(C15-Assumptions!$D$47)
B30: Implied entry yield (Y1 NOI / price) | C30: =OpEx_CapEx!$E$9/Assumptions!$D$11
B31: Day-1 debt yield (Y1 NOI / debt) | C31: =OpEx_CapEx!$E$9/Assumptions!$D$47

Sheet Stress_Summary
B2: STRESS TEST SUMMARY — Bank format
B3: 5 scenarios. Base case must clear all 4 gates. Severe/Stress define downside protection.
B5: Metric | C5: Base | D5: Downside | E5: Severe | F5: Stress | G5: Upside
B6: NPV @ WACC (Project, SAR M) | C6: =Scenario_Engine!C17/1000000 | D6: =Scenario_Engine!D17/1000000 | E6: =Scenario_Engine!E17/1000000 | F6: =Scenario_Engine!F17/1000000 | G6: =Scenario_Engine!G17/1000000
B7: Equity IRR | C7: =Scenario_Engine!C18 | D7: =Scenario_Engine!D18 | E7: =Scenario_Engine!E18 | F7: =Scenario_Engine!F18 | G7: =Scenario_Engine!G18
B8: Equity MOIC | C8: =Scenario_Engine!C19 | D8: =Scenario_Engine!D19 | E8: =Scenario_Engine!E19 | F8: =Scenario_Engine!F19 | G8: =Scenario_Engine!G19
B9: Y1 DSCR | C9: =Scenario_Engine!C20 | D9: =Scenario_Engine!D20 | E9: =Scenario_Engine!E20 | F9: =Scenario_Engine!F20 | G9: =Scenario_Engine!G20
B10: Exit value (SAR M) | C10: =Scenario_Engine!C21/1000000 | D10: =Scenario_Engine!D21/1000000 | E10: =Scenario_Engine!E21/1000000 | F10: =Scenario_Engine!F21/1000000 | G10: =Scenario_Engine!G21/1000000
B11: Investment verdict | C11: =Scenario_Engine!C22 | D11: =Scenario_Engine!D22 | E11: =Scenario_Engine!E22 | F11: =Scenario_Engine!F22 | G11: =Scenario_Engine!G22
B14: BANK GATES (must clear in Base AND Downside)
B15: Gate | C15: Base | D15: Downside | E15: Pass?
B16: Y1 DSCR ≥ 1.35x | C16: =Stress_Summary!C9 | D16: =Stress_Summary!D9 | E16: =IF(AND(C16>=1.35,D16>=1.35),"PASS","FAIL")
B17: NPV @ WACC ≥ 0 | C17: =Stress_Summary!C6 | D17: =Stress_Summary!D6 | E17: =IF(AND(C17>=0,D17>=0),"PASS","FAIL")
B18: Equity IRR ≥ 12% | C18: =Stress_Summary!C7 | D18: =Stress_Summary!D7 | E18: =IF(AND(C18>=0.12,D18>=0.12),"PASS","FAIL")
B19: Verdict ≠ REJECT | C19: =Stress_Summary!C11 | D19: =Stress_Summary!D11 | E19: =IF(AND(C19<>"REJECT",D19<>"REJECT"),"PASS","FAIL")
B22: OVERALL STRESS TEST OUTCOME
B23: Number of gates passed (of 4) | C23: =COUNTIF(E16:E19,"PASS")
B24: Recommendation | C24: =IF(C23=4,"APPROVE",IF(C23>=2,"CONDITIONAL — Restructure","REJECT"))

Sheet Covenant_Test
B2: COVENANT COMPLIANCE — annual + cushion test
B3: Test bank covenants every year. Cushion = (actual − threshold). Negative cushion = breach. Cash sweep above 1.45x.
B5: Covenant | C5: Y1 | D5: Y2 | E5: Y3 | F5: Y4 | G5: Y5 | H5: Y6 | I5: Y7 | J5: Y8 | K5: Y9 | L5: Y10
B6: DSCR (CFADS / DS) | C6: =Lender_Metrics!E8 | D6: =Lender_Metrics!F8 | E6: =Lender_Metrics!G8 | F6: =Lender_Metrics!H8 | G6: =Lender_Metrics!I8 | H6: =Lender_Metrics!J8 | I6: =Lender_Metrics!K8 | J6: =Lender_Metrics!L8 | ... L6: =Lender_Metrics!N8
B7: DSCR cushion vs 1.35x | C7: =IFERROR(C6-Assumptions!$D$73,0) | D7: =IFERROR(D6-Assumptions!$D$73,0) | E7: =IFERROR(E6-Assumptions!$D$73,0) | F7: =IFERROR(F6-Assumptions!$D$73,0) | G7: =IFERROR(G6-Assumptions!$D$73,0) | H7: =IFERROR(H6-Assumptions!$D$73,0) | I7: =IFERROR(I6-Assumptions!$D$73,0) | J7: =IFERROR(J6-Assumptions!$D$73,0) | ... L7: =IFERROR(L6-Assumptions!$D$73,0)
B8: DSCR compliance | C8: =IF(C6>=Assumptions!$D$73,"PASS","BREACH") | D8: =IF(D6>=Assumptions!$D$73,"PASS","BREACH") | E8: =IF(E6>=Assumptions!$D$73,"PASS","BREACH") | F8: =IF(F6>=Assumptions!$D$73,"PASS","BREACH") | G8: =IF(G6>=Assumptions!$D$73,"PASS","BREACH") | H8: =IF(H6>=Assumptions!$D$73,"PASS","BREACH") | I8: =IF(I6>=Assumptions!$D$73,"PASS","BREACH") | J8: =IF(J6>=Assumptions!$D$73,"PASS","BREACH") | ... L8: =IF(L6>=Assumptions!$D$73,"PASS","BREACH")
B9: Cash sweep trigger (DSCR < 1.45x) | C9: =IF(C6<1.45,"SWEEP","FREE CASH") | D9: =IF(D6<1.45,"SWEEP","FREE CASH") | E9: =IF(E6<1.45,"SWEEP","FREE CASH") | F9: =IF(F6<1.45,"SWEEP","FREE CASH") | G9: =IF(G6<1.45,"SWEEP","FREE CASH") | H9: =IF(H6<1.45,"SWEEP","FREE CASH") | I9: =IF(I6<1.45,"SWEEP","FREE CASH") | J9: =IF(J6<1.45,"SWEEP","FREE CASH") | ... L9: =IF(L6<1.45,"SWEEP","FREE CASH")
B11: LLCR (PV CFADS / Debt) | C11: =IFERROR(Lender_Metrics!E10,0) | D11: =IFERROR(Lender_Metrics!F10,0) | E11: =IFERROR(Lender_Metrics!G10,0) | F11: =IFERROR(Lender_Metrics!H10,0) | G11: =IFERROR(Lender_Metrics!I10,0) | H11: =IFERROR(Lender_Metrics!J10,0) | I11: =IFERROR(Lender_Metrics!K10,0) | J11: =IFERROR(Lender_Metrics!L10,0) | ... L11: =IFERROR(Lender_Metrics!N10,0)
B12: LLCR compliance (≥ 1.40x) | C12: =IF(C11>=1.4,"PASS","BREACH") | D12: =IF(D11>=1.4,"PASS","BREACH") | E12: =IF(E11>=1.4,"PASS","BREACH") | F12: =IF(F11>=1.4,"PASS","BREACH") | G12: =IF(G11>=1.4,"PASS","BREACH") | H12: =IF(H11>=1.4,"PASS","BREACH") | I12: =IF(I11>=1.4,"PASS","BREACH") | J12: =IF(J11>=1.4,"PASS","BREACH") | ... L12: =IF(L11>=1.4,"PASS","BREACH")
B14: Debt yield (NOI / Debt) | C14: =IFERROR(Lender_Metrics!E13,0) | D14: =IFERROR(Lender_Metrics!F13,0) | E14: =IFERROR(Lender_Metrics!G13,0) | F14: =IFERROR(Lender_Metrics!H13,0) | G14: =IFERROR(Lender_Metrics!I13,0) | H14: =IFERROR(Lender_Metrics!J13,0) | I14: =IFERROR(Lender_Metrics!K13,0) | J14: =IFERROR(Lender_Metrics!L13,0) | ... L14: =IFERROR(Lender_Metrics!N13,0)
B15: DY compliance (≥ 10%) | C15: =IF(C14>=Assumptions!$D$75,"PASS","BREACH") | D15: =IF(D14>=Assumptions!$D$75,"PASS","BREACH") | E15: =IF(E14>=Assumptions!$D$75,"PASS","BREACH") | F15: =IF(F14>=Assumptions!$D$75,"PASS","BREACH") | G15: =IF(G14>=Assumptions!$D$75,"PASS","BREACH") | H15: =IF(H14>=Assumptions!$D$75,"PASS","BREACH") | I15: =IF(I14>=Assumptions!$D$75,"PASS","BREACH") | J15: =IF(J14>=Assumptions!$D$75,"PASS","BREACH") | ... L15: =IF(L14>=Assumptions!$D$75,"PASS","BREACH")
B17: LTV (Debt / implied market value) | C17: =IFERROR(Debt!E9/(OpEx_CapEx!E9/Assumptions!$D$51),0) | D17: =IFERROR(Debt!F9/(OpEx_CapEx!F9/Assumptions!$D$51),0) | E17: =IFERROR(Debt!G9/(OpEx_CapEx!G9/Assumptions!$D$51),0) | F17: =IFERROR(Debt!H9/(OpEx_CapEx!H9/Assumptions!$D$51),0) | G17: =IFERROR(Debt!I9/(OpEx_CapEx!I9/Assumptions!$D$51),0) | H17: =IFERROR(Debt!J9/(OpEx_CapEx!J9/Assumptions!$D$51),0) | I17: =IFERROR(Debt!K9/(OpEx_CapEx!K9/Assumptions!$D$51),0) | J17: =IFERROR(Debt!L9/(OpEx_CapEx!L9/Assumptions!$D$51),0) | ... L17: =IFERROR(Debt!N9/(OpEx_CapEx!N9/Assumptions!$D$51),0)
B18: LTV compliance (≤ 60%) | C18: =IF(C17<=0.60,"PASS","BREACH") | D18: =IF(D17<=0.60,"PASS","BREACH") | E18: =IF(E17<=0.60,"PASS","BREACH") | F18: =IF(F17<=0.60,"PASS","BREACH") | G18: =IF(G17<=0.60,"PASS","BREACH") | H18: =IF(H17<=0.60,"PASS","BREACH") | I18: =IF(I17<=0.60,"PASS","BREACH") | J18: =IF(J17<=0.60,"PASS","BREACH") | ... L18: =IF(L17<=0.60,"PASS","BREACH")
B20: COMPLIANCE SUMMARY
B21: Total breaches over hold | C21: =COUNTIF(C8:L8,"BREACH")+COUNTIF(C12:L12,"BREACH")+COUNTIF(C15:L15,"BREACH")+COUNTIF(C18:L18,"BREACH")
B22: Quarters in cash sweep | C22: =COUNTIF(C9:L9,"SWEEP")
B23: Verdict | C23: =IF(C21=0,"FULL COMPLIANCE",IF(C21<=2,"MARGINAL — ACCEPTABLE","NON-COMPLIANT"))

Sheet Assumptions
B2: ASSUMPTIONS — Bank-Ready (v5.1 Conservative)
B3: Blue = input. Yellow fill = high-impact assumption. All cells outside the input column should be empty or formula-driven.
B5: 1. PROJECT TIMELINE
B6: Investment closing year (Y0) | D6: 2025 | E6: year | F6: Capital deployed at start of this year
B7: Holding period (operating years) | D7: 10 | E7: yrs | F7: Y1..Y_hold years of operation
B8: Exit calendar year | D8: =Assumptions!$D$6+Assumptions!$D$7 | E8: year | F8: Calculated
B10: 2. PROJECT COST & ACQUISITION
B11: Asset purchase price | D11: 170000000 | E11: SAR | F11: Pre-fee asset price
B12: RETT (Real Estate Transaction Tax) | D12: 0.05 | E12: % | F12: Saudi RETT — confirm current rate
B13: Acquisition broker / agency | D13: 0.025 | E13: % | F13: % of purchase price
B14: Acquisition / DD / legal fee | D14: 0.0025 | E14: % | F14: Advisory + legal
B15: Sum of acquisition costs (%) | D15: =Assumptions!$D$12+Assumptions!$D$13+Assumptions!$D$14 | E15: % | F15: Calculated
B16: Total project cost (incl. fees) | D16: =Assumptions!$D$11*(1+Assumptions!$D$15) | E16: SAR | F16: Calculated
B18: 3. REVENUE
B19: Year 1 gross revenue (stabilised) | D19: 14280000 | E19: SAR | F19: First full operating year revenue
B20: Revenue growth rate (annualised) | D20: 0.025 | E20: % | F20: Effective annual growth
B21: Escalation frequency | D21: 1 | E21: yrs | F21: 1 = annual; 2 = biennial; etc.
B22: Vacancy / collection loss | D22: 0.08 | E22: % | F22: % of gross revenue lost; v3 used 0% — institutional minimum 3-5%
B24: 4. OPERATING EXPENSES (asset level)
B25: OpEx (% of EGI) | D25: 0.08 | E25: % | F25: True asset operating costs — maintenance, utilities, insurance, sec.
B26: Property / municipal tax | D26: 0 | E26: % | F26: % of EGI — adjust to local regime
B27: OpEx inflation | D27: 0.025 | E27: % | F27: Annual cost inflation
B29: 5. CORPORATE / FUND COSTS (below NOI)
B30: Asset management fee (% NAV) | D30: 0.003 | E30: % | F30: 0 if self-managed; NAV-based
B31: Custodian fee (% NAV) | D31: 0.0004 | E31: % | F31: Third-party custody
B32: Fund admin fee (% NAV) | D32: 0.0005 | E32: % | F32: Accounting/admin
B33: Other fixed annual expenses | D33: 285000 | E33: SAR | F33: Audit, legal, board
B35: 6. CAPITAL EXPENDITURE
B36: Maintenance CapEx (% of EGI) | D36: 0.02 | E36: % | F36: Institutional norm 1-2% for stabilized assets — v3 used 0%
B37: Major refurbishment amount | D37: 3000000 | E37: SAR | F37: Cyclical major refurb (one-off)
B38: Refurbishment year (Yn) | D38: 5 | E38: Yn | F38: Year of major refurb
B40: 7. FINANCING / DEBT
B41: Debt ratio (% of total cost) | D41: 0.5 | E41: % | F41: Set 0% for all-equity
B42: Cost of debt (annual) | D42: 0.075 | E42: % | F42: All-in rate
B43: Debt arrangement fee (one-off) | D43: 0.0025 | E43: % | F43: % of debt; paid Y0
B44: Amortization (1=AMORT, 0=BULLET) | D44: 0 | E44: flag | F44: 1 = amortizing over tenor; 0 = bullet at exit
B45: Debt tenor (years) | D45: 10 | E45: yrs | F45: Amortization tenor
B46: Grace period (years, interest-only) | D46: 1 | E46: yrs | F46: Interest-only years
B47: Debt amount | D47: =Assumptions!$D$16*Assumptions!$D$41 | E47: SAR | F47: Calculated
B48: Equity required | D48: =Assumptions!$D$16*(1-Assumptions!$D$41) | E48: SAR | F48: Calculated
...

Sheet Timeline
B2: TIMELINE & PERIOD FLAGS
B3: Period | D3: 0 | E3: 1 | F3: 2 | G3: 3 | H3: 4 | I3: 5 | J3: 6 | K3: 7 | L3: 8 | M3: 9 | N3: 10
B4: Year | D4: =Assumptions!$D$6+0 | E4: =Assumptions!$D$6+1 | F4: =Assumptions!$D$6+2 | G4: =Assumptions!$D$6+3 | H4: =Assumptions!$D$6+4 | I4: =Assumptions!$D$6+5 | J4: =Assumptions!$D$6+6 | K4: =Assumptions!$D$6+7 | L4: =Assumptions!$D$6+8 | M4: =Assumptions!$D$6+9 | N4: =Assumptions!$D$6+10
B5: Operating year flag | D5: 0 | E5: =IF(1<=Assumptions!$D$7,1,0) | F5: =IF(2<=Assumptions!$D$7,1,0) | G5: =IF(3<=Assumptions!$D$7,1,0) | H5: =IF(4<=Assumptions!$D$7,1,0) | I5: =IF(5<=Assumptions!$D$7,1,0) | J5: =IF(6<=Assumptions!$D$7,1,0) | K5: =IF(7<=Assumptions!$D$7,1,0) | L5: =IF(8<=Assumptions!$D$7,1,0) | M5: =IF(9<=Assumptions!$D$7,1,0) | N5: =IF(10<=Assumptions!$D$7,1,0)
B6: Exit year flag | D6: =IF(0=Assumptions!$D$7,1,0) | E6: =IF(1=Assumptions!$D$7,1,0) | F6: =IF(2=Assumptions!$D$7,1,0) | G6: =IF(3=Assumptions!$D$7,1,0) | H6: =IF(4=Assumptions!$D$7,1,0) | I6: =IF(5=Assumptions!$D$7,1,0) | J6: =IF(6=Assumptions!$D$7,1,0) | K6: =IF(7=Assumptions!$D$7,1,0) | L6: =IF(8=Assumptions!$D$7,1,0) | M6: =IF(9=Assumptions!$D$7,1,0) | N6: =IF(10=Assumptions!$D$7,1,0)
B7: Escalation step flag (0/1) | D7: 0 | E7: 0 | F7: =IF(Assumptions!$D$21=0,0,IF(MOD(2-1,Assumptions!$D$21)=0,1,0)) | G7: =IF(Assumptions!$D$21=0,0,IF(MOD(3-1,Assumptions!$D$21)=0,1,0)) | H7: =IF(Assumptions!$D$21=0,0,IF(MOD(4-1,Assumptions!$D$21)=0,1,0)) | I7: =IF(Assumptions!$D$21=0,0,IF(MOD(5-1,Assumptions!$D$21)=0,1,0)) | J7: =IF(Assumptions!$D$21=0,0,IF(MOD(6-1,Assumptions!$D$21)=0,1,0)) | K7: =IF(Assumptions!$D$21=0,0,IF(MOD(7-1,Assumptions!$D$21)=0,1,0)) | L7: =IF(Assumptions!$D$21=0,0,IF(MOD(8-1,Assumptions!$D$21)=0,1,0)) | M7: =IF(Assumptions!$D$21=0,0,IF(MOD(9-1,Assumptions!$D$21)=0,1,0)) | N7: =IF(Assumptions!$D$21=0,0,IF(MOD(10-1,Assumptions!$D$21)=0,1,0))
B8: Cumulative escalation factor | D8: 1 | E8: 1 | F8: =E8*(1+F7*Assumptions!$D$20) | G8: =F8*(1+G7*Assumptions!$D$20) | H8: =G8*(1+H7*Assumptions!$D$20) | I8: =H8*(1+I7*Assumptions!$D$20) | J8: =I8*(1+J7*Assumptions!$D$20) | K8: =J8*(1+K7*Assumptions!$D$20) | L8: =K8*(1+L7*Assumptions!$D$20) | M8: =L8*(1+M7*Assumptions!$D$20) | N8: =M8*(1+N7*Assumptions!$D$20)
B9: OpEx inflation factor | D9: 1 | E9: 1 | F9: =E9*(1+Assumptions!$D$27) | G9: =F9*(1+Assumptions!$D$27) | H9: =G9*(1+Assumptions!$D$27) | I9: =H9*(1+Assumptions!$D$27) | J9: =I9*(1+Assumptions!$D$27) | K9: =J9*(1+Assumptions!$D$27) | L9: =K9*(1+Assumptions!$D$27) | M9: =L9*(1+Assumptions!$D$27) | N9: =M9*(1+Assumptions!$D$27)

Sheet Revenue
B2: REVENUE BUILD
B3: Period | D3: 0 | E3: 1 | F3: 2 | G3: 3 | H3: 4 | I3: 5 | J3: 6 | K3: 7 | L3: 8 | M3: 9 | N3: 10
B4: Year | D4: =Assumptions!$D$6+0 | E4: =Assumptions!$D$6+1 | F4: =Assumptions!$D$6+2 | G4: =Assumptions!$D$6+3 | H4: =Assumptions!$D$6+4 | I4: =Assumptions!$D$6+5 | J4: =Assumptions!$D$6+6 | K4: =Assumptions!$D$6+7 | L4: =Assumptions!$D$6+8 | M4: =Assumptions!$D$6+9 | N4: =Assumptions!$D$6+10
B5: Gross potential revenue | D5: =Assumptions!$D$19*Timeline!D8*Timeline!D5 | E5: =Assumptions!$D$19*Timeline!E8*Timeline!E5 | F5: =Assumptions!$D$19*Timeline!F8*Timeline!F5 | G5: =Assumptions!$D$19*Timeline!G8*Timeline!G5 | H5: =Assumptions!$D$19*Timeline!H8*Timeline!H5 | I5: =Assumptions!$D$19*Timeline!I8*Timeline!I5 | J5: =Assumptions!$D$19*Timeline!J8*Timeline!J5 | K5: =Assumptions!$D$19*Timeline!K8*Timeline!K5 | ... N5: =Assumptions!$D$19*Timeline!N8*Timeline!N5
B6: Vacancy / collection loss | D6: =-D5*Assumptions!$D$22 | E6: =-E5*Assumptions!$D$22 | F6: =-F5*Assumptions!$D$22 | G6: =-G5*Assumptions!$D$22 | H6: =-H5*Assumptions!$D$22 | I6: =-I5*Assumptions!$D$22 | J6: =-J5*Assumptions!$D$22 | K6: =-K5*Assumptions!$D$22 | ... N6: =-N5*Assumptions!$D$22
B7: EFFECTIVE GROSS INCOME (EGI) | D7: =D5+D6 | E7: =E5+E6 | F7: =F5+F6 | G7: =G5+G6 | H7: =H5+H6 | I7: =I5+I6 | J7: =J5+J6 | K7: =K5+K6 | ... N7: =N5+N6
B8: YoY EGI growth | E8: =IFERROR(IF(D7=0,0,E7/D7-1),0) | F8: =IFERROR(IF(E7=0,0,F7/E7-1),0) | G8: =IFERROR(IF(F7=0,0,G7/F7-1),0) | H8: =IFERROR(IF(G7=0,0,H7/G7-1),0) | I8: =IFERROR(IF(H7=0,0,I7/H7-1),0) | J8: =IFERROR(IF(I7=0,0,J7/I7-1),0) | K8: =IFERROR(IF(J7=0,0,K7/J7-1),0) | L8: =IFERROR(IF(K7=0,0,L7/K7-1),0) | ... N8: =IFERROR(IF(M7=0,0,N7/M7-1),0)

Sheet OpEx_CapEx
B2: OPERATING EXPENSES & CAPITAL EXPENDITURE
B3: Period | D3: 0 | E3: 1 | F3: 2 | G3: 3 | H3: 4 | I3: 5 | J3: 6 | K3: 7 | L3: 8 | M3: 9 | N3: 10
B4: Year | D4: =Assumptions!$D$6+0 | E4: =Assumptions!$D$6+1 | F4: =Assumptions!$D$6+2 | G4: =Assumptions!$D$6+3 | H4: =Assumptions!$D$6+4 | I4: =Assumptions!$D$6+5 | J4: =Assumptions!$D$6+6 | K4: =Assumptions!$D$6+7 | L4: =Assumptions!$D$6+8 | M4: =Assumptions!$D$6+9 | N4: =Assumptions!$D$6+10
B5: ASSET-LEVEL OPERATING EXPENSES
B6: Operating expenses (OpEx) | D6: =-Revenue!D7*Assumptions!$D$25*Timeline!D9/Timeline!E9 | E6: =-Revenue!E7*Assumptions!$D$25*Timeline!E9/Timeline!E9 | F6: =-Revenue!F7*Assumptions!$D$25*Timeline!F9/Timeline!E9 | G6: =-Revenue!G7*Assumptions!$D$25*Timeline!G9/Timeline!E9 | H6: =-Revenue!H7*Assumptions!$D$25*Timeline!H9/Timeline!E9 | I6: =-Revenue!I7*Assumptions!$D$25*Timeline!I9/Timeline!E9 | J6: =-Revenue!J7*Assumptions!$D$25*Timeline!J9/Timeline!E9 | K6: =-Revenue!K7*Assumptions!$D$25*Timeline!K9/Timeline!E9 | L6: =-Revenue!L7*Assumptions!$D$25*Timeline!L9/Timeline!E9 | M6: =-Revenue!M7*Assumptions!$D$25*Timeline!M9/Timeline!E9 | N6: =-Revenue!N7*Assumptions!$D$25*Timeline!N9/Timeline!E9
B7: Property / municipal tax | D7: =-Revenue!D7*Assumptions!$D$26 | E7: =-Revenue!E7*Assumptions!$D$26 | F7: =-Revenue!F7*Assumptions!$D$26 | G7: =-Revenue!G7*Assumptions!$D$26 | H7: =-Revenue!H7*Assumptions!$D$26 | I7: =-Revenue!I7*Assumptions!$D$26 | J7: =-Revenue!J7*Assumptions!$D$26 | K7: =-Revenue!K7*Assumptions!$D$26 | ... N7: =-Revenue!N7*Assumptions!$D$26
B8: TOTAL ASSET OPERATING EXPENSES | D8: =D6+D7 | E8: =E6+E7 | F8: =F6+F7 | G8: =G6+G7 | H8: =H6+H7 | I8: =I6+I7 | J8: =J6+J7 | K8: =K6+K7 | ... N8: =N6+N7
B9: NET OPERATING INCOME (NOI) | D9: =Revenue!D7+D8 | E9: =Revenue!E7+E8 | F9: =Revenue!F7+F8 | G9: =Revenue!G7+G8 | H9: =Revenue!H7+H8 | I9: =Revenue!I7+I8 | J9: =Revenue!J7+J8 | K9: =Revenue!K7+K8 | ... N9: =Revenue!N7+N8
B10: NOI margin | D10: =IFERROR(IF(Revenue!D7=0,0,D9/Revenue!D7),0) | E10: =IFERROR(IF(Revenue!E7=0,0,E9/Revenue!E7),0) | F10: =IFERROR(IF(Revenue!F7=0,0,F9/Revenue!F7),0) | G10: =IFERROR(IF(Revenue!G7=0,0,G9/Revenue!G7),0) | H10: =IFERROR(IF(Revenue!H7=0,0,H9/Revenue!H7),0) | I10: =IFERROR(IF(Revenue!I7=0,0,I9/Revenue!I7),0) | J10: =IFERROR(IF(Revenue!J7=0,0,J9/Revenue!J7),0) | K10: =IFERROR(IF(Revenue!K7=0,0,K9/Revenue!K7),0) | ... N10: =IFERROR(IF(Revenue!N7=0,0,N9/Revenue!N7),0)
B12: CORPORATE / FUND-LEVEL COSTS (below NOI)
B13: Management fee (% NAV proxy: total cost) | D13: =-Assumptions!$D$16*Assumptions!$D$30*Timeline!D5 | E13: =-Assumptions!$D$16*Assumptions!$D$30*Timeline!E5 | F13: =-Assumptions!$D$16*Assumptions!$D$30*Timeline!F5 | G13: =-Assumptions!$D$16*Assumptions!$D$30*Timeline!G5 | H13: =-Assumptions!$D$16*Assumptions!$D$30*Timeline!H5 | I13: =-Assumptions!$D$16*Assumptions!$D$30*Timeline!I5 | J13: =-Assumptions!$D$16*Assumptions!$D$30*Timeline!J5 | K13: =-Assumptions!$D$16*Assumptions!$D$30*Timeline!K5 | ... N13: =-Assumptions!$D$16*Assumptions!$D$30*Timeline!N5
B14: Custodian fee | D14: =-Assumptions!$D$16*Assumptions!$D$31*Timeline!D5 | E14: =-Assumptions!$D$16*Assumptions!$D$31*Timeline!E5 | F14: =-Assumptions!$D$16*Assumptions!$D$31*Timeline!F5 | G14: =-Assumptions!$D$16*Assumptions!$D$31*Timeline!G5 | H14: =-Assumptions!$D$16*Assumptions!$D$31*Timeline!H5 | I14: =-Assumptions!$D$16*Assumptions!$D$31*Timeline!I5 | J14: =-Assumptions!$D$16*Assumptions!$D$31*Timeline!J5 | K14: =-Assumptions!$D$16*Assumptions!$D$31*Timeline!K5 | ... N14: =-Assumptions!$D$16*Assumptions!$D$31*Timeline!N5
B15: Fund admin fee | D15: =-Assumptions!$D$16*Assumptions!$D$32*Timeline!D5 | E15: =-Assumptions!$D$16*Assumptions!$D$32*Timeline!E5 | F15: =-Assumptions!$D$16*Assumptions!$D$32*Timeline!F5 | G15: =-Assumptions!$D$16*Assumptions!$D$32*Timeline!G5 | H15: =-Assumptions!$D$16*Assumptions!$D$32*Timeline!H5 | I15: =-Assumptions!$D$16*Assumptions!$D$32*Timeline!I5 | J15: =-Assumptions!$D$16*Assumptions!$D$32*Timeline!J5 | K15: =-Assumptions!$D$16*Assumptions!$D$32*Timeline!K5 | ... N15: =-Assumptions!$D$16*Assumptions!$D$32*Timeline!N5
B16: Other fixed annual expenses | D16: =-Assumptions!$D$33*Timeline!D9*Timeline!D5 | E16: =-Assumptions!$D$33*Timeline!E9*Timeline!E5 | F16: =-Assumptions!$D$33*Timeline!F9*Timeline!F5 | G16: =-Assumptions!$D$33*Timeline!G9*Timeline!G5 | H16: =-Assumptions!$D$33*Timeline!H9*Timeline!H5 | I16: =-Assumptions!$D$33*Timeline!I9*Timeline!I5 | J16: =-Assumptions!$D$33*Timeline!J9*Timeline!J5 | K16: =-Assumptions!$D$33*Timeline!K9*Timeline!K5 | ... N16: =-Assumptions!$D$33*Timeline!N9*Timeline!N5
B17: TOTAL CORPORATE COSTS | D17: =SUM(D13:D16) | E17: =SUM(E13:E16) | F17: =SUM(F13:F16) | G17: =SUM(G13:G16) | H17: =SUM(H13:H16) | I17: =SUM(I13:I16) | J17: =SUM(J13:J16) | K17: =SUM(K13:K16) | ... N17: =SUM(N13:N16)
B18: EBITDA (NOI − Corporate costs) | D18: =D9+D17 | E18: =E9+E17 | F18: =F9+F17 | G18: =G9+G17 | H18: =H9+H17 | I18: =I9+I17 | J18: =J9+J17 | K18: =K9+K17 | ... N18: =N9+N17
B20: CAPITAL EXPENDITURE
B21: Maintenance CapEx (% EGI) | D21: =-Revenue!D7*Assumptions!$D$36 | E21: =-Revenue!E7*Assumptions!$D$36 | F21: =-Revenue!F7*Assumptions!$D$36 | G21: =-Revenue!G7*Assumptions!$D$36 | H21: =-Revenue!H7*Assumptions!$D$36 | I21: =-Revenue!I7*Assumptions!$D$36 | J21: =-Revenue!J7*Assumptions!$D$36 | K21: =-Revenue!K7*Assumptions!$D$36 | ... N21: =-Revenue!N7*Assumptions!$D$36
B22: Major refurbishment | D22: =IF(0=Assumptions!$D$38,-Assumptions!$D$37,0) | E22: =IF(1=Assumptions!$D$38,-Assumptions!$D$37,0) | F22: =IF(2=Assumptions!$D$38,-Assumptions!$D$37,0) | G22: =IF(3=Assumptions!$D$38,-Assumptions!$D$37,0) | H22: =IF(4=Assumptions!$D$38,-Assumptions!$D$37,0) | I22: =IF(5=Assumptions!$D$38,-Assumptions!$D$37,0) | J22: =IF(6=Assumptions!$D$38,-Assumptions!$D$37,0) | K22: =IF(7=Assumptions!$D$38,-Assumptions!$D$37,0) | L22: =IF(8=Assumptions!$D$38,-Assumptions!$D$37,0) | M22: =IF(9=Assumptions!$D$38,-Assumptions!$D$37,0) | N22: =IF(10=Assumptions!$D$38,-Assumptions!$D$37,0)
B23: TOTAL CAPEX | D23: =D21+D22 | E23: =E21+E22 | F23: =F21+F22 | G23: =G21+G22 | H23: =H21+H22 | I23: =I21+I22 | J23: =J21+J22 | K23: =K21+K22 | ... N23: =N21+N22

Sheet Debt
B2: DEBT SCHEDULE
B3: Period | D3: 0 | E3: 1 | F3: 2 | G3: 3 | H3: 4 | I3: 5 | J3: 6 | K3: 7 | L3: 8 | M3: 9 | N3: 10
B4: Year | D4: =Assumptions!$D$6+0 | E4: =Assumptions!$D$6+1 | F4: =Assumptions!$D$6+2 | G4: =Assumptions!$D$6+3 | H4: =Assumptions!$D$6+4 | I4: =Assumptions!$D$6+5 | J4: =Assumptions!$D$6+6 | K4: =Assumptions!$D$6+7 | L4: =Assumptions!$D$6+8 | M4: =Assumptions!$D$6+9 | N4: =Assumptions!$D$6+10
B5: Opening balance | D5: 0 | E5: =D9 | F5: =E9 | G5: =F9 | H5: =G9 | I5: =H9 | J5: =I9 | K5: =J9 | L5: =K9 | ... N5: =M9
B6: Drawdown | D6: =Assumptions!$D$47 | E6: 0 | F6: 0 | G6: 0 | H6: 0 | I6: 0 | J6: 0 | K6: 0 | L6: 0 | M6: 0 | N6: 0
B7: Scheduled principal repayment | D7: 0 | E7: =-IF(AND(Assumptions!$D$44=1,1>Assumptions!$D$46,1<Assumptions!$D$7,Assumptions!$D$45-Assumptions!$D$46>0),Assumptions!$D$47/(Assumptions!$D$45-Assumptions!$D$46),0) | F7: =-IF(AND(Assumptions!$D$44=1,2>Assumptions!$D$46,2<Assumptions!$D$7,Assumptions!$D$45-Assumptions!$D$46>0),Assumptions!$D$47/(Assumptions!$D$45-Assumptions!$D$46),0) | G7: =-IF(AND(Assumptions!$D$44=1,3>Assumptions!$D$46,3<Assumptions!$D$7,Assumptions!$D$45-Assumptions!$D$46>0),Assumptions!$D$47/(Assumptions!$D$45-Assumptions!$D$46),0) | H7: =-IF(AND(Assumptions!$D$44=1,4>Assumptions!$D$46,4<Assumptions!$D$7,Assumptions!$D$45-Assumptions!$D$46>0),Assumptions!$D$47/(Assumptions!$D$45-Assumptions!$D$46),0) | I7: =-IF(AND(Assumptions!$D$44=1,5>Assumptions!$D$46,5<Assumptions!$D$7,Assumptions!$D$45-Assumptions!$D$46>0),Assumptions!$D$47/(Assumptions!$D$45-Assumptions!$D$46),0) | J7: =-IF(AND(Assumptions!$D$44=1,6>Assumptions!$D$46,6<Assumptions!$D$7,Assumptions!$D$45-Assumptions!$D$46>0),Assumptions!$D$47/(Assumptions!$D$45-Assumptions!$D$46),0) | K7: =-IF(AND(Assumptions!$D$44=1,7>Assumptions!$D$46,7<Assumptions!$D$7,Assumptions!$D$45-Assumptions!$D$46>0),Assumptions!$D$47/(Assumptions!$D$45-Assumptions!$D$46),0) | L7: =-IF(AND(Assumptions!$D$44=1,8>Assumptions!$D$46,8<Assumptions!$D$7,Assumptions!$D$45-Assumptions!$D$46>0),Assumptions!$D$47/(Assumptions!$D$45-Assumptions!$D$46),0) | M7: =-IF(AND(Assumptions!$D$44=1,9>Assumptions!$D$46,9<Assumptions!$D$7,Assumptions!$D$45-Assumptions!$D$46>0),Assumptions!$D$47/(Assumptions!$D$45-Assumptions!$D$46),0) | N7: =-IF(AND(Assumptions!$D$44=1,10>Assumptions!$D$46,10<Assumptions!$D$7,Assumptions!$D$45-Assumptions!$D$46>0),Assumptions!$D$47/(Assumptions!$D$45-Assumptions!$D$46),0)
B8: Bullet repayment at exit | D8: 0 | E8: =-IF(1=Assumptions!$D$7,E5+E6+E7,0) | F8: =-IF(2=Assumptions!$D$7,F5+F6+F7,0) | G8: =-IF(3=Assumptions!$D$7,G5+G6+G7,0) | H8: =-IF(4=Assumptions!$D$7,H5+H6+H7,0) | I8: =-IF(5=Assumptions!$D$7,I5+I6+I7,0) | J8: =-IF(6=Assumptions!$D$7,J5+J6+J7,0) | K8: =-IF(7=Assumptions!$D$7,K5+K6+K7,0) | L8: =-IF(8=Assumptions!$D$7,L5+L6+L7,0) | M8: =-IF(9=Assumptions!$D$7,M5+M6+M7,0) | N8: =-IF(10=Assumptions!$D$7,N5+N6+N7,0)
B9: CLOSING BALANCE | D9: =D5+D6+D7+D8 | E9: =E5+E6+E7+E8 | F9: =F5+F6+F7+F8 | G9: =G5+G6+G7+G8 | H9: =H5+H6+H7+H8 | I9: =I5+I6+I7+I8 | J9: =J5+J6+J7+J8 | K9: =K5+K6+K7+K8 | ... N9: =N5+N6+N7+N8
B10: Interest expense | D10: 0 | E10: =-E5*Assumptions!$D$42*Timeline!E5 | F10: =-F5*Assumptions!$D$42*Timeline!F5 | G10: =-G5*Assumptions!$D$42*Timeline!G5 | H10: =-H5*Assumptions!$D$42*Timeline!H5 | I10: =-I5*Assumptions!$D$42*Timeline!I5 | J10: =-J5*Assumptions!$D$42*Timeline!J5 | K10: =-K5*Assumptions!$D$42*Timeline!K5 | L10: =-L5*Assumptions!$D$42*Timeline!L5 | ... N10: =-N5*Assumptions!$D$42*Timeline!N5
B11: Arrangement fee (one-off) | D11: =-Assumptions!$D$47*Assumptions!$D$43 | E11: 0 | F11: 0 | G11: 0 | H11: 0 | I11: 0 | J11: 0 | K11: 0 | L11: 0 | M11: 0 | N11: 0
B12: TOTAL DEBT SERVICE (interest + principal) | D12: =D7+D8+D10+D11 | E12: =E7+E8+E10+E11 | F12: =F7+F8+F10+F11 | G12: =G7+G8+G10+G11 | H12: =H7+H8+H10+H11 | I12: =I7+I8+I10+I11 | J12: =J7+J8+J10+J11 | K12: =K7+K8+K10+K11 | ... N12: =N7+N8+N10+N11
B14: COVERAGE RATIOS (per year)
B15: Interest Coverage (NOI / |Interest|) | D15: =IFERROR(IF(D10=0,999,OpEx_CapEx!D9/ABS(D10)),999) | E15: =IFERROR(IF(E10=0,999,OpEx_CapEx!E9/ABS(E10)),999) | F15: =IFERROR(IF(F10=0,999,OpEx_CapEx!F9/ABS(F10)),999) | G15: =IFERROR(IF(G10=0,999,OpEx_CapEx!G9/ABS(G10)),999) | H15: =IFERROR(IF(H10=0,999,OpEx_CapEx!H9/ABS(H10)),999) | I15: =IFERROR(IF(I10=0,999,OpEx_CapEx!I9/ABS(I10)),999) | J15: =IFERROR(IF(J10=0,999,OpEx_CapEx!J9/ABS(J10)),999) | K15: =IFERROR(IF(K10=0,999,OpEx_CapEx!K9/ABS(K10)),999) | ... N15: =IFERROR(IF(N10=0,999,OpEx_CapEx!N9/ABS(N10)),999)
B16: DSCR (NOI / (|Interest|+|Principal|+|Bullet|)) | D16: =IFERROR(IF(ABS(D10)+ABS(D7)+ABS(D8)=0,999,OpEx_CapEx!D9/(ABS(D10)+ABS(D7)+ABS(D8))),999) | E16: =IFERROR(IF(ABS(E10)+ABS(E7)+ABS(E8)=0,999,OpEx_CapEx!E9/(ABS(E10)+ABS(E7)+ABS(E8))),999) | F16: =IFERROR(IF(ABS(F10)+ABS(F7)+ABS(F8)=0,999,OpEx_CapEx!F9/(ABS(F10)+ABS(F7)+ABS(F8))),999) | G16: =IFERROR(IF(ABS(G10)+ABS(G7)+ABS(G8)=0,999,OpEx_CapEx!G9/(ABS(G10)+ABS(G7)+ABS(G8))),999) | H16: =IFERROR(IF(ABS(H10)+ABS(H7)+ABS(H8)=0,999,OpEx_CapEx!H9/(ABS(H10)+ABS(H7)+ABS(H8))),999) | I16: =IFERROR(IF(ABS(I10)+ABS(I7)+ABS(I8)=0,999,OpEx_CapEx!I9/(ABS(I10)+ABS(I7)+ABS(I8))),999) | J16: =IFERROR(IF(ABS(J10)+ABS(J7)+ABS(J8)=0,999,OpEx_CapEx!J9/(ABS(J10)+ABS(J7)+ABS(J8))),999) | K16: =IFERROR(IF(ABS(K10)+ABS(K7)+ABS(K8)=0,999,OpEx_CapEx!K9/(ABS(K10)+ABS(K7)+ABS(K8))),999) | ... N16: =IFERROR(IF(ABS(N10)+ABS(N7)+ABS(N8)=0,999,OpEx_CapEx!N9/(ABS(N10)+ABS(N7)+ABS(N8))),999)
B17: LTV (Debt / Asset Value at acquisition) | D17: =IFERROR(IF(Assumptions!$D$16=0,0,D9/Assumptions!$D$16),0) | E17: =IFERROR(IF(Assumptions!$D$16=0,0,E9/Assumptions!$D$16),0) | F17: =IFERROR(IF(Assumptions!$D$16=0,0,F9/Assumptions!$D$16),0) | G17: =IFERROR(IF(Assumptions!$D$16=0,0,G9/Assumptions!$D$16),0) | H17: =IFERROR(IF(Assumptions!$D$16=0,0,H9/Assumptions!$D$16),0) | I17: =IFERROR(IF(Assumptions!$D$16=0,0,I9/Assumptions!$D$16),0) | J17: =IFERROR(IF(Assumptions!$D$16=0,0,J9/Assumptions!$D$16),0) | K17: =IFERROR(IF(Assumptions!$D$16=0,0,K9/Assumptions!$D$16),0) | ... N17: =IFERROR(IF(Assumptions!$D$16=0,0,N9/Assumptions!$D$16),0)
B18: Debt yield (NOI / Debt outstanding) | D18: =IFERROR(IF(D9=0,"",OpEx_CapEx!D9/D9),"") | E18: =IFERROR(IF(E9=0,"",OpEx_CapEx!E9/E9),"") | F18: =IFERROR(IF(F9=0,"",OpEx_CapEx!F9/F9),"") | G18: =IFERROR(IF(G9=0,"",OpEx_CapEx!G9/G9),"") | H18: =IFERROR(IF(H9=0,"",OpEx_CapEx!H9/H9),"") | I18: =IFERROR(IF(I9=0,"",OpEx_CapEx!I9/I9),"") | J18: =IFERROR(IF(J9=0,"",OpEx_CapEx!J9/J9),"") | K18: =IFERROR(IF(K9=0,"",OpEx_CapEx!K9/K9),"") | ... N18: =IFERROR(IF(N9=0,"",OpEx_CapEx!N9/N9),"")
B19: Operating DSCR (interest + scheduled principal only) | D19: =IFERROR(IF(ABS(D10)+ABS(D7)=0,999,OpEx_CapEx!D9/(ABS(D10)+ABS(D7))),999) | E19: =IFERROR(IF(ABS(E10)+ABS(E7)=0,999,OpEx_CapEx!E9/(ABS(E10)+ABS(E7))),999) | F19: =IFERROR(IF(ABS(F10)+ABS(F7)=0,999,OpEx_CapEx!F9/(ABS(F10)+ABS(F7))),999) | G19: =IFERROR(IF(ABS(G10)+ABS(G7)=0,999,OpEx_CapEx!G9/(ABS(G10)+ABS(G7))),999) | H19: =IFERROR(IF(ABS(H10)+ABS(H7)=0,999,OpEx_CapEx!H9/(ABS(H10)+ABS(H7))),999) | I19: =IFERROR(IF(ABS(I10)+ABS(I7)=0,999,OpEx_CapEx!I9/(ABS(I10)+ABS(I7))),999) | J19: =IFERROR(IF(ABS(J10)+ABS(J7)=0,999,OpEx_CapEx!J9/(ABS(J10)+ABS(J7))),999) | K19: =IFERROR(IF(ABS(K10)+ABS(K7)=0,999,OpEx_CapEx!K9/(ABS(K10)+ABS(K7))),999) | ... N19: =IFERROR(IF(ABS(N10)+ABS(N7)=0,999,OpEx_CapEx!N9/(ABS(N10)+ABS(N7))),999)

Sheet QtrDebt
B2: QUARTERLY DEBT SERVICE — covenant & DSCR testing (40 quarters)
B3: Mirrors annual debt schedule at quarterly granularity. NOI approximated as annual / 4 (assumes flat intra-year).
B5: Quarter | C5: Q0 | D5: Q1 | E5: Q2 | F5: Q3 | G5: Q4 | H5: Q5 | I5: Q6 | J5: Q7 | K5: Q8 | L5: Q9 | M5: Q10 | N5: Q11 | O5: Q12 | P5: Q13 | Q5: Q14 | R5: Q15 | S5: Q16 | T5: Q17 | U5: Q18 | V5: Q19 | W5: Q20 | X5: Q21 | Y5: Q22 | Z5: Q23 | AA5: Q24 | AB5: Q25 | AC5: Q26 | AD5: Q27 | AE5: Q28 | AF5: Q29 | AG5: Q30 | AH5: Q31 | AI5: Q32 | AJ5: Q33 | AK5: Q34 | AL5: Q35 | AM5: Q36 | AN5: Q37 | AO5: Q38 | AP5: Q39 | AQ5: Q40
B6: Calendar year | C6: =Assumptions!$D$6+0 | D6: =Assumptions!$D$6+0 | E6: =Assumptions!$D$6+0 | F6: =Assumptions!$D$6+0 | G6: =Assumptions!$D$6+1 | H6: =Assumptions!$D$6+1 | I6: =Assumptions!$D$6+1 | J6: =Assumptions!$D$6+1 | K6: =Assumptions!$D$6+2 | L6: =Assumptions!$D$6+2 | M6: =Assumptions!$D$6+2 | N6: =Assumptions!$D$6+2 | O6: =Assumptions!$D$6+3 | P6: =Assumptions!$D$6+3 | Q6: =Assumptions!$D$6+3 | R6: =Assumptions!$D$6+3 | S6: =Assumptions!$D$6+4 | T6: =Assumptions!$D$6+4 | U6: =Assumptions!$D$6+4 | V6: =Assumptions!$D$6+4 | W6: =Assumptions!$D$6+5 | X6: =Assumptions!$D$6+5 | Y6: =Assumptions!$D$6+5 | Z6: =Assumptions!$D$6+5 | AA6: =Assumptions!$D$6+6 | AB6: =Assumptions!$D$6+6 | AC6: =Assumptions!$D$6+6 | AD6: =Assumptions!$D$6+6 | AE6: =Assumptions!$D$6+7 | AF6: =Assumptions!$D$6+7 | AG6: =Assumptions!$D$6+7 | AH6: =Assumptions!$D$6+7 | AI6: =Assumptions!$D$6+8 | AJ6: =Assumptions!$D$6+8 | AK6: =Assumptions!$D$6+8 | AL6: =Assumptions!$D$6+8 | AM6: =Assumptions!$D$6+9 | AN6: =Assumptions!$D$6+9 | AO6: =Assumptions!$D$6+9 | AP6: =Assumptions!$D$6+9 | AQ6: =Assumptions!$D$6+10
B7: Operating flag | C7: =IF(AND(0>=1,0<=Assumptions!$D$7),1,0) | D7: =IF(AND(0>=1,0<=Assumptions!$D$7),1,0) | E7: =IF(AND(0>=1,0<=Assumptions!$D$7),1,0) | F7: =IF(AND(0>=1,0<=Assumptions!$D$7),1,0) | G7: =IF(AND(1>=1,1<=Assumptions!$D$7),1,0) | H7: =IF(AND(1>=1,1<=Assumptions!$D$7),1,0) | I7: =IF(AND(1>=1,1<=Assumptions!$D$7),1,0) | J7: =IF(AND(1>=1,1<=Assumptions!$D$7),1,0) | K7: =IF(AND(2>=1,2<=Assumptions!$D$7),1,0) | L7: =IF(AND(2>=1,2<=Assumptions!$D$7),1,0) | M7: =IF(AND(2>=1,2<=Assumptions!$D$7),1,0) | N7: =IF(AND(2>=1,2<=Assumptions!$D$7),1,0) | O7: =IF(AND(3>=1,3<=Assumptions!$D$7),1,0) | P7: =IF(AND(3>=1,3<=Assumptions!$D$7),1,0) | Q7: =IF(AND(3>=1,3<=Assumptions!$D$7),1,0) | R7: =IF(AND(3>=1,3<=Assumptions!$D$7),1,0) | S7: =IF(AND(4>=1,4<=Assumptions!$D$7),1,0) | T7: =IF(AND(4>=1,4<=Assumptions!$D$7),1,0) | U7: =IF(AND(4>=1,4<=Assumptions!$D$7),1,0) | V7: =IF(AND(4>=1,4<=Assumptions!$D$7),1,0) | W7: =IF(AND(5>=1,5<=Assumptions!$D$7),1,0) | X7: =IF(AND(5>=1,5<=Assumptions!$D$7),1,0) | Y7: =IF(AND(5>=1,5<=Assumptions!$D$7),1,0) | Z7: =IF(AND(5>=1,5<=Assumptions!$D$7),1,0) | AA7: =IF(AND(6>=1,6<=Assumptions!$D$7),1,0) | AB7: =IF(AND(6>=1,6<=Assumptions!$D$7),1,0) | AC7: =IF(AND(6>=1,6<=Assumptions!$D$7),1,0) | AD7: =IF(AND(6>=1,6<=Assumptions!$D$7),1,0) | AE7: =IF(AND(7>=1,7<=Assumptions!$D$7),1,0) | AF7: =IF(AND(7>=1,7<=Assumptions!$D$7),1,0) | AG7: =IF(AND(7>=1,7<=Assumptions!$D$7),1,0) | AH7: =IF(AND(7>=1,7<=Assumptions!$D$7),1,0) | AI7: =IF(AND(8>=1,8<=Assumptions!$D$7),1,0) | AJ7: =IF(AND(8>=1,8<=Assumptions!$D$7),1,0) | AK7: =IF(AND(8>=1,8<=Assumptions!$D$7),1,0) | AL7: =IF(AND(8>=1,8<=Assumptions!$D$7),1,0) | AM7: =IF(AND(9>=1,9<=Assumptions!$D$7),1,0) | AN7: =IF(AND(9>=1,9<=Assumptions!$D$7),1,0) | AO7: =IF(AND(9>=1,9<=Assumptions!$D$7),1,0) | AP7: =IF(AND(9>=1,9<=Assumptions!$D$7),1,0) | AQ7: =IF(AND(10>=1,10<=Assumptions!$D$7),1,0)
B9: Quarterly NOI | C9: =INDEX(OpEx_CapEx!$D$9:$N$9,1,1)/4*C7 | D9: =INDEX(OpEx_CapEx!$D$9:$N$9,1,1)/4*D7 | E9: =INDEX(OpEx_CapEx!$D$9:$N$9,1,1)/4*E7 | F9: =INDEX(OpEx_CapEx!$D$9:$N$9,1,1)/4*F7 | G9: =INDEX(OpEx_CapEx!$D$9:$N$9,1,2)/4*G7 | H9: =INDEX(OpEx_CapEx!$D$9:$N$9,1,2)/4*H7 | I9: =INDEX(OpEx_CapEx!$D$9:$N$9,1,2)/4*I7 | J9: =INDEX(OpEx_CapEx!$D$9:$N$9,1,2)/4*J7 | K9: =INDEX(OpEx_CapEx!$D$9:$N$9,1,3)/4*K7 | L9: =INDEX(OpEx_CapEx!$D$9:$N$9,1,3)/4*L7 | M9: =INDEX(OpEx_CapEx!$D$9:$N$9,1,3)/4*M7 | N9: =INDEX(OpEx_CapEx!$D$9:$N$9,1,3)/4*N7 | O9: =INDEX(OpEx_CapEx!$D$9:$N$9,1,4)/4*O7 | P9: =INDEX(OpEx_CapEx!$D$9:$N$9,1,4)/4*P7 | Q9: =INDEX(OpEx_CapEx!$D$9:$N$9,1,4)/4*Q7 | R9: =INDEX(OpEx_CapEx!$D$9:$N$9,1,4)/4*R7 | S9: =INDEX(OpEx_CapEx!$D$9:$N$9,1,5)/4*S7 | T9: =INDEX(OpEx_CapEx!$D$9:$N$9,1,5)/4*T7 | U9: =INDEX(OpEx_CapEx!$D$9:$N$9,1,5)/4*U7 | V9: =INDEX(OpEx_CapEx!$D$9:$N$9,1,5)/4*V7 | W9: =INDEX(OpEx_CapEx!$D$9:$N$9,1,6)/4*W7 | X9: =INDEX(OpEx_CapEx!$D$9:$N$9,1,6)/4*X7 | Y9: =INDEX(OpEx_CapEx!$D$9:$N$9,1,6)/4*Y7 | Z9: =INDEX(OpEx_CapEx!$D$9:$N$9,1,6)/4*Z7 | AA9: =INDEX(OpEx_CapEx!$D$9:$N$9,1,7)/4*AA7 | AB9: =INDEX(OpEx_CapEx!$D$9:$N$9,1,7)/4*AB7 | AC9: =INDEX(OpEx_CapEx!$D$9:$N$9,1,7)/4*AC7 | AD9: =INDEX(OpEx_CapEx!$D$9:$N$9,1,7)/4*AD7 | AE9: =INDEX(OpEx_CapEx!$D$9:$N$9,1,8)/4*AE7 | AF9: =INDEX(OpEx_CapEx!$D$9:$N$9,1,8)/4*AF7 | AG9: =INDEX(OpEx_CapEx!$D$9:$N$9,1,8)/4*AG7 | AH9: =INDEX(OpEx_CapEx!$D$9:$N$9,1,8)/4*AH7 | AI9: =INDEX(OpEx_CapEx!$D$9:$N$9,1,9)/4*AI7 | AJ9: =INDEX(OpEx_CapEx!$D$9:$N$9,1,9)/4*AJ7 | AK9: =INDEX(OpEx_CapEx!$D$9:$N$9,1,9)/4*AK7 | AL9: =INDEX(OpEx_CapEx!$D$9:$N$9,1,9)/4*AL7 | AM9: =INDEX(OpEx_CapEx!$D$9:$N$9,1,10)/4*AM7 | AN9: =INDEX(OpEx_CapEx!$D$9:$N$9,1,10)/4*AN7 | AO9: =INDEX(OpEx_CapEx!$D$9:$N$9,1,10)/4*AO7 | AP9: =INDEX(OpEx_CapEx!$D$9:$N$9,1,10)/4*AP7 | AQ9: =INDEX(OpEx_CapEx!$D$9:$N$9,1,11)/4*AQ7
B10: Debt balance (period-start) | C10: =INDEX(Debt!$D$5:$N$5,1,1) | D10: =INDEX(Debt!$D$5:$N$5,1,1) | E10: =INDEX(Debt!$D$5:$N$5,1,1) | F10: =INDEX(Debt!$D$5:$N$5,1,1) | G10: =INDEX(Debt!$D$5:$N$5,1,2) | H10: =INDEX(Debt!$D$5:$N$5,1,2) | I10: =INDEX(Debt!$D$5:$N$5,1,2) | J10: =INDEX(Debt!$D$5:$N$5,1,2) | K10: =INDEX(Debt!$D$5:$N$5,1,3) | L10: =INDEX(Debt!$D$5:$N$5,1,3) | M10: =INDEX(Debt!$D$5:$N$5,1,3) | N10: =INDEX(Debt!$D$5:$N$5,1,3) | O10: =INDEX(Debt!$D$5:$N$5,1,4) | P10: =INDEX(Debt!$D$5:$N$5,1,4) | Q10: =INDEX(Debt!$D$5:$N$5,1,4) | R10: =INDEX(Debt!$D$5:$N$5,1,4) | S10: =INDEX(Debt!$D$5:$N$5,1,5) | T10: =INDEX(Debt!$D$5:$N$5,1,5) | U10: =INDEX(Debt!$D$5:$N$5,1,5) | V10: =INDEX(Debt!$D$5:$N$5,1,5) | W10: =INDEX(Debt!$D$5:$N$5,1,6) | X10: =INDEX(Debt!$D$5:$N$5,1,6) | Y10: =INDEX(Debt!$D$5:$N$5,1,6) | Z10: =INDEX(Debt!$D$5:$N$5,1,6) | AA10: =INDEX(Debt!$D$5:$N$5,1,7) | AB10: =INDEX(Debt!$D$5:$N$5,1,7) | AC10: =INDEX(Debt!$D$5:$N$5,1,7) | AD10: =INDEX(Debt!$D$5:$N$5,1,7) | AE10: =INDEX(Debt!$D$5:$N$5,1,8) | AF10: =INDEX(Debt!$D$5:$N$5,1,8) | AG10: =INDEX(Debt!$D$5:$N$5,1,8) | AH10: =INDEX(Debt!$D$5:$N$5,1,8) | AI10: =INDEX(Debt!$D$5:$N$5,1,9) | AJ10: =INDEX(Debt!$D$5:$N$5,1,9) | AK10: =INDEX(Debt!$D$5:$N$5,1,9) | AL10: =INDEX(Debt!$D$5:$N$5,1,9) | AM10: =INDEX(Debt!$D$5:$N$5,1,10) | AN10: =INDEX(Debt!$D$5:$N$5,1,10) | AO10: =INDEX(Debt!$D$5:$N$5,1,10) | AP10: =INDEX(Debt!$D$5:$N$5,1,10) | AQ10: =INDEX(Debt!$D$5:$N$5,1,11)
B11: Quarterly interest | C11: =C10*Assumptions!$D$42/4*C7 | D11: =D10*Assumptions!$D$42/4*D7 | E11: =E10*Assumptions!$D$42/4*E7 | F11: =F10*Assumptions!$D$42/4*F7 | G11: =G10*Assumptions!$D$42/4*G7 | H11: =H10*Assumptions!$D$42/4*H7 | I11: =I10*Assumptions!$D$42/4*I7 | J11: =J10*Assumptions!$D$42/4*J7 | ... AQ11: =AQ10*Assumptions!$D$42/4*AQ7
B12: Quarterly principal (scheduled) | C12: =IFERROR(INDEX(Debt!$D$7:$N$7,1,1)/4,0)*C7 | D12: =IFERROR(INDEX(Debt!$D$7:$N$7,1,1)/4,0)*D7 | E12: =IFERROR(INDEX(Debt!$D$7:$N$7,1,1)/4,0)*E7 | F12: =IFERROR(INDEX(Debt!$D$7:$N$7,1,1)/4,0)*F7 | G12: =IFERROR(INDEX(Debt!$D$7:$N$7,1,2)/4,0)*G7 | H12: =IFERROR(INDEX(Debt!$D$7:$N$7,1,2)/4,0)*H7 | I12: =IFERROR(INDEX(Debt!$D$7:$N$7,1,2)/4,0)*I7 | J12: =IFERROR(INDEX(Debt!$D$7:$N$7,1,2)/4,0)*J7 | K12: =IFERROR(INDEX(Debt!$D$7:$N$7,1,3)/4,0)*K7 | L12: =IFERROR(INDEX(Debt!$D$7:$N$7,1,3)/4,0)*L7 | M12: =IFERROR(INDEX(Debt!$D$7:$N$7,1,3)/4,0)*M7 | N12: =IFERROR(INDEX(Debt!$D$7:$N$7,1,3)/4,0)*N7 | O12: =IFERROR(INDEX(Debt!$D$7:$N$7,1,4)/4,0)*O7 | P12: =IFERROR(INDEX(Debt!$D$7:$N$7,1,4)/4,0)*P7 | Q12: =IFERROR(INDEX(Debt!$D$7:$N$7,1,4)/4,0)*Q7 | R12: =IFERROR(INDEX(Debt!$D$7:$N$7,1,4)/4,0)*R7 | S12: =IFERROR(INDEX(Debt!$D$7:$N$7,1,5)/4,0)*S7 | T12: =IFERROR(INDEX(Debt!$D$7:$N$7,1,5)/4,0)*T7 | U12: =IFERROR(INDEX(Debt!$D$7:$N$7,1,5)/4,0)*U7 | V12: =IFERROR(INDEX(Debt!$D$7:$N$7,1,5)/4,0)*V7 | W12: =IFERROR(INDEX(Debt!$D$7:$N$7,1,6)/4,0)*W7 | X12: =IFERROR(INDEX(Debt!$D$7:$N$7,1,6)/4,0)*X7 | Y12: =IFERROR(INDEX(Debt!$D$7:$N$7,1,6)/4,0)*Y7 | Z12: =IFERROR(INDEX(Debt!$D$7:$N$7,1,6)/4,0)*Z7 | AA12: =IFERROR(INDEX(Debt!$D$7:$N$7,1,7)/4,0)*AA7 | AB12: =IFERROR(INDEX(Debt!$D$7:$N$7,1,7)/4,0)*AB7 | AC12: =IFERROR(INDEX(Debt!$D$7:$N$7,1,7)/4,0)*AC7 | AD12: =IFERROR(INDEX(Debt!$D$7:$N$7,1,7)/4,0)*AD7 | AE12: =IFERROR(INDEX(Debt!$D$7:$N$7,1,8)/4,0)*AE7 | AF12: =IFERROR(INDEX(Debt!$D$7:$N$7,1,8)/4,0)*AF7 | AG12: =IFERROR(INDEX(Debt!$D$7:$N$7,1,8)/4,0)*AG7 | AH12: =IFERROR(INDEX(Debt!$D$7:$N$7,1,8)/4,0)*AH7 | AI12: =IFERROR(INDEX(Debt!$D$7:$N$7,1,9)/4,0)*AI7 | AJ12: =IFERROR(INDEX(Debt!$D$7:$N$7,1,9)/4,0)*AJ7 | AK12: =IFERROR(INDEX(Debt!$D$7:$N$7,1,9)/4,0)*AK7 | AL12: =IFERROR(INDEX(Debt!$D$7:$N$7,1,9)/4,0)*AL7 | AM12: =IFERROR(INDEX(Debt!$D$7:$N$7,1,10)/4,0)*AM7 | AN12: =IFERROR(INDEX(Debt!$D$7:$N$7,1,10)/4,0)*AN7 | AO12: =IFERROR(INDEX(Debt!$D$7:$N$7,1,10)/4,0)*AO7 | AP12: =IFERROR(INDEX(Debt!$D$7:$N$7,1,10)/4,0)*AP7 | AQ12: =IFERROR(INDEX(Debt!$D$7:$N$7,1,11)/4,0)*AQ7
B13: Bullet repayment at exit | C13: 0 | D13: 0 | E13: 0 | F13: 0 | G13: 0 | H13: 0 | I13: 0 | J13: 0 | K13: 0 | L13: 0 | M13: 0 | N13: 0 | O13: 0 | P13: 0 | Q13: 0 | R13: 0 | S13: 0 | T13: 0 | U13: 0 | V13: 0 | W13: 0 | X13: 0 | Y13: 0 | Z13: 0 | AA13: 0 | AB13: 0 | AC13: 0 | AD13: 0 | AE13: 0 | AF13: 0 | AG13: 0 | AH13: 0 | AI13: 0 | AJ13: 0 | AK13: 0 | AL13: 0 | AM13: 0 | AN13: 0 | AO13: 0 | AP13: 0 | AQ13: =INDEX(Debt!$D$8:$N$8,1,Assumptions!$D$7+1)
B14: Total quarterly debt service | C14: =ABS(C11)+ABS(C12)+ABS(C13) | D14: =ABS(D11)+ABS(D12)+ABS(D13) | E14: =ABS(E11)+ABS(E12)+ABS(E13) | F14: =ABS(F11)+ABS(F12)+ABS(F13) | G14: =ABS(G11)+ABS(G12)+ABS(G13) | H14: =ABS(H11)+ABS(H12)+ABS(H13) | I14: =ABS(I11)+ABS(I12)+ABS(I13) | J14: =ABS(J11)+ABS(J12)+ABS(J13) | ... AQ14: =ABS(AQ11)+ABS(AQ12)+ABS(AQ13)
B16: Quarterly DSCR (excl. bullet) | C16: =IFERROR(IF(ABS(C11)+ABS(C12)=0,"-",C9/(ABS(C11)+ABS(C12))),"-") | D16: =IFERROR(IF(ABS(D11)+ABS(D12)=0,"-",D9/(ABS(D11)+ABS(D12))),"-") | E16: =IFERROR(IF(ABS(E11)+ABS(E12)=0,"-",E9/(ABS(E11)+ABS(E12))),"-") | F16: =IFERROR(IF(ABS(F11)+ABS(F12)=0,"-",F9/(ABS(F11)+ABS(F12))),"-") | G16: =IFERROR(IF(ABS(G11)+ABS(G12)=0,"-",G9/(ABS(G11)+ABS(G12))),"-") | H16: =IFERROR(IF(ABS(H11)+ABS(H12)=0,"-",H9/(ABS(H11)+ABS(H12))),"-") | I16: =IFERROR(IF(ABS(I11)+ABS(I12)=0,"-",I9/(ABS(I11)+ABS(I12))),"-") | J16: =IFERROR(IF(ABS(J11)+ABS(J12)=0,"-",J9/(ABS(J11)+ABS(J12))),"-") | ... AQ16: =IFERROR(IF(ABS(AQ11)+ABS(AQ12)=0,"-",AQ9/(ABS(AQ11)+ABS(AQ12))),"-")
B17: Quarterly covenant test (≥ 1.30x) | C17: =IFERROR(IF(C16="-","-",IF(C16>=Assumptions!$D$73,"PASS","BREACH")),"-") | D17: =IFERROR(IF(D16="-","-",IF(D16>=Assumptions!$D$73,"PASS","BREACH")),"-") | E17: =IFERROR(IF(E16="-","-",IF(E16>=Assumptions!$D$73,"PASS","BREACH")),"-") | F17: =IFERROR(IF(F16="-","-",IF(F16>=Assumptions!$D$73,"PASS","BREACH")),"-") | G17: =IFERROR(IF(G16="-","-",IF(G16>=Assumptions!$D$73,"PASS","BREACH")),"-") | H17: =IFERROR(IF(H16="-","-",IF(H16>=Assumptions!$D$73,"PASS","BREACH")),"-") | I17: =IFERROR(IF(I16="-","-",IF(I16>=Assumptions!$D$73,"PASS","BREACH")),"-") | J17: =IFERROR(IF(J16="-","-",IF(J16>=Assumptions!$D$73,"PASS","BREACH")),"-") | ... AQ17: =IFERROR(IF(AQ16="-","-",IF(AQ16>=Assumptions!$D$73,"PASS","BREACH")),"-")
B19: Min quarterly DSCR | C19: =MIN(C16:AQ16)
B20: Quarters in breach | C20: =COUNTIF(C17:AQ17,"BREACH")

Sheet Refinance
B2: REFINANCING MODULE — institutional treatment of bullet exit
B3: Models a single refinancing event during hold. When ON, bullet at original maturity is replaced by amortizing/bullet refi; remaining principal at exit is repaid from sale proceeds.
B5: Refi switch | D5: =Assumptions!$D$79
B6: Refi year (Yn) | D6: =Assumptions!$D$80
B7: Property value at refi (Y_refi NOI / exit cap proxy) | D7: =IFERROR(INDEX(OpEx_CapEx!E9:N9,1,Assumptions!$D$80)/Assumptions!$D$51,0)
B8: Refi LTV | D8: =Assumptions!$D$81
B9: New debt size | D9: =D7*D8
B10: Existing debt outstanding at refi | D10: =IFERROR(INDEX(Debt!D9:N9,1,Assumptions!$D$80+1),0)
B11: Refi cash inflow / (paydown) | D11: =IF(D5=1,D9-D10,0)
B12: Refi fee (one-off) | D12: =IF(D5=1,-D9*Assumptions!$D$85,0)
B13: Refi cost of debt | D13: =Assumptions!$D$82
B14: Refi tenor (yrs) | D14: =Assumptions!$D$83
B15: Refi amortization | D15: =IF(Assumptions!$D$84=1,"AMORT","BULLET")
B17: REFINANCED-LOAN ANNUAL SCHEDULE
B18: Metric | C18: Y0 | D18: Y1 | E18: Y2 | F18: Y3 | G18: Y4 | H18: Y5 | I18: Y6 | J18: Y7 | K18: Y8 | L18: Y9 | M18: Y10
D19: 0 | E19: =IF(D5=0,0,IF(1=D6,D9,IF(1>D6,MAX(0,D19+D21+D22),0))) | F19: =IF(D5=0,0,IF(2=D6,D9,IF(2>D6,MAX(0,E19+E21+E22),0))) | G19: =IF(D5=0,0,IF(3=D6,D9,IF(3>D6,MAX(0,F19+F21+F22),0))) | H19: =IF(D5=0,0,IF(4=D6,D9,IF(4>D6,MAX(0,G19+G21+G22),0))) | I19: =IF(D5=0,0,IF(5=D6,D9,IF(5>D6,MAX(0,H19+H21+H22),0))) | J19: =IF(D5=0,0,IF(6=D6,D9,IF(6>D6,MAX(0,I19+I21+I22),0))) | K19: =IF(D5=0,0,IF(7=D6,D9,IF(7>D6,MAX(0,J19+J21+J22),0))) | L19: =IF(D5=0,0,IF(8=D6,D9,IF(8>D6,MAX(0,K19+K21+K22),0))) | M19: =IF(D5=0,0,IF(9=D6,D9,IF(9>D6,MAX(0,L19+L21+L22),0))) | N19: =IF(D5=0,0,IF(10=D6,D9,IF(10>D6,MAX(0,M19+M21+M22),0)))
B20: Drawdown / (paydown) at refi | D20: =IF(AND(D5=1,0=D6),D9,0) | E20: =IF(AND(D5=1,1=D6),D9,0) | F20: =IF(AND(D5=1,2=D6),D9,0) | G20: =IF(AND(D5=1,3=D6),D9,0) | H20: =IF(AND(D5=1,4=D6),D9,0) | I20: =IF(AND(D5=1,5=D6),D9,0) | J20: =IF(AND(D5=1,6=D6),D9,0) | K20: =IF(AND(D5=1,7=D6),D9,0) | L20: =IF(AND(D5=1,8=D6),D9,0) | M20: =IF(AND(D5=1,9=D6),D9,0) | N20: =IF(AND(D5=1,10=D6),D9,0)
B21: Refi scheduled principal | D21: =IF(AND(D5=1,Assumptions!$D$84=1,0>D6,0<Assumptions!$D$7,D14>0),-D9/D14,0) | E21: =IF(AND(D5=1,Assumptions!$D$84=1,1>D6,1<Assumptions!$D$7,D14>0),-D9/D14,0) | F21: =IF(AND(D5=1,Assumptions!$D$84=1,2>D6,2<Assumptions!$D$7,D14>0),-D9/D14,0) | G21: =IF(AND(D5=1,Assumptions!$D$84=1,3>D6,3<Assumptions!$D$7,D14>0),-D9/D14,0) | H21: =IF(AND(D5=1,Assumptions!$D$84=1,4>D6,4<Assumptions!$D$7,D14>0),-D9/D14,0) | I21: =IF(AND(D5=1,Assumptions!$D$84=1,5>D6,5<Assumptions!$D$7,D14>0),-D9/D14,0) | J21: =IF(AND(D5=1,Assumptions!$D$84=1,6>D6,6<Assumptions!$D$7,D14>0),-D9/D14,0) | K21: =IF(AND(D5=1,Assumptions!$D$84=1,7>D6,7<Assumptions!$D$7,D14>0),-D9/D14,0) | L21: =IF(AND(D5=1,Assumptions!$D$84=1,8>D6,8<Assumptions!$D$7,D14>0),-D9/D14,0) | M21: =IF(AND(D5=1,Assumptions!$D$84=1,9>D6,9<Assumptions!$D$7,D14>0),-D9/D14,0) | N21: =IF(AND(D5=1,Assumptions!$D$84=1,10>D6,10<Assumptions!$D$7,D14>0),-D9/D14,0)
B22: Refi bullet at exit | D22: 0 | E22: =IF(AND(D5=1,1=Assumptions!$D$7),-MAX(0,D19+D20+D21),0) | F22: =IF(AND(D5=1,2=Assumptions!$D$7),-MAX(0,E19+E20+E21),0) | G22: =IF(AND(D5=1,3=Assumptions!$D$7),-MAX(0,F19+F20+F21),0) | H22: =IF(AND(D5=1,4=Assumptions!$D$7),-MAX(0,G19+G20+G21),0) | I22: =IF(AND(D5=1,5=Assumptions!$D$7),-MAX(0,H19+H20+H21),0) | J22: =IF(AND(D5=1,6=Assumptions!$D$7),-MAX(0,I19+I20+I21),0) | K22: =IF(AND(D5=1,7=Assumptions!$D$7),-MAX(0,J19+J20+J21),0) | L22: =IF(AND(D5=1,8=Assumptions!$D$7),-MAX(0,K19+K20+K21),0) | M22: =IF(AND(D5=1,9=Assumptions!$D$7),-MAX(0,L19+L20+L21),0) | N22: =IF(AND(D5=1,10=Assumptions!$D$7),-MAX(0,M19+M20+M21),0)
B23: Refi interest expense | D23: 0 | E23: =IF(D5=1,-D19*D13,0) | F23: =IF(D5=1,-E19*D13,0) | G23: =IF(D5=1,-F19*D13,0) | H23: =IF(D5=1,-G19*D13,0) | I23: =IF(D5=1,-H19*D13,0) | J23: =IF(D5=1,-I19*D13,0) | K23: =IF(D5=1,-J19*D13,0) | L23: =IF(D5=1,-K19*D13,0) | M23: =IF(D5=1,-L19*D13,0) | N23: =IF(D5=1,-M19*D13,0)
B25: REFINANCED-LOAN DSCR (NOI − CapEx) / |Refi debt service|
E26: =IFERROR(IF(D5=0,"-",IF(ABS(E23)+ABS(E21)=0,"-",(OpEx_CapEx!E9+OpEx_CapEx!E23)/(ABS(E23)+ABS(E21)))),"-") | F26: =IFERROR(IF(D5=0,"-",IF(ABS(F23)+ABS(F21)=0,"-",(OpEx_CapEx!F9+OpEx_CapEx!F23)/(ABS(F23)+ABS(F21)))),"-") | G26: =IFERROR(IF(D5=0,"-",IF(ABS(G23)+ABS(G21)=0,"-",(OpEx_CapEx!G9+OpEx_CapEx!G23)/(ABS(G23)+ABS(G21)))),"-") | H26: =IFERROR(IF(D5=0,"-",IF(ABS(H23)+ABS(H21)=0,"-",(OpEx_CapEx!H9+OpEx_CapEx!H23)/(ABS(H23)+ABS(H21)))),"-") | I26: =IFERROR(IF(D5=0,"-",IF(ABS(I23)+ABS(I21)=0,"-",(OpEx_CapEx!I9+OpEx_CapEx!I23)/(ABS(I23)+ABS(I21)))),"-") | J26: =IFERROR(IF(D5=0,"-",IF(ABS(J23)+ABS(J21)=0,"-",(OpEx_CapEx!J9+OpEx_CapEx!J23)/(ABS(J23)+ABS(J21)))),"-") | K26: =IFERROR(IF(D5=0,"-",IF(ABS(K23)+ABS(K21)=0,"-",(OpEx_CapEx!K9+OpEx_CapEx!K23)/(ABS(K23)+ABS(K21)))),"-") | L26: =IFERROR(IF(D5=0,"-",IF(ABS(L23)+ABS(L21)=0,"-",(OpEx_CapEx!L9+OpEx_CapEx!L23)/(ABS(L23)+ABS(L21)))),"-") | M26: =IFERROR(IF(D5=0,"-",IF(ABS(M23)+ABS(M21)=0,"-",(OpEx_CapEx!M9+OpEx_CapEx!M23)/(ABS(M23)+ABS(M21)))),"-") | N26: =IFERROR(IF(D5=0,"-",IF(ABS(N23)+ABS(N21)=0,"-",(OpEx_CapEx!N9+OpEx_CapEx!N23)/(ABS(N23)+ABS(N21)))),"-")
B27: Refi total debt service (cash out) | D27: =D23+D21+D22 | E27: =E23+E21+E22 | F27: =F23+F21+F22 | G27: =G23+G21+G22 | H27: =H23+H21+H22 | I27: =I23+I21+I22 | J27: =J23+J21+J22 | K27: =K23+K21+K22 | ... N27: =N23+N21+N22
B29: Net refi cash to equity (drawdown − paydown − fee) | D29: =IF(AND(D5=1,0=D6),D11+D12,0) | E29: =IF(AND(D5=1,1=D6),D11+D12,0) | F29: =IF(AND(D5=1,2=D6),D11+D12,0) | G29: =IF(AND(D5=1,3=D6),D11+D12,0) | H29: =IF(AND(D5=1,4=D6),D11+D12,0) | I29: =IF(AND(D5=1,5=D6),D11+D12,0) | J29: =IF(AND(D5=1,6=D6),D11+D12,0) | K29: =IF(AND(D5=1,7=D6),D11+D12,0) | L29: =IF(AND(D5=1,8=D6),D11+D12,0) | M29: =IF(AND(D5=1,9=D6),D11+D12,0) | N29: =IF(AND(D5=1,10=D6),D11+D12,0)

Sheet Reserves
B2: RESERVE ACCOUNTS — institutional liquidity stack
B3: Required liquidity at closing and minimum runway during operations.
B5: INITIAL FUNDING AT CLOSING (Y0)
B6: Annual debt service (Y1, approx) | D6: =ABS(Debt!E12)
