Workbook

Sheet Cover
B2: BIN AMER HOLDING — INVESTMENT UNDERWRITING MODEL v4
B4: Document | C4: Institutional-grade real estate / income-asset underwriting model
B5: Prepared for | C5: Investment Committee / Bank / JV Partner Review
B6: Currency | C6: SAR (Saudi Riyal) unless stated
B7: Periodicity | C7: Annual, Y0 (closing) + Y1–Y10 (operating)
B8: Version | C8: v4.0 — Institutional Rebuild
B10: COLOR-CODING CONVENTIONS
B11: BLUE | C11: Hardcoded user input
B12: BLACK | C12: Formula / calculation
B13: GREEN | C13: Cross-sheet link
B14: YELLOW fill | C14: Key assumption requiring management sign-off
B15: YELLOW fill | C15: Warning / negative result / audit error
B17: SHEET MAP
B18: Assumptions | C18: Single source of truth for all hardcoded inputs
B19: Timeline | C19: Period flags, calendar years, operating-year switches
B20: Revenue | C20: Gross revenue, vacancy, EGI build-up
B21: OpEx_CapEx | C21: Operating expense build, maintenance + refurbishment CapEx
B22: Debt | C22: Amortization OR bullet schedule, ICR, DSCR per year
B23: Tax | C23: Zakat, corporate tax, withholding, disposal tax
B24: Cash_Flow | C24: Layered: NOI → EBITDA → EBT → Project FCF → Equity FCF
B25: DCF | C25: Unlevered DCF using exit-cap terminal value (no double-count)
B26: Returns | C26: IRR, NPV, MOIC, DSCR, LTV, debt yield, payback, CoC
B27: Scenarios | C27: Base / Downside / Severe / Upside cases
B28: Sensitivity | C28: Two-variable sensitivities on key drivers
B29: Audit | C29: Integrity, sign convention, balance, reconciliation checks
B30: Dashboard | C30: IC-ready executive summary
B32: KEY MODEL CHANGES vs v3 (read before use)
B33: 1. | C33: Removed Gordon-Growth terminal value — was double-counted with Exit Cap Value.
B34: 2. | C34: Exit Value now uses FORWARD NOI net of disposal costs (broker + legal).
B35: 3. | C35: True NOI line now excludes fund/admin/custodian fees (moved below to corporate).
B36: 4. | C36: Full annual debt schedule with amortization OR bullet toggle; DSCR computed per year.
B37: 5. | C37: Zakat, corporate tax, and withholding tax now flow through cash flow and IRR.
B38: 6. | C38: Maintenance CapEx and periodic refurbishment CapEx modelled separately.
B39: 7. | C39: Y0/Y1 timing corrected: Y0 = closing year (outflow), Y1 = first operating year.
B40: 8. | C40: Project IRR/NPV use Project FCF; Equity IRR/NPV use Equity FCF after debt + tax.
B41: 9. | C41: Audit sheet flags any structural error with OK / ERROR status.
B42: 10. | C42: Sensitivity tables for cap rate, vacancy, revenue growth, interest rate, OpEx.

Sheet Assumptions
B2: ASSUMPTIONS — Single Source of Truth
B3: Blue = input. Yellow fill = high-impact assumption. All cells outside the input column should be empty or formula-driven.
B5: 1. PROJECT TIMELINE
B6: Investment closing year (Y0) | D6: 2025 | E6: year | F6: Capital deployed at start of this year
B7: Holding period (operating years) | D7: 10 | E7: yrs | F7: Y1..Y_hold years of operation
B8: Exit calendar year | D8: =Assumptions!$D$6+Assumptions!$D$7 -> 2035 | E8: year | F8: Calculated
B10: 2. PROJECT COST & ACQUISITION
B11: Asset purchase price | D11: 200000000 | E11: SAR | F11: Pre-fee asset price
B12: RETT (Real Estate Transaction Tax) | D12: 0.05 | E12: % | F12: Saudi RETT — confirm current rate
B13: Acquisition broker / agency | D13: 0.025 | E13: % | F13: % of purchase price
B14: Acquisition / DD / legal fee | D14: 0.0025 | E14: % | F14: Advisory + legal
B15: Sum of acquisition costs (%) | D15: =Assumptions!$D$12+Assumptions!$D$13+Assumptions!$D$14 -> 0.0775 | E15: % | F15: Calculated
B16: Total project cost (incl. fees) | D16: =Assumptions!$D$11*(1+Assumptions!$D$15) -> 2.155e+08 | E16: SAR | F16: Calculated
B18: 3. REVENUE
B19: Year 1 gross revenue (stabilised) | D19: 15000000 | E19: SAR | F19: First full operating year revenue
B20: Revenue growth rate (annualised) | D20: 0.03 | E20: % | F20: Effective annual growth
B21: Escalation frequency | D21: 2 | E21: yrs | F21: 1 = annual; 2 = biennial; etc.
B22: Vacancy / collection loss | D22: 0.05 | E22: % | F22: % of gross revenue lost; v3 used 0% — institutional minimum 3-5%
B24: 4. OPERATING EXPENSES (asset level)
B25: OpEx (% of EGI) | D25: 0.05 | E25: % | F25: True asset operating costs — maintenance, utilities, insurance, sec.
B26: Property / municipal tax | D26: 0 | E26: % | F26: % of EGI — adjust to local regime
B27: OpEx inflation | D27: 0.03 | E27: % | F27: Annual cost inflation
B29: 5. CORPORATE / FUND COSTS (below NOI)
B30: Asset management fee (% NAV) | D30: 0.003 | E30: % | F30: 0 if self-managed; NAV-based
B31: Custodian fee (% NAV) | D31: 0.0004 | E31: % | F31: Third-party custody
B32: Fund admin fee (% NAV) | D32: 0.0005 | E32: % | F32: Accounting/admin
B33: Other fixed annual expenses | D33: 285000 | E33: SAR | F33: Audit, legal, board
B35: 6. CAPITAL EXPENDITURE
B36: Maintenance CapEx (% of EGI) | D36: 0.015 | E36: % | F36: Institutional norm 1-2% for stabilized assets — v3 used 0%
B37: Major refurbishment amount | D37: 3000000 | E37: SAR | F37: Cyclical major refurb (one-off)
B38: Refurbishment year (Yn) | D38: 5 | E38: Yn | F38: Year of major refurb
B40: 7. FINANCING / DEBT
B41: Debt ratio (% of total cost) | D41: 0.5 | E41: % | F41: Set 0% for all-equity
B42: Cost of debt (annual) | D42: 0.07 | E42: % | F42: All-in rate
B43: Debt arrangement fee (one-off) | D43: 0.0025 | E43: % | F43: % of debt; paid Y0
B44: Amortization (1=AMORT, 0=BULLET) | D44: 0 | E44: flag | F44: 1 = amortizing over tenor; 0 = bullet at exit
B45: Debt tenor (years) | D45: 10 | E45: yrs | F45: Amortization tenor
B46: Grace period (years, interest-only) | D46: 1 | E46: yrs | F46: Interest-only years
B47: Debt amount | D47: =Assumptions!$D$16*Assumptions!$D$41 -> 1.0775e+08 | E47: SAR | F47: Calculated
B48: Equity required | D48: =Assumptions!$D$16*(1-Assumptions!$D$41) -> 1.0775e+08 | E48: SAR | F48: Calculated
...

Sheet Timeline
B2: TIMELINE & PERIOD FLAGS
B3: Period | D3: 0 | E3: 1 | F3: 2 | G3: 3 | H3: 4 | I3: 5 | J3: 6 | K3: 7 | L3: 8 | M3: 9 | N3: 10
B4: Year | D4: =Assumptions!$D$6+0 -> 2025 | E4: =Assumptions!$D$6+1 -> 2026 | F4: =Assumptions!$D$6+2 -> 2027 | G4: =Assumptions!$D$6+3 -> 2028 | H4: =Assumptions!$D$6+4 -> 2029 | I4: =Assumptions!$D$6+5 -> 2030 | J4: =Assumptions!$D$6+6 -> 2031 | K4: =Assumptions!$D$6+7 -> 2032 | L4: =Assumptions!$D$6+8 -> 2033 | M4: =Assumptions!$D$6+9 -> 2034 | N4: =Assumptions!$D$6+10 -> 2035
B5: Operating year flag | D5: 0 | E5: =IF(1<=Assumptions!$D$7,1,0) -> 1 | F5: =IF(2<=Assumptions!$D$7,1,0) -> 1 | G5: =IF(3<=Assumptions!$D$7,1,0) -> 1 | H5: =IF(4<=Assumptions!$D$7,1,0) -> 1 | I5: =IF(5<=Assumptions!$D$7,1,0) -> 1 | J5: =IF(6<=Assumptions!$D$7,1,0) -> 1 | K5: =IF(7<=Assumptions!$D$7,1,0) -> 1 | L5: =IF(8<=Assumptions!$D$7,1,0) -> 1 | M5: =IF(9<=Assumptions!$D$7,1,0) -> 1 | N5: =IF(10<=Assumptions!$D$7,1,0) -> 1
B6: Exit year flag | D6: =IF(0=Assumptions!$D$7,1,0) -> 0 | E6: =IF(1=Assumptions!$D$7,1,0) -> 0 | F6: =IF(2=Assumptions!$D$7,1,0) -> 0 | G6: =IF(3=Assumptions!$D$7,1,0) -> 0 | H6: =IF(4=Assumptions!$D$7,1,0) -> 0 | I6: =IF(5=Assumptions!$D$7,1,0) -> 0 | J6: =IF(6=Assumptions!$D$7,1,0) -> 0 | K6: =IF(7=Assumptions!$D$7,1,0) -> 0 | L6: =IF(8=Assumptions!$D$7,1,0) -> 0 | M6: =IF(9=Assumptions!$D$7,1,0) -> 0 | N6: =IF(10=Assumptions!$D$7,1,0) -> 1
B7: Escalation step flag (0/1) | D7: 0 | E7: 0 | F7: =IF(Assumptions!$D$21=0,0,IF(MOD(2-1,Assumptions!$D$21)=0,1,0)) -> 0 | G7: =IF(Assumptions!$D$21=0,0,IF(MOD(3-1,Assumptions!$D$21)=0,1,0)) -> 1 | H7: =IF(Assumptions!$D$21=0,0,IF(MOD(4-1,Assumptions!$D$21)=0,1,0)) -> 0 | I7: =IF(Assumptions!$D$21=0,0,IF(MOD(5-1,Assumptions!$D$21)=0,1,0)) -> 1 | J7: =IF(Assumptions!$D$21=0,0,IF(MOD(6-1,Assumptions!$D$21)=0,1,0)) -> 0 | K7: =IF(Assumptions!$D$21=0,0,IF(MOD(7-1,Assumptions!$D$21)=0,1,0)) -> 1 | L7: =IF(Assumptions!$D$21=0,0,IF(MOD(8-1,Assumptions!$D$21)=0,1,0)) -> 0 | M7: =IF(Assumptions!$D$21=0,0,IF(MOD(9-1,Assumptions!$D$21)=0,1,0)) -> 1 | N7: =IF(Assumptions!$D$21=0,0,IF(MOD(10-1,Assumptions!$D$21)=0,1,0)) -> 0
B8: Cumulative escalation factor | D8: 1 | E8: 1 | F8: =E8*(1+F7*Assumptions!$D$20) -> 1 | G8: =F8*(1+G7*Assumptions!$D$20) -> 1.03 | H8: =G8*(1+H7*Assumptions!$D$20) -> 1.03 | I8: =H8*(1+I7*Assumptions!$D$20) -> 1.0609 | J8: =I8*(1+J7*Assumptions!$D$20) -> 1.0609 | K8: =J8*(1+K7*Assumptions!$D$20) -> 1.092727 | L8: =K8*(1+L7*Assumptions!$D$20) -> 1.092727 | M8: =L8*(1+M7*Assumptions!$D$20) -> 1.1255088 | N8: =M8*(1+N7*Assumptions!$D$20) -> 1.1255088
B9: OpEx inflation factor | D9: 1 | E9: 1 | F9: =E9*(1+Assumptions!$D$27) -> 1.03 | G9: =F9*(1+Assumptions!$D$27) -> 1.0609 | H9: =G9*(1+Assumptions!$D$27) -> 1.092727 | I9: =H9*(1+Assumptions!$D$27) -> 1.1255088 | J9: =I9*(1+Assumptions!$D$27) -> 1.1592741 | K9: =J9*(1+Assumptions!$D$27) -> 1.1940523 | L9: =K9*(1+Assumptions!$D$27) -> 1.2298739 | M9: =L9*(1+Assumptions!$D$27) -> 1.2667701 | N9: =M9*(1+Assumptions!$D$27) -> 1.3047732

Sheet Revenue
B2: REVENUE BUILD
B3: Period | D3: 0 | E3: 1 | F3: 2 | G3: 3 | H3: 4 | I3: 5 | J3: 6 | K3: 7 | L3: 8 | M3: 9 | N3: 10
B4: Year | D4: =Assumptions!$D$6+0 -> 2025 | E4: =Assumptions!$D$6+1 -> 2026 | F4: =Assumptions!$D$6+2 -> 2027 | G4: =Assumptions!$D$6+3 -> 2028 | H4: =Assumptions!$D$6+4 -> 2029 | I4: =Assumptions!$D$6+5 -> 2030 | J4: =Assumptions!$D$6+6 -> 2031 | K4: =Assumptions!$D$6+7 -> 2032 | L4: =Assumptions!$D$6+8 -> 2033 | M4: =Assumptions!$D$6+9 -> 2034 | N4: =Assumptions!$D$6+10 -> 2035
B5: Gross potential revenue | D5: =Assumptions!$D$19*Timeline!D8*Timeline!D5 -> 0 | E5: =Assumptions!$D$19*Timeline!E8*Timeline!E5 -> 15000000 | F5: =Assumptions!$D$19*Timeline!F8*Timeline!F5 -> 15000000 | G5: =Assumptions!$D$19*Timeline!G8*Timeline!G5 -> 15450000 | H5: =Assumptions!$D$19*Timeline!H8*Timeline!H5 -> 15450000 | I5: =Assumptions!$D$19*Timeline!I8*Timeline!I5 -> 15913500 | J5: =Assumptions!$D$19*Timeline!J8*Timeline!J5 -> 15913500 | K5: =Assumptions!$D$19*Timeline!K8*Timeline!K5 -> 16390905 | ... N5: =Assumptions!$D$19*Timeline!N8*Timeline!N5 -> 16882632
B6: Vacancy / collection loss | D6: =-D5*Assumptions!$D$22 -> 0 | E6: =-E5*Assumptions!$D$22 -> -750000 | F6: =-F5*Assumptions!$D$22 -> -750000 | G6: =-G5*Assumptions!$D$22 -> -772500 | H6: =-H5*Assumptions!$D$22 -> -772500 | I6: =-I5*Assumptions!$D$22 -> -795675 | J6: =-J5*Assumptions!$D$22 -> -795675 | K6: =-K5*Assumptions!$D$22 -> -819545.25 | ... N6: =-N5*Assumptions!$D$22 -> -844131.61
B7: EFFECTIVE GROSS INCOME (EGI) | D7: =D5+D6 -> 0 | E7: =E5+E6 -> 14250000 | F7: =F5+F6 -> 14250000 | G7: =G5+G6 -> 14677500 | H7: =H5+H6 -> 14677500 | I7: =I5+I6 -> 15117825 | J7: =J5+J6 -> 15117825 | K7: =K5+K6 -> 15571360 | ... N7: =N5+N6 -> 16038501
B8: YoY EGI growth | E8: =IFERROR(IF(D7=0,0,E7/D7-1),0) -> 0 | F8: =IFERROR(IF(E7=0,0,F7/E7-1),0) -> 0 | G8: =IFERROR(IF(F7=0,0,G7/F7-1),0) -> 0.03 | H8: =IFERROR(IF(G7=0,0,H7/G7-1),0) -> 0 | I8: =IFERROR(IF(H7=0,0,I7/H7-1),0) -> 0.03 | J8: =IFERROR(IF(I7=0,0,J7/I7-1),0) -> 0 | K8: =IFERROR(IF(J7=0,0,K7/J7-1),0) -> 0.03 | L8: =IFERROR(IF(K7=0,0,L7/K7-1),0) -> 0 | ... N8: =IFERROR(IF(M7=0,0,N7/M7-1),0) -> 0

Sheet OpEx_CapEx
B2: OPERATING EXPENSES & CAPITAL EXPENDITURE
B3: Period | D3: 0 | E3: 1 | F3: 2 | G3: 3 | H3: 4 | I3: 5 | J3: 6 | K3: 7 | L3: 8 | M3: 9 | N3: 10
B4: Year | D4: =Assumptions!$D$6+0 -> 2025 | E4: =Assumptions!$D$6+1 -> 2026 | F4: =Assumptions!$D$6+2 -> 2027 | G4: =Assumptions!$D$6+3 -> 2028 | H4: =Assumptions!$D$6+4 -> 2029 | I4: =Assumptions!$D$6+5 -> 2030 | J4: =Assumptions!$D$6+6 -> 2031 | K4: =Assumptions!$D$6+7 -> 2032 | L4: =Assumptions!$D$6+8 -> 2033 | M4: =Assumptions!$D$6+9 -> 2034 | N4: =Assumptions!$D$6+10 -> 2035
B5: ASSET-LEVEL OPERATING EXPENSES
B6: Operating expenses (OpEx) | D6: =-Revenue!D7*Assumptions!$D$25*Timeline!D9/Timeline!E9 -> 0 | E6: =-Revenue!E7*Assumptions!$D$25*Timeline!E9/Timeline!E9 -> -712500 | F6: =-Revenue!F7*Assumptions!$D$25*Timeline!F9/Timeline!E9 -> -733875 | G6: =-Revenue!G7*Assumptions!$D$25*Timeline!G9/Timeline!E9 -> -778567.99 | H6: =-Revenue!H7*Assumptions!$D$25*Timeline!H9/Timeline!E9 -> -801925.03 | I6: =-Revenue!I7*Assumptions!$D$25*Timeline!I9/Timeline!E9 -> -850762.26 | J6: =-Revenue!J7*Assumptions!$D$25*Timeline!J9/Timeline!E9 -> -876285.13 | K6: =-Revenue!K7*Assumptions!$D$25*Timeline!K9/Timeline!E9 -> -929650.89 | L6: =-Revenue!L7*Assumptions!$D$25*Timeline!L9/Timeline!E9 -> -957540.42 | M6: =-Revenue!M7*Assumptions!$D$25*Timeline!M9/Timeline!E9 -> -1015854.6 | N6: =-Revenue!N7*Assumptions!$D$25*Timeline!N9/Timeline!E9 -> -1046330.3
B7: Property / municipal tax | D7: =-Revenue!D7*Assumptions!$D$26 -> 0 | E7: =-Revenue!E7*Assumptions!$D$26 -> 0 | F7: =-Revenue!F7*Assumptions!$D$26 -> 0 | G7: =-Revenue!G7*Assumptions!$D$26 -> 0 | H7: =-Revenue!H7*Assumptions!$D$26 -> 0 | I7: =-Revenue!I7*Assumptions!$D$26 -> 0 | J7: =-Revenue!J7*Assumptions!$D$26 -> 0 | K7: =-Revenue!K7*Assumptions!$D$26 -> 0 | ... N7: =-Revenue!N7*Assumptions!$D$26 -> 0
B8: TOTAL ASSET OPERATING EXPENSES | D8: =D6+D7 -> 0 | E8: =E6+E7 -> -712500 | F8: =F6+F7 -> -733875 | G8: =G6+G7 -> -778567.99 | H8: =H6+H7 -> -801925.03 | I8: =I6+I7 -> -850762.26 | J8: =J6+J7 -> -876285.13 | K8: =K6+K7 -> -929650.89 | ... N8: =N6+N7 -> -1046330.3
B9: NET OPERATING INCOME (NOI) | D9: =Revenue!D7+D8 -> 0 | E9: =Revenue!E7+E8 -> 13537500 | F9: =Revenue!F7+F8 -> 13516125 | G9: =Revenue!G7+G8 -> 13898932 | H9: =Revenue!H7+H8 -> 13875575 | I9: =Revenue!I7+I8 -> 14267063 | J9: =Revenue!J7+J8 -> 14241540 | K9: =Revenue!K7+K8 -> 14641709 | ... N9: =Revenue!N7+N8 -> 14992170
B10: NOI margin | D10: =IFERROR(IF(Revenue!D7=0,0,D9/Revenue!D7),0) -> 0 | E10: =IFERROR(IF(Revenue!E7=0,0,E9/Revenue!E7),0) -> 0.95 | F10: =IFERROR(IF(Revenue!F7=0,0,F9/Revenue!F7),0) -> 0.9485 | G10: =IFERROR(IF(Revenue!G7=0,0,G9/Revenue!G7),0) -> 0.946955 | H10: =IFERROR(IF(Revenue!H7=0,0,H9/Revenue!H7),0) -> 0.94536365 | I10: =IFERROR(IF(Revenue!I7=0,0,I9/Revenue!I7),0) -> 0.94372456 | J10: =IFERROR(IF(Revenue!J7=0,0,J9/Revenue!J7),0) -> 0.9420363 | K10: =IFERROR(IF(Revenue!K7=0,0,K9/Revenue!K7),0) -> 0.94029739 | ... N10: =IFERROR(IF(Revenue!N7=0,0,N9/Revenue!N7),0) -> 0.93476134
B12: CORPORATE / FUND-LEVEL COSTS (below NOI)
B13: Management fee (% NAV proxy: total cost) | D13: =-Assumptions!$D$16*Assumptions!$D$30*Timeline!D5 -> 0 | E13: =-Assumptions!$D$16*Assumptions!$D$30*Timeline!E5 -> -646500 | F13: =-Assumptions!$D$16*Assumptions!$D$30*Timeline!F5 -> -646500 | G13: =-Assumptions!$D$16*Assumptions!$D$30*Timeline!G5 -> -646500 | H13: =-Assumptions!$D$16*Assumptions!$D$30*Timeline!H5 -> -646500 | I13: =-Assumptions!$D$16*Assumptions!$D$30*Timeline!I5 -> -646500 | J13: =-Assumptions!$D$16*Assumptions!$D$30*Timeline!J5 -> -646500 | K13: =-Assumptions!$D$16*Assumptions!$D$30*Timeline!K5 -> -646500 | ... N13: =-Assumptions!$D$16*Assumptions!$D$30*Timeline!N5 -> -646500
B14: Custodian fee | D14: =-Assumptions!$D$16*Assumptions!$D$31*Timeline!D5 -> 0 | E14: =-Assumptions!$D$16*Assumptions!$D$31*Timeline!E5 -> -86200 | F14: =-Assumptions!$D$16*Assumptions!$D$31*Timeline!F5 -> -86200 | G14: =-Assumptions!$D$16*Assumptions!$D$31*Timeline!G5 -> -86200 | H14: =-Assumptions!$D$16*Assumptions!$D$31*Timeline!H5 -> -86200 | I14: =-Assumptions!$D$16*Assumptions!$D$31*Timeline!I5 -> -86200 | J14: =-Assumptions!$D$16*Assumptions!$D$31*Timeline!J5 -> -86200 | K14: =-Assumptions!$D$16*Assumptions!$D$31*Timeline!K5 -> -86200 | ... N14: =-Assumptions!$D$16*Assumptions!$D$31*Timeline!N5 -> -86200
B15: Fund admin fee | D15: =-Assumptions!$D$16*Assumptions!$D$32*Timeline!D5 -> 0 | E15: =-Assumptions!$D$16*Assumptions!$D$32*Timeline!E5 -> -107750 | F15: =-Assumptions!$D$16*Assumptions!$D$32*Timeline!F5 -> -107750 | G15: =-Assumptions!$D$16*Assumptions!$D$32*Timeline!G5 -> -107750 | H15: =-Assumptions!$D$16*Assumptions!$D$32*Timeline!H5 -> -107750 | I15: =-Assumptions!$D$16*Assumptions!$D$32*Timeline!I5 -> -107750 | J15: =-Assumptions!$D$16*Assumptions!$D$32*Timeline!J5 -> -107750 | K15: =-Assumptions!$D$16*Assumptions!$D$32*Timeline!K5 -> -107750 | ... N15: =-Assumptions!$D$16*Assumptions!$D$32*Timeline!N5 -> -107750
B16: Other fixed annual expenses | D16: =-Assumptions!$D$33*Timeline!D9*Timeline!D5 -> 0 | E16: =-Assumptions!$D$33*Timeline!E9*Timeline!E5 -> -285000 | F16: =-Assumptions!$D$33*Timeline!F9*Timeline!F5 -> -293550 | G16: =-Assumptions!$D$33*Timeline!G9*Timeline!G5 -> -302356.5 | H16: =-Assumptions!$D$33*Timeline!H9*Timeline!H5 -> -311427.2 | I16: =-Assumptions!$D$33*Timeline!I9*Timeline!I5 -> -320770.01 | J16: =-Assumptions!$D$33*Timeline!J9*Timeline!J5 -> -330393.11 | K16: =-Assumptions!$D$33*Timeline!K9*Timeline!K5 -> -340304.9 | ... N16: =-Assumptions!$D$33*Timeline!N9*Timeline!N5 -> -371860.36
B17: TOTAL CORPORATE COSTS | D17: =SUM(D13:D16) -> 0 | E17: =SUM(E13:E16) -> -1125450 | F17: =SUM(F13:F16) -> -1134000 | G17: =SUM(G13:G16) -> -1142806.5 | H17: =SUM(H13:H16) -> -1151877.2 | I17: =SUM(I13:I16) -> -1161220 | J17: =SUM(J13:J16) -> -1170843.1 | K17: =SUM(K13:K16) -> -1180754.9 | ... N17: =SUM(N13:N16) -> -1212310.4
B18: EBITDA (NOI − Corporate costs) | D18: =D9+D17 -> 0 | E18: =E9+E17 -> 12412050 | F18: =F9+F17 -> 12382125 | G18: =G9+G17 -> 12756126 | H18: =H9+H17 -> 12723698 | I18: =I9+I17 -> 13105843 | J18: =J9+J17 -> 13070697 | K18: =K9+K17 -> 13460954 | ... N18: =N9+N17 -> 13779860
B20: CAPITAL EXPENDITURE
B21: Maintenance CapEx (% EGI) | D21: =-Revenue!D7*Assumptions!$D$36 -> 0 | E21: =-Revenue!E7*Assumptions!$D$36 -> -213750 | F21: =-Revenue!F7*Assumptions!$D$36 -> -213750 | G21: =-Revenue!G7*Assumptions!$D$36 -> -220162.5 | H21: =-Revenue!H7*Assumptions!$D$36 -> -220162.5 | I21: =-Revenue!I7*Assumptions!$D$36 -> -226767.38 | J21: =-Revenue!J7*Assumptions!$D$36 -> -226767.38 | K21: =-Revenue!K7*Assumptions!$D$36 -> -233570.4 | ... N21: =-Revenue!N7*Assumptions!$D$36 -> -240577.51
B22: Major refurbishment | D22: =IF(0=Assumptions!$D$38,-Assumptions!$D$37,0) -> 0 | E22: =IF(1=Assumptions!$D$38,-Assumptions!$D$37,0) -> 0 | F22: =IF(2=Assumptions!$D$38,-Assumptions!$D$37,0) -> 0 | G22: =IF(3=Assumptions!$D$38,-Assumptions!$D$37,0) -> 0 | H22: =IF(4=Assumptions!$D$38,-Assumptions!$D$37,0) -> 0 | I22: =IF(5=Assumptions!$D$38,-Assumptions!$D$37,0) -> -3000000 | J22: =IF(6=Assumptions!$D$38,-Assumptions!$D$37,0) -> 0 | K22: =IF(7=Assumptions!$D$38,-Assumptions!$D$37,0) -> 0 | L22: =IF(8=Assumptions!$D$38,-Assumptions!$D$37,0) -> 0 | M22: =IF(9=Assumptions!$D$38,-Assumptions!$D$37,0) -> 0 | N22: =IF(10=Assumptions!$D$38,-Assumptions!$D$37,0) -> 0
B23: TOTAL CAPEX | D23: =D21+D22 -> 0 | E23: =E21+E22 -> -213750 | F23: =F21+F22 -> -213750 | G23: =G21+G22 -> -220162.5 | H23: =H21+H22 -> -220162.5 | I23: =I21+I22 -> -3226767.4 | J23: =J21+J22 -> -226767.38 | K23: =K21+K22 -> -233570.4 | ... N23: =N21+N22 -> -240577.51

Sheet Debt
B2: DEBT SCHEDULE
B3: Period | D3: 0 | E3: 1 | F3: 2 | G3: 3 | H3: 4 | I3: 5 | J3: 6 | K3: 7 | L3: 8 | M3: 9 | N3: 10
B4: Year | D4: =Assumptions!$D$6+0 -> 2025 | E4: =Assumptions!$D$6+1 -> 2026 | F4: =Assumptions!$D$6+2 -> 2027 | G4: =Assumptions!$D$6+3 -> 2028 | H4: =Assumptions!$D$6+4 -> 2029 | I4: =Assumptions!$D$6+5 -> 2030 | J4: =Assumptions!$D$6+6 -> 2031 | K4: =Assumptions!$D$6+7 -> 2032 | L4: =Assumptions!$D$6+8 -> 2033 | M4: =Assumptions!$D$6+9 -> 2034 | N4: =Assumptions!$D$6+10 -> 2035
B5: Opening balance | D5: 0 | E5: =D9 -> 1.0775e+08 | F5: =E9 -> 1.0775e+08 | G5: =F9 -> 1.0775e+08 | H5: =G9 -> 1.0775e+08 | I5: =H9 -> 1.0775e+08 | J5: =I9 -> 1.0775e+08 | K5: =J9 -> 1.0775e+08 | L5: =K9 -> 1.0775e+08 | ... N5: =M9 -> 1.0775e+08
B6: Drawdown | D6: =Assumptions!$D$47 -> 1.0775e+08 | E6: 0 | F6: 0 | G6: 0 | H6: 0 | I6: 0 | J6: 0 | K6: 0 | L6: 0 | M6: 0 | N6: 0
B7: Scheduled principal repayment | D7: 0 | E7: =-IF(AND(Assumptions!$D$44=1,1>Assumptions!$D$46,1<Assumptions!$D$7,Assumptions!$D$45-Assumptions!$D$46>0),Assumptions!$D$47/(Assumptions!$D$45-Assumptions!$D$46),0) -> 0 | F7: =-IF(AND(Assumptions!$D$44=1,2>Assumptions!$D$46,2<Assumptions!$D$7,Assumptions!$D$45-Assumptions!$D$46>0),Assumptions!$D$47/(Assumptions!$D$45-Assumptions!$D$46),0) -> 0 | G7: =-IF(AND(Assumptions!$D$44=1,3>Assumptions!$D$46,3<Assumptions!$D$7,Assumptions!$D$45-Assumptions!$D$46>0),Assumptions!$D$47/(Assumptions!$D$45-Assumptions!$D$46),0) -> 0 | H7: =-IF(AND(Assumptions!$D$44=1,4>Assumptions!$D$46,4<Assumptions!$D$7,Assumptions!$D$45-Assumptions!$D$46>0),Assumptions!$D$47/(Assumptions!$D$45-Assumptions!$D$46),0) -> 0 | I7: =-IF(AND(Assumptions!$D$44=1,5>Assumptions!$D$46,5<Assumptions!$D$7,Assumptions!$D$45-Assumptions!$D$46>0),Assumptions!$D$47/(Assumptions!$D$45-Assumptions!$D$46),0) -> 0 | J7: =-IF(AND(Assumptions!$D$44=1,6>Assumptions!$D$46,6<Assumptions!$D$7,Assumptions!$D$45-Assumptions!$D$46>0),Assumptions!$D$47/(Assumptions!$D$45-Assumptions!$D$46),0) -> 0 | K7: =-IF(AND(Assumptions!$D$44=1,7>Assumptions!$D$46,7<Assumptions!$D$7,Assumptions!$D$45-Assumptions!$D$46>0),Assumptions!$D$47/(Assumptions!$D$45-Assumptions!$D$46),0) -> 0 | L7: =-IF(AND(Assumptions!$D$44=1,8>Assumptions!$D$46,8<Assumptions!$D$7,Assumptions!$D$45-Assumptions!$D$46>0),Assumptions!$D$47/(Assumptions!$D$45-Assumptions!$D$46),0) -> 0 | M7: =-IF(AND(Assumptions!$D$44=1,9>Assumptions!$D$46,9<Assumptions!$D$7,Assumptions!$D$45-Assumptions!$D$46>0),Assumptions!$D$47/(Assumptions!$D$45-Assumptions!$D$46),0) -> 0 | N7: =-IF(AND(Assumptions!$D$44=1,10>Assumptions!$D$46,10<Assumptions!$D$7,Assumptions!$D$45-Assumptions!$D$46>0),Assumptions!$D$47/(Assumptions!$D$45-Assumptions!$D$46),0) -> 0
B8: Bullet repayment at exit | D8: 0 | E8: =-IF(1=Assumptions!$D$7,E5+E6+E7,0) -> 0 | F8: =-IF(2=Assumptions!$D$7,F5+F6+F7,0) -> 0 | G8: =-IF(3=Assumptions!$D$7,G5+G6+G7,0) -> 0 | H8: =-IF(4=Assumptions!$D$7,H5+H6+H7,0) -> 0 | I8: =-IF(5=Assumptions!$D$7,I5+I6+I7,0) -> 0 | J8: =-IF(6=Assumptions!$D$7,J5+J6+J7,0) -> 0 | K8: =-IF(7=Assumptions!$D$7,K5+K6+K7,0) -> 0 | L8: =-IF(8=Assumptions!$D$7,L5+L6+L7,0) -> 0 | M8: =-IF(9=Assumptions!$D$7,M5+M6+M7,0) -> 0 | N8: =-IF(10=Assumptions!$D$7,N5+N6+N7,0) -> -1.0775e+08
B9: CLOSING BALANCE | D9: =D5+D6+D7+D8 -> 1.0775e+08 | E9: =E5+E6+E7+E8 -> 1.0775e+08 | F9: =F5+F6+F7+F8 -> 1.0775e+08 | G9: =G5+G6+G7+G8 -> 1.0775e+08 | H9: =H5+H6+H7+H8 -> 1.0775e+08 | I9: =I5+I6+I7+I8 -> 1.0775e+08 | J9: =J5+J6+J7+J8 -> 1.0775e+08 | K9: =K5+K6+K7+K8 -> 1.0775e+08 | ... N9: =N5+N6+N7+N8 -> 0
B10: Interest expense | D10: 0 | E10: =-E5*Assumptions!$D$42*Timeline!E5 -> -7542500 | F10: =-F5*Assumptions!$D$42*Timeline!F5 -> -7542500 | G10: =-G5*Assumptions!$D$42*Timeline!G5 -> -7542500 | H10: =-H5*Assumptions!$D$42*Timeline!H5 -> -7542500 | I10: =-I5*Assumptions!$D$42*Timeline!I5 -> -7542500 | J10: =-J5*Assumptions!$D$42*Timeline!J5 -> -7542500 | K10: =-K5*Assumptions!$D$42*Timeline!K5 -> -7542500 | L10: =-L5*Assumptions!$D$42*Timeline!L5 -> -7542500 | ... N10: =-N5*Assumptions!$D$42*Timeline!N5 -> -7542500
B11: Arrangement fee (one-off) | D11: =-Assumptions!$D$47*Assumptions!$D$43 -> -269375 | E11: 0 | F11: 0 | G11: 0 | H11: 0 | I11: 0 | J11: 0 | K11: 0 | L11: 0 | M11: 0 | N11: 0
B12: TOTAL DEBT SERVICE (interest + principal) | D12: =D7+D8+D10+D11 -> -269375 | E12: =E7+E8+E10+E11 -> -7542500 | F12: =F7+F8+F10+F11 -> -7542500 | G12: =G7+G8+G10+G11 -> -7542500 | H12: =H7+H8+H10+H11 -> -7542500 | I12: =I7+I8+I10+I11 -> -7542500 | J12: =J7+J8+J10+J11 -> -7542500 | K12: =K7+K8+K10+K11 -> -7542500 | ... N12: =N7+N8+N10+N11 -> -1.152925e+08
B14: COVERAGE RATIOS (per year)
B15: Interest Coverage (NOI / |Interest|) | D15: =IFERROR(IF(D10=0,999,OpEx_CapEx!D9/ABS(D10)),999) -> 999 | E15: =IFERROR(IF(E10=0,999,OpEx_CapEx!E9/ABS(E10)),999) -> 1.7948293 | F15: =IFERROR(IF(F10=0,999,OpEx_CapEx!F9/ABS(F10)),999) -> 1.7919954 | G15: =IFERROR(IF(G10=0,999,OpEx_CapEx!G9/ABS(G10)),999) -> 1.8427487 | H15: =IFERROR(IF(H10=0,999,OpEx_CapEx!H9/ABS(H10)),999) -> 1.839652 | I15: =IFERROR(IF(I10=0,999,OpEx_CapEx!I9/ABS(I10)),999) -> 1.8915562 | J15: =IFERROR(IF(J10=0,999,OpEx_CapEx!J9/ABS(J10)),999) -> 1.8881723 | K15: =IFERROR(IF(K10=0,999,OpEx_CapEx!K9/ABS(K10)),999) -> 1.9412276 | ... N15: =IFERROR(IF(N10=0,999,OpEx_CapEx!N9/ABS(N10)),999) -> 1.9876924
B16: DSCR (NOI / (|Interest|+|Principal|+|Bullet|)) | D16: =IFERROR(IF(ABS(D10)+ABS(D7)+ABS(D8)=0,999,OpEx_CapEx!D9/(ABS(D10)+ABS(D7)+ABS(D8))),999) -> 999 | E16: =IFERROR(IF(ABS(E10)+ABS(E7)+ABS(E8)=0,999,OpEx_CapEx!E9/(ABS(E10)+ABS(E7)+ABS(E8))),999) -> 1.7948293 | F16: =IFERROR(IF(ABS(F10)+ABS(F7)+ABS(F8)=0,999,OpEx_CapEx!F9/(ABS(F10)+ABS(F7)+ABS(F8))),999) -> 1.7919954 | G16: =IFERROR(IF(ABS(G10)+ABS(G7)+ABS(G8)=0,999,OpEx_CapEx!G9/(ABS(G10)+ABS(G7)+ABS(G8))),999) -> 1.8427487 | H16: =IFERROR(IF(ABS(H10)+ABS(H7)+ABS(H8)=0,999,OpEx_CapEx!H9/(ABS(H10)+ABS(H7)+ABS(H8))),999) -> 1.839652 | I16: =IFERROR(IF(ABS(I10)+ABS(I7)+ABS(I8)=0,999,OpEx_CapEx!I9/(ABS(I10)+ABS(I7)+ABS(I8))),999) -> 1.8915562 | J16: =IFERROR(IF(ABS(J10)+ABS(J7)+ABS(J8)=0,999,OpEx_CapEx!J9/(ABS(J10)+ABS(J7)+ABS(J8))),999) -> 1.8881723 | K16: =IFERROR(IF(ABS(K10)+ABS(K7)+ABS(K8)=0,999,OpEx_CapEx!K9/(ABS(K10)+ABS(K7)+ABS(K8))),999) -> 1.9412276 | ... N16: =IFERROR(IF(ABS(N10)+ABS(N7)+ABS(N8)=0,999,OpEx_CapEx!N9/(ABS(N10)+ABS(N7)+ABS(N8))),999) -> 0.13003595
B17: LTV (Debt / Asset Value at acquisition) | D17: =IFERROR(IF(Assumptions!$D$16=0,0,D9/Assumptions!$D$16),0) -> 0.5 | E17: =IFERROR(IF(Assumptions!$D$16=0,0,E9/Assumptions!$D$16),0) -> 0.5 | F17: =IFERROR(IF(Assumptions!$D$16=0,0,F9/Assumptions!$D$16),0) -> 0.5 | G17: =IFERROR(IF(Assumptions!$D$16=0,0,G9/Assumptions!$D$16),0) -> 0.5 | H17: =IFERROR(IF(Assumptions!$D$16=0,0,H9/Assumptions!$D$16),0) -> 0.5 | I17: =IFERROR(IF(Assumptions!$D$16=0,0,I9/Assumptions!$D$16),0) -> 0.5 | J17: =IFERROR(IF(Assumptions!$D$16=0,0,J9/Assumptions!$D$16),0) -> 0.5 | K17: =IFERROR(IF(Assumptions!$D$16=0,0,K9/Assumptions!$D$16),0) -> 0.5 | ... N17: =IFERROR(IF(Assumptions!$D$16=0,0,N9/Assumptions!$D$16),0) -> 0
B18: Debt yield (NOI / Debt outstanding) | D18: =IFERROR(IF(D9=0,"",OpEx_CapEx!D9/D9),"") -> 0 | E18: =IFERROR(IF(E9=0,"",OpEx_CapEx!E9/E9),"") -> 0.12563805 | F18: =IFERROR(IF(F9=0,"",OpEx_CapEx!F9/F9),"") -> 0.12543968 | G18: =IFERROR(IF(G9=0,"",OpEx_CapEx!G9/G9),"") -> 0.12899241 | H18: =IFERROR(IF(H9=0,"",OpEx_CapEx!H9/H9),"") -> 0.12877564 | I18: =IFERROR(IF(I9=0,"",OpEx_CapEx!I9/I9),"") -> 0.13240893 | J18: =IFERROR(IF(J9=0,"",OpEx_CapEx!J9/J9),"") -> 0.13217206 | K18: =IFERROR(IF(K9=0,"",OpEx_CapEx!K9/K9),"") -> 0.13588593 | ... N18: =IFERROR(IF(N9=0,"",OpEx_CapEx!N9/N9),"")

Sheet Tax
B2: TAX SCHEDULE
B3: Period | D3: 0 | E3: 1 | F3: 2 | G3: 3 | H3: 4 | I3: 5 | J3: 6 | K3: 7 | L3: 8 | M3: 9 | N3: 10
B4: Year | D4: =Assumptions!$D$6+0 -> 2025 | E4: =Assumptions!$D$6+1 -> 2026 | F4: =Assumptions!$D$6+2 -> 2027 | G4: =Assumptions!$D$6+3 -> 2028 | H4: =Assumptions!$D$6+4 -> 2029 | I4: =Assumptions!$D$6+5 -> 2030 | J4: =Assumptions!$D$6+6 -> 2031 | K4: =Assumptions!$D$6+7 -> 2032 | L4: =Assumptions!$D$6+8 -> 2033 | M4: =Assumptions!$D$6+9 -> 2034 | N4: =Assumptions!$D$6+10 -> 2035
B5: EBITDA (from OpEx_CapEx) | D5: =OpEx_CapEx!D18 -> 0 | E5: =OpEx_CapEx!E18 -> 12412050 | F5: =OpEx_CapEx!F18 -> 12382125 | G5: =OpEx_CapEx!G18 -> 12756126 | H5: =OpEx_CapEx!H18 -> 12723698 | I5: =OpEx_CapEx!I18 -> 13105843 | J5: =OpEx_CapEx!J18 -> 13070697 | K5: =OpEx_CapEx!K18 -> 13460954 | ... N5: =OpEx_CapEx!N18 -> 13779860
B6: Less: Interest expense | D6: =Debt!D10 -> 0 | E6: =Debt!E10 -> -7542500 | F6: =Debt!F10 -> -7542500 | G6: =Debt!G10 -> -7542500 | H6: =Debt!H10 -> -7542500 | I6: =Debt!I10 -> -7542500 | J6: =Debt!J10 -> -7542500 | K6: =Debt!K10 -> -7542500 | ... N6: =Debt!N10 -> -7542500
B7: Less: Depreciation proxy (CapEx) | D7: =OpEx_CapEx!D23 -> 0 | E7: =OpEx_CapEx!E23 -> -213750 | F7: =OpEx_CapEx!F23 -> -213750 | G7: =OpEx_CapEx!G23 -> -220162.5 | H7: =OpEx_CapEx!H23 -> -220162.5 | I7: =OpEx_CapEx!I23 -> -3226767.4 | J7: =OpEx_CapEx!J23 -> -226767.38 | K7: =OpEx_CapEx!K23 -> -233570.4 | ... N7: =OpEx_CapEx!N23 -> -240577.51
B8: Earnings before tax (EBT) | D8: =D5+D6+D7 -> 0 | E8: =E5+E6+E7 -> 4655800 | F8: =F5+F6+F7 -> 4625875 | G8: =G5+G6+G7 -> 4993463 | H8: =H5+H6+H7 -> 4961035.3 | I8: =I5+I6+I7 -> 2336575.4 | J8: =J5+J6+J7 -> 5301429.4 | K8: =K5+K6+K7 -> 5684883.6 | ... N8: =N5+N6+N7 -> 5996782.4
B9: Zakat (on equity-base proxy: total cost × equity %) | D9: =-Assumptions!$D$48*Assumptions!$D$57*Timeline!D5 -> 0 | E9: =-Assumptions!$D$48*Assumptions!$D$57*Timeline!E5 -> -2693750 | F9: =-Assumptions!$D$48*Assumptions!$D$57*Timeline!F5 -> -2693750 | G9: =-Assumptions!$D$48*Assumptions!$D$57*Timeline!G5 -> -2693750 | H9: =-Assumptions!$D$48*Assumptions!$D$57*Timeline!H5 -> -2693750 | I9: =-Assumptions!$D$48*Assumptions!$D$57*Timeline!I5 -> -2693750 | J9: =-Assumptions!$D$48*Assumptions!$D$57*Timeline!J5 -> -2693750 | K9: =-Assumptions!$D$48*Assumptions!$D$57*Timeline!K5 -> -2693750 | ... N9: =-Assumptions!$D$48*Assumptions!$D$57*Timeline!N5 -> -2693750
B10: Corporate tax (on positive EBT) | D10: =-MAX(D8,0)*Assumptions!$D$58*Timeline!D5 -> 0 | E10: =-MAX(E8,0)*Assumptions!$D$58*Timeline!E5 -> 0 | F10: =-MAX(F8,0)*Assumptions!$D$58*Timeline!F5 -> 0 | G10: =-MAX(G8,0)*Assumptions!$D$58*Timeline!G5 -> 0 | H10: =-MAX(H8,0)*Assumptions!$D$58*Timeline!H5 -> 0 | I10: =-MAX(I8,0)*Assumptions!$D$58*Timeline!I5 -> 0 | J10: =-MAX(J8,0)*Assumptions!$D$58*Timeline!J5 -> 0 | K10: =-MAX(K8,0)*Assumptions!$D$58*Timeline!K5 -> 0 | ... N10: =-MAX(N8,0)*Assumptions!$D$58*Timeline!N5 -> 0
B11: Withholding tax on equity distributions | D11: =-MAX(D8+D9+D10,0)*Assumptions!$D$59*Timeline!D5 -> 0 | E11: =-MAX(E8+E9+E10,0)*Assumptions!$D$59*Timeline!E5 -> -98102.5 | F11: =-MAX(F8+F9+F10,0)*Assumptions!$D$59*Timeline!F5 -> -96606.25 | G11: =-MAX(G8+G9+G10,0)*Assumptions!$D$59*Timeline!G5 -> -114985.65 | H11: =-MAX(H8+H9+H10,0)*Assumptions!$D$59*Timeline!H5 -> -113364.26 | I11: =-MAX(I8+I9+I10,0)*Assumptions!$D$59*Timeline!I5 -> 0 | J11: =-MAX(J8+J9+J10,0)*Assumptions!$D$59*Timeline!J5 -> -130383.97 | K11: =-MAX(K8+K9+K10,0)*Assumptions!$D$59*Timeline!K5 -> -149556.68 | ... N11: =-MAX(N8+N9+N10,0)*Assumptions!$D$59*Timeline!N5 -> -165151.62
B12: TOTAL TAX (negative = cash out) | D12: =D9+D10+D11 -> 0 | E12: =E9+E10+E11 -> -2791852.5 | F12: =F9+F10+F11 -> -2790356.3 | G12: =G9+G10+G11 -> -2808735.7 | H12: =H9+H10+H11 -> -2807114.3 | I12: =I9+I10+I11 -> -2693750 | J12: =J9+J10+J11 -> -2824134 | K12: =K9+K10+K11 -> -2843306.7 | ... N12: =N9+N10+N11 -> -2858901.6
B13: Disposal tax (one-off at exit) | D13: =-DCF!D9*Assumptions!$D$60 -> 0 | E13: =-DCF!E9*Assumptions!$D$60 -> 0 | F13: =-DCF!F9*Assumptions!$D$60 -> 0 | G13: =-DCF!G9*Assumptions!$D$60 -> 0 | H13: =-DCF!H9*Assumptions!$D$60 -> 0 | I13: =-DCF!I9*Assumptions!$D$60 -> 0 | J13: =-DCF!J9*Assumptions!$D$60 -> 0 | K13: =-DCF!K9*Assumptions!$D$60 -> 0 | ... N13: =-DCF!N9*Assumptions!$D$60 -> 0

Sheet Cash_Flow
B2: CASH FLOW STATEMENT (Project & Equity)
B3: Period | D3: 0 | E3: 1 | F3: 2 | G3: 3 | H3: 4 | I3: 5 | J3: 6 | K3: 7 | L3: 8 | M3: 9 | N3: 10
B4: Year | D4: =Assumptions!$D$6+0 -> 2025 | E4: =Assumptions!$D$6+1 -> 2026 | F4: =Assumptions!$D$6+2 -> 2027 | G4: =Assumptions!$D$6+3 -> 2028 | H4: =Assumptions!$D$6+4 -> 2029 | I4: =Assumptions!$D$6+5 -> 2030 | J4: =Assumptions!$D$6+6 -> 2031 | K4: =Assumptions!$D$6+7 -> 2032 | L4: =Assumptions!$D$6+8 -> 2033 | M4: =Assumptions!$D$6+9 -> 2034 | N4: =Assumptions!$D$6+10 -> 2035
B5: UNLEVERED (PROJECT) CASH FLOW
B6: Revenue (EGI) | D6: =Revenue!D7 -> 0 | E6: =Revenue!E7 -> 14250000 | F6: =Revenue!F7 -> 14250000 | G6: =Revenue!G7 -> 14677500 | H6: =Revenue!H7 -> 14677500 | I6: =Revenue!I7 -> 15117825 | J6: =Revenue!J7 -> 15117825 | K6: =Revenue!K7 -> 15571360 | ... N6: =Revenue!N7 -> 16038501
B7: Operating expenses | D7: =OpEx_CapEx!D8 -> 0 | E7: =OpEx_CapEx!E8 -> -712500 | F7: =OpEx_CapEx!F8 -> -733875 | G7: =OpEx_CapEx!G8 -> -778567.99 | H7: =OpEx_CapEx!H8 -> -801925.03 | I7: =OpEx_CapEx!I8 -> -850762.26 | J7: =OpEx_CapEx!J8 -> -876285.13 | K7: =OpEx_CapEx!K8 -> -929650.89 | ... N7: =OpEx_CapEx!N8 -> -1046330.3
B8: NOI | D8: =OpEx_CapEx!D9 -> 0 | E8: =OpEx_CapEx!E9 -> 13537500 | F8: =OpEx_CapEx!F9 -> 13516125 | G8: =OpEx_CapEx!G9 -> 13898932 | H8: =OpEx_CapEx!H9 -> 13875575 | I8: =OpEx_CapEx!I9 -> 14267063 | J8: =OpEx_CapEx!J9 -> 14241540 | K8: =OpEx_CapEx!K9 -> 14641709 | ... N8: =OpEx_CapEx!N9 -> 14992170
B9: Corporate costs | D9: =OpEx_CapEx!D17 -> 0 | E9: =OpEx_CapEx!E17 -> -1125450 | F9: =OpEx_CapEx!F17 -> -1134000 | G9: =OpEx_CapEx!G17 -> -1142806.5 | H9: =OpEx_CapEx!H17 -> -1151877.2 | I9: =OpEx_CapEx!I17 -> -1161220 | J9: =OpEx_CapEx!J17 -> -1170843.1 | K9: =OpEx_CapEx!K17 -> -1180754.9 | ... N9: =OpEx_CapEx!N17 -> -1212310.4
B10: EBITDA | D10: =OpEx_CapEx!D18 -> 0 | E10: =OpEx_CapEx!E18 -> 12412050 | F10: =OpEx_CapEx!F18 -> 12382125 | G10: =OpEx_CapEx!G18 -> 12756126 | H10: =OpEx_CapEx!H18 -> 12723698 | I10: =OpEx_CapEx!I18 -> 13105843 | J10: =OpEx_CapEx!J18 -> 13070697 | K10: =OpEx_CapEx!K18 -> 13460954 | ... N10: =OpEx_CapEx!N18 -> 13779860
B11: CapEx (maintenance + refurb) | D11: =OpEx_CapEx!D23 -> 0 | E11: =OpEx_CapEx!E23 -> -213750 | F11: =OpEx_CapEx!F23 -> -213750 | G11: =OpEx_CapEx!G23 -> -220162.5 | H11: =OpEx_CapEx!H23 -> -220162.5 | I11: =OpEx_CapEx!I23 -> -3226767.4 | J11: =OpEx_CapEx!J23 -> -226767.38 | K11: =OpEx_CapEx!K23 -> -233570.4 | ... N11: =OpEx_CapEx!N23 -> -240577.51
B12: Acquisition outflow (Y0) | D12: =-Assumptions!$D$16 -> -2.155e+08 | E12: 0 | F12: 0 | G12: 0 | H12: 0 | I12: 0 | J12: 0 | K12: 0 | L12: 0 | M12: 0 | N12: 0
B13: Exit value net of disposal costs (Y_exit) | D13: =IF(0=Assumptions!$D$7,DCF!D10,0) -> 0 | E13: =IF(1=Assumptions!$D$7,DCF!E10,0) -> 0 | F13: =IF(2=Assumptions!$D$7,DCF!F10,0) -> 0 | G13: =IF(3=Assumptions!$D$7,DCF!G10,0) -> 0 | H13: =IF(4=Assumptions!$D$7,DCF!H10,0) -> 0 | I13: =IF(5=Assumptions!$D$7,DCF!I10,0) -> 0 | J13: =IF(6=Assumptions!$D$7,DCF!J10,0) -> 0 | K13: =IF(7=Assumptions!$D$7,DCF!K10,0) -> 0 | L13: =IF(8=Assumptions!$D$7,DCF!L10,0) -> 0 | M13: =IF(9=Assumptions!$D$7,DCF!M10,0) -> 0 | N13: =IF(10=Assumptions!$D$7,DCF!N10,0) -> 1.9680722e+08
B14: Disposal tax (Y_exit) | D14: =Tax!D13 -> 0 | E14: =Tax!E13 -> 0 | F14: =Tax!F13 -> 0 | G14: =Tax!G13 -> 0 | H14: =Tax!H13 -> 0 | I14: =Tax!I13 -> 0 | J14: =Tax!J13 -> 0 | K14: =Tax!K13 -> 0 | ... N14: =Tax!N13 -> 0
B15: PROJECT FREE CASH FLOW (unlevered) | D15: =D10+D11+D12+D13+D14 -> -2.155e+08 | E15: =E10+E11+E12+E13+E14 -> 12198300 | F15: =F10+F11+F12+F13+F14 -> 12168375 | G15: =G10+G11+G12+G13+G14 -> 12535963 | H15: =H10+H11+H12+H13+H14 -> 12503535 | I15: =I10+I11+I12+I13+I14 -> 9879075.4 | J15: =J10+J11+J12+J13+J14 -> 12843929 | K15: =K10+K11+K12+K13+K14 -> 13227384 | ... N15: =N10+N11+N12+N13+N14 -> 2.103465e+08
B17: EQUITY (LEVERED) CASH FLOW
B18: Project FCF | D18: =D15 -> -2.155e+08 | E18: =E15 -> 12198300 | F18: =F15 -> 12168375 | G18: =G15 -> 12535963 | H18: =H15 -> 12503535 | I18: =I15 -> 9879075.4 | J18: =J15 -> 12843929 | K18: =K15 -> 13227384 | ... N18: =N15 -> 2.103465e+08
B19: Debt drawdown | D19: =Debt!D6 -> 1.0775e+08 | E19: =Debt!E6 -> 0 | F19: =Debt!F6 -> 0 | G19: =Debt!G6 -> 0 | H19: =Debt!H6 -> 0 | I19: =Debt!I6 -> 0 | J19: =Debt!J6 -> 0 | K19: =Debt!K6 -> 0 | ... N19: =Debt!N6 -> 0
B20: Arrangement fee | D20: =Debt!D11 -> -269375 | E20: =Debt!E11 -> 0 | F20: =Debt!F11 -> 0 | G20: =Debt!G11 -> 0 | H20: =Debt!H11 -> 0 | I20: =Debt!I11 -> 0 | J20: =Debt!J11 -> 0 | K20: =Debt!K11 -> 0 | ... N20: =Debt!N11 -> 0
B21: Interest expense | D21: =Debt!D10 -> 0 | E21: =Debt!E10 -> -7542500 | F21: =Debt!F10 -> -7542500 | G21: =Debt!G10 -> -7542500 | H21: =Debt!H10 -> -7542500 | I21: =Debt!I10 -> -7542500 | J21: =Debt!J10 -> -7542500 | K21: =Debt!K10 -> -7542500 | ... N21: =Debt!N10 -> -7542500
B22: Scheduled principal | D22: =Debt!D7 -> 0 | E22: =Debt!E7 -> 0 | F22: =Debt!F7 -> 0 | G22: =Debt!G7 -> 0 | H22: =Debt!H7 -> 0 | I22: =Debt!I7 -> 0 | J22: =Debt!J7 -> 0 | K22: =Debt!K7 -> 0 | ... N22: =Debt!N7 -> 0
B23: Bullet repayment at exit | D23: =Debt!D8 -> 0 | E23: =Debt!E8 -> 0 | F23: =Debt!F8 -> 0 | G23: =Debt!G8 -> 0 | H23: =Debt!H8 -> 0 | I23: =Debt!I8 -> 0 | J23: =Debt!J8 -> 0 | K23: =Debt!K8 -> 0 | ... N23: =Debt!N8 -> -1.0775e+08
B24: Income taxes (zakat + corp + WHT) | D24: =Tax!D12 -> 0 | E24: =Tax!E12 -> -2791852.5 | F24: =Tax!F12 -> -2790356.3 | G24: =Tax!G12 -> -2808735.7 | H24: =Tax!H12 -> -2807114.3 | I24: =Tax!I12 -> -2693750 | J24: =Tax!J12 -> -2824134 | K24: =Tax!K12 -> -2843306.7 | ... N24: =Tax!N12 -> -2858901.6
B25: EQUITY FREE CASH FLOW | D25: =D18+D19+D20+D21+D22+D23+D24 -> -1.0801938e+08 | E25: =E18+E19+E20+E21+E22+E23+E24 -> 1863947.5 | F25: =F18+F19+F20+F21+F22+F23+F24 -> 1835518.7 | G25: =G18+G19+G20+G21+G22+G23+G24 -> 2184727.4 | H25: =H18+H19+H20+H21+H22+H23+H24 -> 2153921 | I25: =I18+I19+I20+I21+I22+I23+I24 -> -357174.65 | J25: =J18+J19+J20+J21+J22+J23+J24 -> 2477295.4 | K25: =K18+K19+K20+K21+K22+K23+K24 -> 2841576.9 | ... N25: =N18+N19+N20+N21+N22+N23+N24 -> 92195097
B26: Cumulative equity FCF | D26: =D25 -> -1.0801938e+08 | E26: =D26+E25 -> -1.0615543e+08 | F26: =E26+F25 -> -1.0431991e+08 | G26: =F26+G25 -> -1.0213518e+08 | H26: =G26+H25 -> -99981260 | I26: =H26+I25 -> -1.0033844e+08 | J26: =I26+J25 -> -97861140 | K26: =J26+K25 -> -95019563 | L26: =K26+L25 -> -92214180 | ... N26: =M26+N25 -> 3158039.7

Sheet DCF
B2: DCF VALUATION (Unlevered) — Exit-Cap method, no double-count
B3: Period | D3: 0 | E3: 1 | F3: 2 | G3: 3 | H3: 4 | I3: 5 | J3: 6 | K3: 7 | L3: 8 | M3: 9 | N3: 10
B4: Year | D4: =Assumptions!$D$6+0 -> 2025 | E4: =Assumptions!$D$6+1 -> 2026 | F4: =Assumptions!$D$6+2 -> 2027 | G4: =Assumptions!$D$6+3 -> 2028 | H4: =Assumptions!$D$6+4 -> 2029 | I4: =Assumptions!$D$6+5 -> 2030 | J4: =Assumptions!$D$6+6 -> 2031 | K4: =Assumptions!$D$6+7 -> 2032 | L4: =Assumptions!$D$6+8 -> 2033 | M4: =Assumptions!$D$6+9 -> 2034 | N4: =Assumptions!$D$6+10 -> 2035
B5: EXIT VALUE BUILD (forward NOI method)
B6: Forward NOI (Y+1 of exit year) | D6: =IF(0=Assumptions!$D$7,OpEx_CapEx!D9*(1+Assumptions!$D$20/Assumptions!$D$21),0) -> 0 | E6: =IF(1=Assumptions!$D$7,OpEx_CapEx!E9*(1+Assumptions!$D$20/Assumptions!$D$21),0) -> 0 | F6: =IF(2=Assumptions!$D$7,OpEx_CapEx!F9*(1+Assumptions!$D$20/Assumptions!$D$21),0) -> 0 | G6: =IF(3=Assumptions!$D$7,OpEx_CapEx!G9*(1+Assumptions!$D$20/Assumptions!$D$21),0) -> 0 | H6: =IF(4=Assumptions!$D$7,OpEx_CapEx!H9*(1+Assumptions!$D$20/Assumptions!$D$21),0) -> 0 | I6: =IF(5=Assumptions!$D$7,OpEx_CapEx!I9*(1+Assumptions!$D$20/Assumptions!$D$21),0) -> 0 | J6: =IF(6=Assumptions!$D$7,OpEx_CapEx!J9*(1+Assumptions!$D$20/Assumptions!$D$21),0) -> 0 | K6: =IF(7=Assumptions!$D$7,OpEx_CapEx!K9*(1+Assumptions!$D$20/Assumptions!$D$21),0) -> 0 | L6: =IF(8=Assumptions!$D$7,OpEx_CapEx!L9*(1+Assumptions!$D$20/Assumptions!$D$21),0) -> 0 | M6: =IF(9=Assumptions!$D$7,OpEx_CapEx!M9*(1+Assumptions!$D$20/Assumptions!$D$21),0) -> 0 | N6: =IF(10=Assumptions!$D$7,OpEx_CapEx!N9*(1+Assumptions!$D$20/Assumptions!$D$21),0) -> 15217053
B7: Exit cap rate | D7: =IF(0=Assumptions!$D$7,Assumptions!$D$51,0) -> 0 | E7: =IF(1=Assumptions!$D$7,Assumptions!$D$51,0) -> 0 | F7: =IF(2=Assumptions!$D$7,Assumptions!$D$51,0) -> 0 | G7: =IF(3=Assumptions!$D$7,Assumptions!$D$51,0) -> 0 | H7: =IF(4=Assumptions!$D$7,Assumptions!$D$51,0) -> 0 | I7: =IF(5=Assumptions!$D$7,Assumptions!$D$51,0) -> 0 | J7: =IF(6=Assumptions!$D$7,Assumptions!$D$51,0) -> 0 | K7: =IF(7=Assumptions!$D$7,Assumptions!$D$51,0) -> 0 | L7: =IF(8=Assumptions!$D$7,Assumptions!$D$51,0) -> 0 | M7: =IF(9=Assumptions!$D$7,Assumptions!$D$51,0) -> 0 | N7: =IF(10=Assumptions!$D$7,Assumptions!$D$51,0) -> 0.075
B8: Disposal costs % (broker + legal + other) | D8: =IF(0=Assumptions!$D$7,Assumptions!$D$52+Assumptions!$D$53+Assumptions!$D$54,0) -> 0 | E8: =IF(1=Assumptions!$D$7,Assumptions!$D$52+Assumptions!$D$53+Assumptions!$D$54,0) -> 0 | F8: =IF(2=Assumptions!$D$7,Assumptions!$D$52+Assumptions!$D$53+Assumptions!$D$54,0) -> 0 | G8: =IF(3=Assumptions!$D$7,Assumptions!$D$52+Assumptions!$D$53+Assumptions!$D$54,0) -> 0 | H8: =IF(4=Assumptions!$D$7,Assumptions!$D$52+Assumptions!$D$53+Assumptions!$D$54,0) -> 0 | I8: =IF(5=Assumptions!$D$7,Assumptions!$D$52+Assumptions!$D$53+Assumptions!$D$54,0) -> 0 | J8: =IF(6=Assumptions!$D$7,Assumptions!$D$52+Assumptions!$D$53+Assumptions!$D$54,0) -> 0 | K8: =IF(7=Assumptions!$D$7,Assumptions!$D$52+Assumptions!$D$53+Assumptions!$D$54,0) -> 0 | L8: =IF(8=Assumptions!$D$7,Assumptions!$D$52+Assumptions!$D$53+Assumptions!$D$54,0) -> 0 | M8: =IF(9=Assumptions!$D$7,Assumptions!$D$52+Assumptions!$D$53+Assumptions!$D$54,0) -> 0 | N8: =IF(10=Assumptions!$D$7,Assumptions!$D$52+Assumptions!$D$53+Assumptions!$D$54,0) -> 0.03
B9: GROSS EXIT VALUE = Forward NOI / Exit Cap | D9: =IFERROR(IF(D7=0,0,D6/D7),0) -> 0 | E9: =IFERROR(IF(E7=0,0,E6/E7),0) -> 0 | F9: =IFERROR(IF(F7=0,0,F6/F7),0) -> 0 | G9: =IFERROR(IF(G7=0,0,G6/G7),0) -> 0 | H9: =IFERROR(IF(H7=0,0,H6/H7),0) -> 0 | I9: =IFERROR(IF(I7=0,0,I6/I7),0) -> 0 | J9: =IFERROR(IF(J7=0,0,J6/J7),0) -> 0 | K9: =IFERROR(IF(K7=0,0,K6/K7),0) -> 0 | ... N9: =IFERROR(IF(N7=0,0,N6/N7),0) -> 2.0289404e+08
B10: NET EXIT VALUE (gross − disposal costs) | D10: =D9*(1-D8) -> 0 | E10: =E9*(1-E8) -> 0 | F10: =F9*(1-F8) -> 0 | G10: =G9*(1-G8) -> 0 | H10: =H9*(1-H8) -> 0 | I10: =I9*(1-I8) -> 0 | J10: =J9*(1-J8) -> 0 | K10: =K9*(1-K8) -> 0 | ... N10: =N9*(1-N8) -> 1.9680722e+08
B12: UNLEVERED DCF — PROJECT LEVEL
B13: Project FCF (unlevered) | D13: =Cash_Flow!D15 -> -2.155e+08 | E13: =Cash_Flow!E15 -> 12198300 | F13: =Cash_Flow!F15 -> 12168375 | G13: =Cash_Flow!G15 -> 12535963 | H13: =Cash_Flow!H15 -> 12503535 | I13: =Cash_Flow!I15 -> 9879075.4 | J13: =Cash_Flow!J15 -> 12843929 | K13: =Cash_Flow!K15 -> 13227384 | ... N13: =Cash_Flow!N15 -> 2.103465e+08
B14: Discount factor @ WACC | D14: =1/(1+Assumptions!$D$68)^0 -> 1 | E14: =1/(1+Assumptions!$D$68)^1 -> 0.92165899 | F14: =1/(1+Assumptions!$D$68)^2 -> 0.84945529 | G14: =1/(1+Assumptions!$D$68)^3 -> 0.7829081 | H14: =1/(1+Assumptions!$D$68)^4 -> 0.72157428 | I14: =1/(1+Assumptions!$D$68)^5 -> 0.66504542 | J14: =1/(1+Assumptions!$D$68)^6 -> 0.61294509 | K14: =1/(1+Assumptions!$D$68)^7 -> 0.56492635 | L14: =1/(1+Assumptions!$D$68)^8 -> 0.52066945 | M14: =1/(1+Assumptions!$D$68)^9 -> 0.47987968 | N14: =1/(1+Assumptions!$D$68)^10 -> 0.44228542
B15: PV of FCF | D15: =D13*D14 -> -2.155e+08 | E15: =E13*E14 -> 11242673 | F15: =F13*F14 -> 10336490 | G15: =G13*G14 -> 9814507 | H15: =H13*H14 -> 9022229.5 | I15: =I13*I14 -> 6570033.8 | J15: =J13*J14 -> 7872623.5 | K15: =K13*K14 -> 7472497.5 | ... N15: =N13*N14 -> 93033189
B17: NPV (Project) = Σ PV(Project FCF) | D17: =SUM(D15:N15) -> -46751451
B18: Enterprise Value (EV) = NPV + Initial Outflow Reversed | D18: =D17-Cash_Flow!D12 -> 1.6874855e+08 | F18: Note: EV here = sum of PV future cash flows excluding acquisition.
B20: LEVERED DCF — EQUITY LEVEL
B21: Equity FCF (levered) | D21: =Cash_Flow!D25 -> -1.0801938e+08 | E21: =Cash_Flow!E25 -> 1863947.5 | F21: =Cash_Flow!F25 -> 1835518.7 | G21: =Cash_Flow!G25 -> 2184727.4 | H21: =Cash_Flow!H25 -> 2153921 | I21: =Cash_Flow!I25 -> -357174.65 | J21: =Cash_Flow!J25 -> 2477295.4 | K21: =Cash_Flow!K25 -> 2841576.9 | ... N21: =Cash_Flow!N25 -> 92195097
B22: Discount factor @ Cost of Equity | D22: =1/(1+Assumptions!$D$66)^0 -> 1 | E22: =1/(1+Assumptions!$D$66)^1 -> 0.90909091 | F22: =1/(1+Assumptions!$D$66)^2 -> 0.82644628 | G22: =1/(1+Assumptions!$D$66)^3 -> 0.7513148 | H22: =1/(1+Assumptions!$D$66)^4 -> 0.68301346 | I22: =1/(1+Assumptions!$D$66)^5 -> 0.62092132 | J22: =1/(1+Assumptions!$D$66)^6 -> 0.56447393 | K22: =1/(1+Assumptions!$D$66)^7 -> 0.51315812 | L22: =1/(1+Assumptions!$D$66)^8 -> 0.46650738 | M22: =1/(1+Assumptions!$D$66)^9 -> 0.42409762 | N22: =1/(1+Assumptions!$D$66)^10 -> 0.38554329
B23: PV of Equity FCF | D23: =D21*D22 -> -1.0801938e+08 | E23: =E21*E22 -> 1694497.7 | F23: =F21*F22 -> 1516957.6 | G23: =G21*G22 -> 1641418 | H23: =H21*H22 -> 1471157 | I23: =I21*I22 -> -221777.35 | J23: =J21*J22 -> 1398368.7 | K23: =K21*K22 -> 1458178.2 | ... N23: =N21*N22 -> 35545201
B25: NPV (Equity) = Σ PV(Equity FCF) | D25: =SUM(D23:N23) -> -60859232

Sheet Returns
B2: RETURN METRICS
B4: PROFITABILITY
B5: Project IRR (unlevered) | D5: =IFERROR(IRR(Cash_Flow!D15:N15),0) -> 0.051117548
B6: Equity IRR (levered, post-tax) | D6: =IFERROR(IRR(Cash_Flow!D25:N25),0) -> 0.0031276319
B7: WACC (hurdle for project) | D7: =Assumptions!$D$68 -> 0.085
B8: Hurdle rate (equity) | D8: =Assumptions!$D$71 -> 0.1
B9: Project IRR vs WACC (gap) | D9: =D5-D7 -> -0.033882452
B10: Equity IRR vs Hurdle (gap) | D10: =D6-D8 -> -0.096872368
B11: NPV @ WACC (Project) | D11: =DCF!D17 -> -46751451
B12: NPV @ Ke (Equity) | D12: =DCF!D25 -> -60859232
B14: EQUITY MULTIPLES & PAYBACK
B15: Initial equity invested (Y0 only) | D15: =ABS(Cash_Flow!D25) -> 1.0801938e+08
B16: Sum of all positive equity distributions | D16: =SUMIF(Cash_Flow!D25:N25,">0") -> 1.1153459e+08
B17: MOIC on initial equity (distributions/initial) | D17: =IFERROR(D16/D15,0) -> 1.0325424
B18: MOIC target | D18: =Assumptions!$D$72 -> 1.75
B19: Payback period (years until cumul. equity FCF ≥ 0) | D19: =IFERROR(MATCH(TRUE(),INDEX(Cash_Flow!E26:N26>=0,0),0),"Beyond exit") -> 10
B21: CURRENT-YEAR METRICS (Year 1)
B22: Cash-on-Cash (Y1 equity FCF ex arrangement fee / equity) | D22: =IFERROR((Cash_Flow!E25-Debt!E11)/Assumptions!$D$48,0) -> 0.017298817
B23: Yield on cost (Y1 NOI / Total Cost) | D23: =IFERROR(OpEx_CapEx!E9/Assumptions!$D$16,0) -> 0.062819026
B24: Entry cap rate implied (Y1 NOI / Purchase price) | D24: =IFERROR(OpEx_CapEx!E9/Assumptions!$D$11,0) -> 0.0676875
B26: CREDIT METRICS
B27: Initial LTV (Debt / Total cost) | D27: =Assumptions!$D$47/Assumptions!$D$16 -> 0.5
B28: Min DSCR over life | D28: =IFERROR(MIN(Debt!E16:N16),0) -> 0.13003595
B29: Avg DSCR | D29: =IFERROR(AVERAGE(Debt!E16:M16),0) -> 1.8799383
B30: Avg debt yield (NOI / Debt outstanding) | D30: =IFERROR(AVERAGE(Debt!E18:M18),0) -> 0.13159568
B31: Min Interest Coverage | D31: =IFERROR(MIN(Debt!E15:N15),0) -> 1.7919954
B33: BREAK-EVEN ANALYSIS
B34: Break-even vacancy (NOI covers debt service) | D34: =IFERROR(1-ABS(Debt!E12)/(Assumptions!$D$19*(1-Assumptions!$D$25-Assumptions!$D$26)),0) -> 0.47070175
B35: NOI cushion vs debt service (Y1) | D35: =OpEx_CapEx!E9-ABS(Debt!E12) -> 5995000
B36: Min DSCR excl. bullet year (Y1–Y9) | D36: =MIN(Debt!E16:M16) -> 1.7919954

Sheet Scenarios
B2: SCENARIO ANALYSIS — Base / Downside / Severe / Upside
B3: Scenarios shock key drivers vs base. Compare equity IRR, NPV, DSCR, MOIC.
B5: Driver | C5: Base | D5: Downside | E5: Severe | F5: Upside
B6: Revenue growth (Δ pp) | C6: 0 | D6: -0.01 | E6: -0.03 | F6: 0.01
B7: Y1 vacancy (Δ pp) | C7: 0 | D7: 0.05 | E7: 0.15 | F7: -0.03
B8: OpEx (Δ % multiplier) | C8: 0 | D8: 0.1 | E8: 0.25 | F8: -0.05
B9: Exit cap rate (Δ bps) | C9: 0 | D9: 50 | E9: 150 | F9: -25
B10: Cost of debt (Δ bps) | C10: 0 | D10: 100 | E10: 250 | F10: -25
B12: SCENARIO IMPACT (estimated, using single-factor shocks via Sensitivity sheet)
B13: See Sensitivity sheet for two-way matrices on each driver.
B14: For full multi-factor scenarios, copy the workbook, change the BLUE inputs on Assumptions, and re-read Returns.
B16: Scenario operating instructions:
B17: 1. To run a scenario, change ONLY the blue cells on the Assumptions sheet.
B18: 2. The whole model re-flows. Read updated metrics on Returns and Dashboard.
B19: 3. To compare side-by-side, save the workbook under each scenario name (e.g. v4_Base.xlsx).
B20: 4. For automated multi-scenario tables, see the Sensitivity sheet which uses one-way shocks.

Sheet Sensitivity
B2: SENSITIVITY ANALYSIS
B3: Excel two-variable data tables are not auto-generated by Python. To populate, use Data > What-If > Data Table on the matrices below.
B5: EXIT CAP RATE SENSITIVITY (Equity IRR)
B6: Equity IRR (base case) | D6: =Returns!D6 -> 0.0031276319
B8: Exit cap rate Δ: | C8: -0.01 | D8: -0.005 | E8: 0 | F8: 0.005 | G8: 0.01 | H8: 0.015
B9: Resulting exit cap | C9: =Assumptions!$D$51+C8 -> 0.065 | D9: =Assumptions!$D$51+D8 -> 0.07 | E9: =Assumptions!$D$51+E8 -> 0.075 | F9: =Assumptions!$D$51+F8 -> 0.08 | G9: =Assumptions!$D$51+G8 -> 0.085 | H9: =Assumptions!$D$51+H8 -> 0.09
B10: Gross exit value (SAR) | C10: =DCF!N6/C9 -> 2.3410851e+08 | D10: =DCF!N6/D9 -> 2.1738647e+08 | E10: =DCF!N6/E9 -> 2.0289404e+08 | F10: =DCF!N6/F9 -> 1.9021316e+08 | G10: =DCF!N6/G9 -> 1.7902415e+08 | H10: =DCF!N6/H9 -> 1.6907836e+08
B11: Net exit value (after disposal costs) | C11: =C10*(1-Assumptions!$D$52-Assumptions!$D$53-Assumptions!$D$54) -> 2.2708525e+08 | D11: =D10*(1-Assumptions!$D$52-Assumptions!$D$53-Assumptions!$D$54) -> 2.1086487e+08 | E11: =E10*(1-Assumptions!$D$52-Assumptions!$D$53-Assumptions!$D$54) -> 1.9680722e+08 | F11: =F10*(1-Assumptions!$D$52-Assumptions!$D$53-Assumptions!$D$54) -> 1.8450677e+08 | G11: =G10*(1-Assumptions!$D$52-Assumptions!$D$53-Assumptions!$D$54) -> 1.7365343e+08 | H11: =H10*(1-Assumptions!$D$52-Assumptions!$D$53-Assumptions!$D$54) -> 1.6400601e+08
B12: Δ equity proceeds at exit | C12: =C11-DCF!N10 -> 30278033 | D12: =D11-DCF!N10 -> 14057658 | E12: =E11-DCF!N10 -> 0 | F12: =F11-DCF!N10 -> -12300451 | G12: =G11-DCF!N10 -> -23153790 | H12: =H11-DCF!N10 -> -32801203
B14: VACANCY SENSITIVITY (Y1 NOI)
B15: Vacancy rate | C15: 0 | D15: 0.025 | E15: 0.05 | F15: 0.1 | G15: 0.15 | H15: 0.2
B16: Y1 EGI | C16: =Assumptions!$D$19*(1-C15) -> 15000000 | D16: =Assumptions!$D$19*(1-D15) -> 14625000 | E16: =Assumptions!$D$19*(1-E15) -> 14250000 | F16: =Assumptions!$D$19*(1-F15) -> 13500000 | G16: =Assumptions!$D$19*(1-G15) -> 12750000 | H16: =Assumptions!$D$19*(1-H15) -> 12000000
B17: Y1 NOI (approx) | C17: =C16*(1-Assumptions!$D$25-Assumptions!$D$26) -> 14250000 | D17: =D16*(1-Assumptions!$D$25-Assumptions!$D$26) -> 13893750 | E17: =E16*(1-Assumptions!$D$25-Assumptions!$D$26) -> 13537500 | F17: =F16*(1-Assumptions!$D$25-Assumptions!$D$26) -> 12825000 | G17: =G16*(1-Assumptions!$D$25-Assumptions!$D$26) -> 12112500 | H17: =H16*(1-Assumptions!$D$25-Assumptions!$D$26) -> 11400000
B18: Y1 DSCR (approx) | C18: =IFERROR(C17/ABS(Debt!E12),0) -> 1.889294 | D18: =IFERROR(D17/ABS(Debt!E12),0) -> 1.8420617 | E18: =IFERROR(E17/ABS(Debt!E12),0) -> 1.7948293 | F18: =IFERROR(F17/ABS(Debt!E12),0) -> 1.7003646 | G18: =IFERROR(G17/ABS(Debt!E12),0) -> 1.6058999 | H18: =IFERROR(H17/ABS(Debt!E12),0) -> 1.5114352
B20: COST OF DEBT SENSITIVITY (Y1 DSCR)
B21: Cost of debt | C21: 0.05 | D21: 0.06 | E21: 0.07 | F21: 0.08 | G21: 0.09 | H21: 0.1
B22: Y1 interest (approx) | C22: =Assumptions!$D$47*C21 -> 5387500 | D22: =Assumptions!$D$47*D21 -> 6465000 | E22: =Assumptions!$D$47*E21 -> 7542500 | F22: =Assumptions!$D$47*F21 -> 8620000 | G22: =Assumptions!$D$47*G21 -> 9697500 | H22: =Assumptions!$D$47*H21 -> 10775000
B23: Y1 DSCR (approx, interest-only proxy) | C23: =IFERROR(OpEx_CapEx!E9/C22,0) -> 2.512761 | D23: =IFERROR(OpEx_CapEx!E9/D22,0) -> 2.0939675 | E23: =IFERROR(OpEx_CapEx!E9/E22,0) -> 1.7948293 | F23: =IFERROR(OpEx_CapEx!E9/F22,0) -> 1.5704756 | G23: =IFERROR(OpEx_CapEx!E9/G22,0) -> 1.3959783 | H23: =IFERROR(OpEx_CapEx!E9/H22,0) -> 1.2563805

Sheet Audit
B2: MODEL INTEGRITY CHECKS
B3: All checks must return OK before model is used for IC/financing.
B5: Check | C5: Expected | D5: Actual | E5: Status
B6: Debt + Equity = Total cost | C6: =Assumptions!$D$16 -> 2.155e+08 | D6: =Assumptions!$D$47+Assumptions!$D$48 -> 2.155e+08 | E6: =IF(ABS(D6-C6)<MAX(1,ABS(C6)*0.001),"OK","REVIEW") -> OK
B7: Y0 acquisition outflow = Total cost (negative) | C7: =-Assumptions!$D$16 -> -2.155e+08 | D7: =Cash_Flow!D12 -> -2.155e+08 | E7: =IF(ABS(D7-C7)<MAX(1,ABS(C7)*0.001),"OK","REVIEW") -> OK
B8: Y0 debt drawdown = Debt amount | C8: =Assumptions!$D$47 -> 1.0775e+08 | D8: =Debt!D6 -> 1.0775e+08 | E8: =IF(ABS(D8-C8)<MAX(1,ABS(C8)*0.001),"OK","REVIEW") -> OK
B9: Debt closing balance at exit = 0 | C9: =0 -> 0 | D9: =Debt!N9 -> 0 | E9: =IF(ABS(D9-C9)<MAX(1,ABS(C9)*0.001),"OK","REVIEW") -> OK
B10: Sum of principal+bullet across life = Debt amount | C10: =Assumptions!$D$47 -> 1.0775e+08 | D10: =ABS(SUM(Debt!D7:N7))+ABS(SUM(Debt!D8:N8)) -> 1.0775e+08 | E10: =IF(ABS(D10-C10)<MAX(1,ABS(C10)*0.001),"OK","REVIEW") -> OK
B11: Project FCF positive in Y_exit (driven by exit value) | C11: Positive | D11: =Cash_Flow!N15 -> 2.103465e+08 | E11: =IF(D11>0,"OK","ERROR") -> OK
B12: Equity outflow only in Y0 | C12: Only Y0 negative | D12: =COUNTIF(Cash_Flow!E25:N25,"<0") -> 1 | E12: =IF(D12=0,"OK","ERROR") -> ERROR
B13: WACC > Cost of debt after-tax | C13: WACC > Kd | D13: =IF(Assumptions!$D$68>Assumptions!$D$67,"OK","ERROR") -> OK | E13: =IF(D13="OK","OK","ERROR") -> OK
B14: Min DSCR ≥ Min DSCR threshold | C14: =Assumptions!$D$73 -> 1.3 | D14: =IFERROR(MIN(Debt!E16:N16),0) -> 0.13003595 | E14: =IF(D14>=C14,"OK","ERROR") -> ERROR
B15: Initial LTV ≤ Max LTV | C15: =Assumptions!$D$74 -> 0.6 | D15: =Assumptions!$D$47/Assumptions!$D$16 -> 0.5 | E15: =IF(D15<=C15,"OK","ERROR") -> OK
B16: Equity IRR ≥ Hurdle | C16: =Assumptions!$D$71 -> 0.1 | D16: =Returns!D6 -> 0.0031276319 | E16: =IF(D16>=C16,"OK","ERROR") -> ERROR
B17: Project IRR ≥ WACC | C17: =Assumptions!$D$68 -> 0.085 | D17: =Returns!D5 -> 0.051117548 | E17: =IF(D17>=C17,"OK","ERROR") -> ERROR
B18: NPV (Project) ≥ 0 | C18: ≥ 0 | D18: =DCF!D17 -> -46751451 | E18: =IF(D18>0,"OK","ERROR") -> ERROR
B19: MOIC ≥ MOIC target | C19: =Assumptions!$D$72 -> 1.75 | D19: =Returns!D17 -> 1.0325424 | E19: =IF(D19>=C19,"OK","ERROR") -> ERROR
B20: Exit value computed only at exit year | C20: 1 non-zero cell | D20: =COUNTIF(DCF!D9:N9,">0") -> 1 | E20: =IF(D20=1,"OK","ERROR") -> OK
B21: Tax line is non-positive (cash outflow) | C21: ≤ 0 every year | D21: =COUNTIF(Cash_Flow!E24:N24,">0") -> 0 | E21: =IF(D21=0,"OK","ERROR") -> OK

Sheet Dashboard
B2: EXECUTIVE DASHBOARD — Bin Amer Holding Investment Committee
B4: CREDIT METRICS
B5: Closing year (Y0) | D5: =Assumptions!$D$6 -> 2025
B6: Exit year (Y_exit) | D6: =Assumptions!$D$8 -> 2035
B7: Holding period | D7: =Assumptions!$D$7 -> 10
B8: Asset purchase price | D8: =Assumptions!$D$11 -> 200000000
B9: Total project cost | D9: =Assumptions!$D$16 -> 2.155e+08
B10: Equity required | D10: =Assumptions!$D$48 -> 1.0775e+08
B11: Debt required | D11: =Assumptions!$D$47 -> 1.0775e+08
B12: Initial LTV | D12: =Assumptions!$D$47/Assumptions!$D$16 -> 0.5
B14: RETURN METRICS
B15: Project IRR (unlevered) | D15: =Returns!D5 -> 0.051117548
B16: Equity IRR (levered, post-tax) | D16: =Returns!D6 -> 0.0031276319
B17: WACC | D17: =Assumptions!$D$68 -> 0.085
B18: Hurdle rate | D18: =Assumptions!$D$71 -> 0.1
B19: NPV @ WACC (Project) | D19: =DCF!D17 -> -46751451
B20: NPV @ Ke (Equity) | D20: =DCF!D25 -> -60859232
B21: MOIC | D21: =Returns!D17 -> 1.0325424
B22: Payback period | D22: =Returns!D19 -> 10
B23: Cash-on-Cash (Y1) | D23: =Returns!D22 -> 0.017298817
B24: Yield on cost (Y1) | D24: =Returns!D23 -> 0.062819026
B26: CREDIT METRICS
B27: Min DSCR over life | D27: =Returns!D28 -> 0.13003595
B28: Avg DSCR | D28: =Returns!D29 -> 1.8799383
B29: Avg Debt Yield | D29: =Returns!D30 -> 0.13159568
B30: Min Interest Coverage | D30: =Returns!D31 -> 1.7919954
B31: Min DSCR threshold | D31: =Assumptions!$D$73 -> 1.3
B32: Initial LTV vs Max LTV | D32: =Returns!D27 & " / " & TEXT(Assumptions!$D$74,"0.0%") -> 0.5 / 60.0%
B34: AUDIT STATUS
B35: Number of audit checks passed | D35: =COUNTIF(Audit!E6:E25,"OK") -> 10
B36: Number of audit checks failed | D36: =COUNTIF(Audit!E6:E25,"ERROR") -> 6
B37: Checks requiring review | D37: =COUNTIF(Audit!E6:E25,"REVIEW") -> 0
B39: INVESTMENT COMMITTEE RECOMMENDATION
B40: Decision logic: Equity IRR ≥ Hurdle, NPV(Project) > 0, Min DSCR ≥ threshold, LTV ≤ Max, Audit clean
B41: RECOMMENDATION | D41: =IF(AND(Returns!D6>=Assumptions!$D$71,DCF!D17>0,Returns!D28>=Assumptions!$D$73,Assumptions!$D$47/Assumptions!$D$16<=Assumptions!$D$74,D36=0),"PROCEED",IF(AND(Returns!D6>=Assumptions!$D$68,DCF!D17>0,D36=0),"CONDITIONAL — Mitigations Required","REJECT — Does Not Meet Criteria")) -> REJECT — Does Not Meet Criteria
B43: KEY DEAL DRIVERS (interpret with caution)
B44: • Outcome is most sensitive to: exit cap rate, Y1 vacancy, OpEx, cost of debt.
B45: • DSCR collapses at exit year if bullet repayment + interest exceed NOI — check Debt!N16.
B46: • Zakat & withholding tax reduce equity IRR by ~30–80 bps depending on structure.
B47: • Forward NOI used in exit value reflects 1-period escalation — verify with broker comps.
...
