Workbook

Sheet Cover
B2: BIN AMER REAL ESTATE FUND — Investment Model v6.0
B3: صندوق بن عامر العقاري الخاص — نموذج استثمار 6.0
B5: Document type | C5: Saudi Private RE Fund — Financial Model (Information Memorandum support)
B6: Sponsor | C6: Bin Amer Holding (مجموعة بن عامر القابضة)
B7: Vehicle | C7: Saudi closed-end Private Real Estate Fund — CMA-licensed
B8: Currency | C8: SAR
B9: Fund life | C9: 5 years (extendable by 1 year with LP consent)
B10: Status | C10: Pre-launch — for qualified-investor discussion only
B13: KEY FACTS (from Information Memorandum)
B14: Total portfolio (book) | C14: SAR 242.4M (29 properties)
B15: Current annual rental | C15: SAR 9.82M (gross yield 4.05%)
B16: Mortgaged properties | C16: 12 of 29 (SAR 117.3M book) securing >SAR 100M debt
B17: Unmortgaged properties | C17: 11 of 29 (SAR 99.6M book)
B18: Idle / inactive properties | C18: 11 of 29 (38%)
B19: Geographic concentration | C19: Mecca >60%, Jeddah, Riyadh, Dammam, Taif
B20: Largest by value | C20: Al-Misfalah lands, Mecca (SAR 60.3M, mortgaged)
B21: Largest by income | C21: Al-Hafayer Hotel, Mecca (SAR 4M/yr = 41% of income)
B22: Vacant land | C22: 9 properties / SAR 118.3M / zero income
B23: Fund target NAV at close | C23: SAR 230–300M
B24: Sponsor in-kind contribution | C24: SAR 130–170M (net of debt)
B25: New LP cash commitment | C25: SAR 100–130M
... B33: Setup fee | C33: 1% of LP commitments (one-time)
B36: SHEET MAP
B37: Fund_Summary | C37: Single-page IC dashboard
B38: Assumptions | C38: All model inputs (BLUE = user input)
B39: Portfolio | C39: 29-property rent roll: value, income, mortgage, category
B40: Activation | C40: 4 idle assets — ramp timeline + value-add
B41: Sources_Uses | C41: Fund formation: in-kind + LP cash → debt settle + activation + reserves
B42: Debt_Restructure | C42: Settlement scenarios (haircut 25–35%)
B43: Revenue | C43: Annual rental + asset-sale revenue build
B44: OpEx_Fees | C44: Property opex + management fees + custodian + setup
B45: Fund_CF | C45: 5-year fund-level cash flow
B46: NAV_Trajectory | C46: NAV evolution (closing through exit)
B47: Waterfall | C47: European waterfall — LP pref / GP catch-up / 80-20 carry
B48: LP_Returns | C48: LP IRR / MOIC / Cash-on-Cash
... B54: Audit | C54: Integrity checks (sources=uses, balance, sign convention)

Sheet Fund_Summary
B2: FUND SUMMARY — IC One-Pager
B4: FUND STRUCTURE
B5: Sponsor | C5: "Bin Amer Holding"
B6: Vehicle | C6: "Saudi Private RE Fund (CMA-licensed)"
B7: Fund life | C7: =Assumptions!$D$6&" years"
B8: Currency | C8: "SAR"
B9: Sharia compliance | C9: "Yes — independent board"
B11: CAPITAL
B12: Total fund equity at close | C12: =Assumptions!$D$18
B13: LP commitment (cash) | C13: =Assumptions!$D$17
B14: Sponsor in-kind | C14: =Assumptions!$D$16
B15: LP ownership % | C15: =Assumptions!$D$19
B16: Initial portfolio value (gross) | C16: =Assumptions!$D$10
B17: Existing senior debt (face) | C17: =Assumptions!$D$30
B18: Settlement cash needed | C18: =Assumptions!$D$32
B19: Settlement haircut benefit | C19: =Assumptions!$D$33
B21: RETURNS (LP)
B22: LP IRR (target 12–15%) | C22: =LP_Returns!$C$12
B23: LP MOIC (target 1.7–2.0x) | C23: =LP_Returns!$C$11
B24: Cash-on-Cash Y2 | C24: =LP_Returns!$C$15
B25: Cash-on-Cash Y3 | C25: =LP_Returns!$C$16
B26: LP NPV @ 13% | C26: =LP_Returns!$C$13
B28: AUDIT
B29: Checks OK | C29: =Audit!$C$22
B30: Checks REVIEW | C30: =Audit!$C$23
B31: Checks ERROR | C31: =Audit!$C$24
B33: RECOMMENDATION
B34: =IF(AND(LP_Returns!$C$12>=0.12,LP_Returns!$C$11>=1.7,Audit!$C$24=0),"PROCEED TO DD",IF(LP_Returns!$C$12>=0.08,"DD WITH CAUTION","REJECT"))

Sheet Assumptions
B2: ASSUMPTIONS — Single source of truth (BLUE = input)
B4: 1. FUND TIMING
B5: Fund close year (Y0) | D5: 2026 | E5: year | F5: First close
B6: Fund life (years) | D6: 5 | E6: yrs | F6: Closed-end. 1-yr extension flex.
B7: Exit year | D7: =$D$5+$D$6 | E7: year | F7: Calculated
B9: 2. PORTFOLIO (anchor)
B10: Total portfolio book value | D10: 242413692 | E10: SAR | F10: From IM Table 0 R2 — 29 properties
B11: Current annual rental income | D11: 9817600 | E11: SAR | F11: From IM Table 0 R3 — pre-activation Y0 run-rate
B12: Current gross yield (implied) | D12: =$D$11/$D$10 | E12: % | F12: Calculated — 4.05%
B13: Vacant-land share of portfolio | D13: 0.488 | E13: % | F13: SAR 118.3M / SAR 242.4M; zero current income
B15: 3. CAPITAL STRUCTURE AT CLOSING
B16: Sponsor in-kind contribution (net of debt) | D16: 145000000 | E16: SAR | F16: Mid-point of SAR 130–170M range; assets net of debt
B17: LP new cash commitment | D17: 115000000 | E17: SAR | F17: Mid-point of SAR 100–130M target
B18: Total fund equity at close | D18: =$D$16+$D$17 | E18: SAR | F18: Initial NAV before debt settlement uses
B19: LP ownership % | D19: =$D$17/$D$18 | E19: % | F19: Calculated
B20: Sponsor ownership % | D20: =$D$16/$D$18 | E20: % | F20: Calculated
B22: 4. USE OF LP CASH (mid-point of doc Table 3)
B23: Debt settlement share | D23: 0.6 | E23: % | F23: 55–65% range; cash paid to creditors
B24: Asset activation share | D24: 0.25 | E24: % | F24: 20–25% range; capex on RE-006, RE-018, RE-020, RE-029
B25: Operating reserve share | D25: 0.12 | E25: % | F25: 10–15% range; working-cap + contingency
B26: Setup/licensing share | D26: 0.03 | E26: % | F26: 3–5% range; CMA fees, valuation, legal
B27: Total use share check | D27: =SUM($D$23:$D$26) | E27: % | F27: Must = 100%
B29: 5. DEBT SETTLEMENT
B30: Existing senior debt (face) | D30: 100000000 | E30: SAR | F30: Bin Amer disclosed >SAR 100M
B31: Settlement haircut (creditors accept) | D31: 0.3 | E31: % | F31: 25–35% range; mid-point
B32: Cash needed to settle | D32: =$D$30*(1-$D$31) | E32: SAR | F32: Face × (1 − haircut)
B33: Cash freed by haircut | D33: =$D$30*$D$31 | E33: SAR | F33: Equity value created for fund
B34: LP cash earmarked for debt | D34: =$D$17*$D$23 | E34: SAR | F34: From LP cash × debt-settle share
B35: LP cash sufficiency vs need | D35: =$D$34-$D$32 | E35: SAR | F35: Positive = enough; negative = shortfall
B37: 6. ACTIVATION (idle assets ramp)
B38: RE-006 (Sulaymaniyah parking) — annual | D38: 400000 | E38: SAR | F38: 300–500K range, online in 1–3 months
B39: RE-018 (Hajj Tower) — annual | D39: 2000000 | E39: SAR | F39: 1–3M range, online in 3–6 months
B40: RE-020 (Al-Masarah villa) — annual | D40: 100000 | E40: SAR | F40: 80–120K range, online in 1–2 months
B41: RE-029 (Bathaa Quraish station) — annual | D41: 300000 | E41: SAR | F41: 200–400K range, online in 1–2 months
B42: Total activation income (steady-state) | D42: =SUM($D$38:$D$41) | E42: SAR | F42: Annual from Y2 onward
B43: Activation capex required | D43: 25900000 | E43: SAR | F43: From LP use of proceeds (25% × 115M)
B44: Activation ramp factor — Y1 | D44: 0.3 | E44: % | F44: Partial ramp during launch year
B45: Activation ramp factor — Y2 | D45: 0.9 | E45: % | F45: Near full ramp
B46: Activation ramp factor — Y3+ | D46: 1 | E46: % | F46: Full run-rate
B48: 7. RENT GROWTH & PROPERTY OPEX
...

Sheet Portfolio
B2: PORTFOLIO RENT ROLL — 29 properties
B3: Source: IM Tables 8, 9, 10. Top 10 detailed; remainder grouped by category.
B5: Code | C5: Property | D5: City | E5: Category | F5: Book value (SAR) | G5: Annual rent (SAR) | H5: Yield | I5: Mortgaged | J5: Notes
B6: RE-001 | C6: Al-Misfalah lands (10 parcels) | D6: Mecca | E6: Vacant land | F6: 60290000 | G6: 0 | H6: =IFERROR(G6/F6,0) | I6: Yes | J6: Largest; pre-2017 valuation
B7: RE-023 | C7: Al-Khumrah warehouse | D7: Jeddah | E7: Industrial | F7: 29110000 | G7: 1600000 | H7: =IFERROR(G7/F7,0) | I7: No | J7: Anchor income asset
B8: RE-003 | C8: Al-Bathaa Quraish lands | D8: Mecca | E8: Vacant land | F8: 20440000 | G8: 0 | H8: =IFERROR(G8/F8,0) | I8: No | J8: Potential sale Y1
B9: RE-025 | C9: Al-Hafayer Hotel | D9: Mecca | E9: Hotel | F9: 17910000 | G9: 4000000 | H9: =IFERROR(G9/F9,0) | I9: TBC | J9: 41% of portfolio income — concentration risk
B10: RE-002 | C10: Al-Shuhada (Bish'm) lands | D10: Mecca | E10: Vacant land | F10: 17080000 | G10: 0 | H10: =IFERROR(G10/F10,0) | I10: Yes | J10: Mortgaged; settle via fund proceeds
B11: RE-010 | C11: Al-Wasiq fuel station | D11: Mecca | E11: Gas station | F11: 15160000 | G11: 600000 | H11: =IFERROR(G11/F11,0) | I11: No | J11: Stable income
B12: RE-011 | C12: Al-Sulay center | D12: Riyadh | E12: Industrial | F12: 12430000 | G12: 645000 | H12: =IFERROR(G12/F12,0) | I12: Yes | J12: Mortgaged
B13: RE-004 | C13: Al-Khudayriyah building | D13: Dammam | E13: Commercial | F13: 11000000 | G13: 924000 | H13: =IFERROR(G13/F13,0) | I13: No | J13: Stable income
B14: RE-008 | C14: Al-Hada land (50% partnership) | D14: Taif | E14: Vacant land | F14: 10370000 | G14: 0 | H14: =IFERROR(G14/F14,0) | I14: Yes | J14: 50% partner; subject to partner consent
B15: RE-012 | C15: Al-Zaydi fuel station | D15: Mecca | E15: Gas station | F15: 9370000 | G15: 900000 | H15: =IFERROR(G15/F15,0) | I15: No | J15: Stable income
B16: RE-006 | C16: Sulaymaniyah parking | D16: Riyadh | E16: Commercial | F16: 5500000 | G16: 0 | H16: =IFERROR(G16/F16,0) | I16: No | J16: ACTIVATION — SAR 0.4M/yr potential
B17: RE-018 | C17: Hajj Tower (ownership TBC) | D17: Mecca | E17: Commercial | F17: 20000000 | G17: 0 | H17: =IFERROR(G17/F17,0) | I17: TBC | J17: ACTIVATION — SAR 2.0M/yr potential
... B25: RE-019 | C25: Rabigh fuel station | D25: Rabigh | E25: Gas station | F25: 2500000 | G25: 200000 | H25: =IFERROR(G25/F25,0) | I25: No | J25: Small income
B26: RE-005 | C26: Residential villa #1 | D26: Jeddah | E26: Residential | F26: 1400000 | G26: 110000 | H26: =IFERROR(G26/F26,0) | I26: No
B27: RE-007 | C27: Residential villa #2 | D27: Jeddah | E27: Residential | F27: 1300000 | G27: 105000 | H27: =IFERROR(G27/F27,0) | I27: No
B28: RE-009 | C28: Residential apartment block | D28: Jeddah | E28: Residential | F28: 1600000 | G28: 130000 | H28: =IFERROR(G28/F28,0) | I28: No
B29: RE-021 | C29: Residential villa #3 | D29: Jeddah | E29: Residential | F29: 1500000 | G29: 115000 | H29: =IFERROR(G29/F29,0) | I29: No
B30: RE-022 | C30: Residential villa #4 | D30: Mecca | E30: Residential | F30: 1100000 | G30: 70000 | H30: =IFERROR(G30/F30,0) | I30: No
B31: RE-024 | C31: Kakkiyah lands (parcel) | D31: Mecca | E31: Vacant land | F31: 12500000 | G31: 0 | H31: =IFERROR(G31/F31,0) | I31: No | J31: Development study candidate
B32: RE-026 | C32: Misfalah small parcel | D32: Mecca | E32: Vacant land | F32: 3500000 | G32: 0 | H32: =IFERROR(G32/F32,0) | I32: Yes
B33: RE-027 | C33: Suburban vacant lot | D33: Riyadh | E33: Vacant land | F33: 4200000 | G33: 0 | H33: =IFERROR(G33/F33,0) | I33: No
B34: RE-028 | C34: Coastal land parcel | D34: Jeddah | E34: Vacant land | F34: 5200000 | G34: 0 | H34: =IFERROR(G34/F34,0) | I34: No | J34: Long-term hold
B36: TOTAL | E36: 29 properties | F36: =SUM(F6:F34) | G36: =SUM(G6:G34) | H36: =IFERROR(G36/F36,0) | I36: —
B39: BY CATEGORY
B40: Category | C40: Count | D40: Value | E40: Income | F40: Yield
B41: Hotel | C41: =COUNTIF(E6:E34,"Hotel") | D41: =SUMIF(E6:E34,"Hotel",F6:F34) | E41: =SUMIF(E6:E34,"Hotel",G6:G34) | F41: =IFERROR(E41/D41,0)
B42: Industrial | C42: =COUNTIF(E6:E34,"Industrial") | D42: =SUMIF(E6:E34,"Industrial",F6:F34) | E42: =SUMIF(E6:E34,"Industrial",G6:G34) | F42: =IFERROR(E42/D42,0)
B43: Gas station | C43: =COUNTIF(E6:E34,"Gas station") | D43: =SUMIF(E6:E34,"Gas station",F6:F34) | E43: =SUMIF(E6:E34,"Gas station",G6:G34) | F43: =IFERROR(E43/D43,0)
B44: Commercial | C44: =COUNTIF(E6:E34,"Commercial") | D44: =SUMIF(E6:E34,"Commercial",F6:F34) | E44: =SUMIF(E6:E34,"Commercial",G6:G34) | F44: =IFERROR(E44/D44,0)
B45: Residential | C45: =COUNTIF(E6:E34,"Residential") | D45: =SUMIF(E6:E34,"Residential",F6:F34) | E45: =SUMIF(E6:E34,"Residential",G6:G34) | F45: =IFERROR(E45/D45,0)
B46: Vacant land | C46: =COUNTIF(E6:E34,"Vacant land") | D46: =SUMIF(E6:E34,"Vacant land",F6:F34) | E46: =SUMIF(E6:E34,"Vacant land",G6:G34) | F46: =IFERROR(E46/D46,0)

Sheet Activation
B2: ASSET ACTIVATION — Idle Assets Ramp-Up
B3: 4 idle assets activated post-closing. Capex from LP cash. Ramp factors per Assumptions §6.
B5: Asset | C5: Steady-state rent | D5: Y1 | E5: Y2 | F5: Y3 | G5: Y4 | H5: Y5
B6: RE-006 — Sulaymaniyah parking | C6: =Assumptions!$D$38 | D6: =C6*Assumptions!$D$44 | E6: =C6*Assumptions!$D$45 | F6: =C6*Assumptions!$D$46 | G6: =C6*Assumptions!$D$46 | H6: =C6*Assumptions!$D$46
B7: RE-018 — Hajj Tower | C7: =Assumptions!$D$39 | D7: =C7*Assumptions!$D$44 | E7: =C7*Assumptions!$D$45 | F7: =C7*Assumptions!$D$46 | G7: =C7*Assumptions!$D$46 | H7: =C7*Assumptions!$D$46
B8: RE-020 — Al-Masarah villa | C8: =Assumptions!$D$40 | D8: =C8*Assumptions!$D$44 | E8: =C8*Assumptions!$D$45 | F8: =C8*Assumptions!$D$46 | G8: =C8*Assumptions!$D$46 | H8: =C8*Assumptions!$D$46
B9: RE-029 — Bathaa Quraish station | C9: =Assumptions!$D$41 | D9: =C9*Assumptions!$D$44 | E9: =C9*Assumptions!$D$45 | F9: =C9*Assumptions!$D$46 | G9: =C9*Assumptions!$D$46 | H9: =C9*Assumptions!$D$46
B10: TOTAL ACTIVATION INCOME | C10: =SUM(C6:C9) | D10: =SUM(D6:D9) | E10: =SUM(E6:E9) | F10: =SUM(F6:F9) | G10: =SUM(G6:G9) | H10: =SUM(H6:H9)
B12: Activation capex (from LP cash) | D12: =Assumptions!$D$43
B14: NOTE: Activation income is ADDITIONAL to current 9.82M base income.

Sheet Sources_Uses
B2: SOURCES & USES — Fund Formation
B3: Inception-day equity sources and capital uses (SAR).
B5: SOURCES OF CAPITAL
B6: Sponsor in-kind contribution (assets net of debt) | C6: =Assumptions!$D$16 | D6: =C6/$C$8 | E6: 44 properties net of mortgages
B7: LP new cash commitment | C7: =Assumptions!$D$17 | D7: =C7/$C$8 | E7: Qualified investors
B8: TOTAL SOURCES | C8: =C6+C7 | D8: =C8/$C$8
B10: USES OF LP CASH (SAR)
B11: Debt settlement (cash to creditors) | C11: =Assumptions!$D$32 | D11: =C11/Assumptions!$D$17 | E11: Settles SAR 100M face at 30% haircut
B12: Activation capex | C12: =Assumptions!$D$43 | D12: =C12/Assumptions!$D$17 | E12: RE-006/018/020/029
B13: Operating + contingency reserve | C13: =Assumptions!$D$17*Assumptions!$D$25 | D13: =C13/Assumptions!$D$17 | E13: Working-capital buffer
B14: Setup, licensing, valuation | C14: =Assumptions!$D$17*Assumptions!$D$26 | D14: =C14/Assumptions!$D$17 | E14: CMA fees, Big-4, legal
B15: TOTAL USES OF LP CASH | C15: =SUM(C11:C14) | D15: =C15/Assumptions!$D$17
B17: Tie-out: LP cash − uses | C17: =Assumptions!$D$17-C15 | D17: =IF(ABS(C17)<10,"BALANCED","REVIEW")
B20: POST-SETTLEMENT NAV CALCULATION
B21: Portfolio book value (gross) | C21: =Assumptions!$D$10
B22: Less: Existing debt (face) | C22: =-Assumptions!$D$30
B23: Cash freed by settlement (haircut benefit) | C23: =Assumptions!$D$33
B24: Cash to settle debt (use of LP cash) | C24: =-Assumptions!$D$32
B25: Activation capex (deployed) | C25: =Assumptions!$D$43
B26: Cash reserve | C26: =C13
B27: Setup fees (expense, written off) | C27: =-C14
B28: TOTAL NAV AT CLOSE | C28: =SUM(C21:C27)
B29: Implied LP % | C29: =Assumptions!$D$17/C28

Sheet Debt_Restructure
B2: DEBT RESTRUCTURE — Settlement Scenarios
B3: Sensitivity to settlement haircut. Base case 30% haircut frees SAR 30M of equity.
B5: Haircut | C5: 0.2 | D5: 0.25 | E5: 0.3 | F5: 0.35 | G5: 0.4
B6: Cash to settle (SAR) | C6: =Assumptions!$D$30*(1-0.2) | D6: =Assumptions!$D$30*(1-0.25) | E6: =Assumptions!$D$30*(1-0.3) | F6: =Assumptions!$D$30*(1-0.35) | G6: =Assumptions!$D$30*(1-0.4)
B7: Cash freed (equity creation) | C7: =Assumptions!$D$30*0.2 | D7: =Assumptions!$D$30*0.25 | E7: =Assumptions!$D$30*0.3 | F7: =Assumptions!$D$30*0.35 | G7: =Assumptions!$D$30*0.4
B8: LP cash earmarked | C8: =Assumptions!$D$34 | D8: =Assumptions!$D$34 | E8: =Assumptions!$D$34 | F8: =Assumptions!$D$34 | G8: =Assumptions!$D$34
B9: Sufficiency (earmark − need) | C9: =C8-C6 | D9: =D8-D6 | E9: =E8-E6 | F9: =F8-F6 | G9: =G8-G6
B10: Status | C10: =IF(C9>=0,"OK","SHORTFALL") | D10: =IF(D9>=0,"OK","SHORTFALL") | E10: =IF(E9>=0,"OK","SHORTFALL") | F10: =IF(F9>=0,"OK","SHORTFALL") | G10: =IF(G9>=0,"OK","SHORTFALL")
B13: EXECUTION RISK
B14: 1. Creditor consent required — settlement only effective if all creditors agree.
B15: 2. Acceptance probability decreases as haircut increases beyond 35%.
B16: 3. Fund will not close without binding settlement letters or LOIs.
B17: 4. Any unsettled debt remains as fund liability — adjust NAV accordingly.
B18: 5. RETT may apply on encumbered-asset transfers; legal review required.

Sheet Revenue
B2: REVENUE BUILD
B4: Year | C4: Y0 | D4: Y1 | E4: Y2 | F4: Y3 | G4: Y4 | H4: Y5
B5: Calendar year | C5: =Assumptions!$D$5 | D5: =Assumptions!$D$5+1 | E5: =Assumptions!$D$5+2 | F5: =Assumptions!$D$5+3 | G5: =Assumptions!$D$5+4 | H5: =Assumptions!$D$5+5
B7: Base rental income (existing portfolio) | C7: 0 | D7: =Assumptions!$D$11*(1+Assumptions!$D$49) | E7: =D7*(1+Assumptions!$D$49) | F7: =E7*(1+Assumptions!$D$49) | G7: =F7*(1+Assumptions!$D$49) | H7: =G7*(1+Assumptions!$D$49)
B8: Activation income (idle assets ramping) | C8: 0 | D8: =Activation!D10 | E8: =Activation!E10 | F8: =Activation!F10 | G8: =Activation!G10 | H8: =Activation!H10
B9: TOTAL GROSS RENTAL | C9: =C7+C8 | D9: =D7+D8 | E9: =E7+E8 | F9: =F7+F8 | G9: =G7+G8 | H9: =H7+H8
B10: Property OpEx (% of gross rental) | C10: =-C9*Assumptions!$D$50 | D10: =-D9*Assumptions!$D$50 | E10: =-E9*Assumptions!$D$50 | F10: =-F9*Assumptions!$D$50 | G10: =-G9*Assumptions!$D$50 | H10: =-H9*Assumptions!$D$50
B11: NOI (rental − opex) | C11: =C9+C10 | D11: =D9+D10 | E11: =E9+E10 | F11: =F9+F10 | G11: =G9+G10 | H11: =H9+H10
B13: Asset sales (non-core) | C13: 0 | D13: =Assumptions!$D$54 | E13: =Assumptions!$D$55 | F13: =Assumptions!$D$56 | G13: =Assumptions!$D$57 | H13: =Assumptions!$D$58
B14: RETT on sales (5%) | C14: 0 | D14: =-D13*Assumptions!$D$80 | E14: =-E13*Assumptions!$D$80 | F14: =-F13*Assumptions!$D$80 | G14: =-G13*Assumptions!$D$80 | H14: =-H13*Assumptions!$D$80
B15: Net sale proceeds | C15: =C13+C14 | D15: =D13+D14 | E15: =E13+E14 | F15: =F13+F14 | G15: =G13+G14 | H15: =H13+H14
B17: TOTAL REVENUE & PROCEEDS | C17: =C11+C15 | D17: =D11+D15 | E17: =E11+E15 | F17: =F11+F15 | G17: =G11+G15 | H17: =H11+H15

Sheet OpEx_Fees
B2: FUND-LEVEL EXPENSES & FEES
B4: Item | C4: Y0 | D4: Y1 | E4: Y2 | F4: Y3 | G4: Y4 | H4: Y5
B6: Manager fee (1.5% of NAV) | C6: 0 | D6: =-NAV_Trajectory!D7*Assumptions!$D$61 | E6: =-NAV_Trajectory!E7*Assumptions!$D$61 | F6: =-NAV_Trajectory!F7*Assumptions!$D$61 | G6: =-NAV_Trajectory!G7*Assumptions!$D$61 | H6: =-NAV_Trajectory!H7*Assumptions!$D$61
B7: Setup fee (1% of LP commitments, one-time) | C7: =-Assumptions!$D$17*Assumptions!$D$62 | D7: 0 | E7: 0 | F7: 0 | G7: 0 | H7: 0
B8: Custodian + audit + legal (annual) | C8: 0 | D8: =-Assumptions!$D$63*(1+Assumptions!$D$51)^0 | E8: =-Assumptions!$D$63*(1+Assumptions!$D$51)^1 | F8: =-Assumptions!$D$63*(1+Assumptions!$D$51)^2 | G8: =-Assumptions!$D$63*(1+Assumptions!$D$51)^3 | H8: =-Assumptions!$D$63*(1+Assumptions!$D$51)^4
B9: Sharia board (annual) | C9: 0 | D9: =-Assumptions!$D$64*(1+Assumptions!$D$51)^0 | E9: =-Assumptions!$D$64*(1+Assumptions!$D$51)^1 | F9: =-Assumptions!$D$64*(1+Assumptions!$D$51)^2 | G9: =-Assumptions!$D$64*(1+Assumptions!$D$51)^3 | H9: =-Assumptions!$D$64*(1+Assumptions!$D$51)^4
B10: White-land tax provision (Mecca) | C10: 0 | D10: =-Assumptions!$D$65*(1+Assumptions!$D$51)^0 | E10: =-Assumptions!$D$65*(1+Assumptions!$D$51)^1 | F10: =-Assumptions!$D$65*(1+Assumptions!$D$51)^2 | G10: =-Assumptions!$D$65*(1+Assumptions!$D$51)^3 | H10: =-Assumptions!$D$65*(1+Assumptions!$D$51)^4
B11: Zakat (on shielded NAV) | C11: 0 | D11: =-NAV_Trajectory!D7*(1-Assumptions!$D$79)*Assumptions!$D$78 | E11: =-NAV_Trajectory!E7*(1-Assumptions!$D$79)*Assumptions!$D$78 | F11: =-NAV_Trajectory!F7*(1-Assumptions!$D$79)*Assumptions!$D$78 | G11: =-NAV_Trajectory!G7*(1-Assumptions!$D$79)*Assumptions!$D$78 | H11: =-NAV_Trajectory!H7*(1-Assumptions!$D$79)*Assumptions!$D$78
B13: TOTAL FUND EXPENSES (cash out) | C13: =SUM(C6:C11) | D13: =SUM(D6:D11) | E13: =SUM(E6:E11) | F13: =SUM(F6:F11) | G13: =SUM(G6:G11) | H13: =SUM(H6:H11)

Sheet Fund_CF
B2: FUND CASH FLOW — 5-Year
B4: Line item | C4: Y0 | D4: Y1 | E4: Y2 | F4: Y3 | G4: Y4 | H4: Y5
B5: SOURCES (Y0 only)
B6: Sponsor in-kind contribution | C6: =Assumptions!$D$16
B7: LP cash commitment | C7: =Assumptions!$D$17
B9: USES (Y0 only)
B10: Cash to settle debt | C10: =-Assumptions!$D$32
B11: Activation capex (deployed) | C11: =-Assumptions!$D$43
B12: Setup fees paid | C12: =-Assumptions!$D$17*Assumptions!$D$26
B14: Net Y0 cash on B/S (reserve) | C14: =C7+C10+C11+C12
B16: OPERATING CASH FLOW
B17: Gross rental income (Revenue!9) | D17: =Revenue!D9 | E17: =Revenue!E9 | F17: =Revenue!F9 | G17: =Revenue!G9 | H17: =Revenue!H9
B18: Less: property OpEx | D18: =Revenue!D10 | E18: =Revenue!E10 | F18: =Revenue!F10 | G18: =Revenue!G10 | H18: =Revenue!H10
B19: NOI | D19: =D17+D18 | E19: =E17+E18 | F19: =F17+F18 | G19: =G17+G18 | H19: =H17+H18
B20: Less: fund expenses (mgmt + custodian + sharia + WLT + zakat) | D20: =OpEx_Fees!D13-OpEx_Fees!D7 | E20: =OpEx_Fees!E13-OpEx_Fees!E7 | F20: =OpEx_Fees!F13-OpEx_Fees!F7 | G20: =OpEx_Fees!G13-OpEx_Fees!G7 | H20: =OpEx_Fees!H13-OpEx_Fees!H7
B21: Operating cash flow | D21: =D19+D20 | E21: =E19+E20 | F21: =F19+F20 | G21: =G19+G20 | H21: =H19+H20
B23: Net asset-sale proceeds | D23: =Revenue!D15 | E23: =Revenue!E15 | F23: =Revenue!F15 | G23: =Revenue!G15 | H23: =Revenue!H15
B25: Exit value (terminal sale of remaining portfolio) | C25: 0 | D25: 0 | E25: 0 | F25: 0 | G25: 0 | H25: =NAV_Trajectory!H7*(1-Assumptions!$D$75)
B27: TOTAL FUND CASH AVAILABLE FOR DISTRIBUTION | D27: =D21+D23+D25 | E27: =E21+E23+E25 | F27: =F21+F23+F25 | G27: =G21+G23+G25 | H27: =H21+H23+H25

Sheet NAV_Trajectory
B2: NAV TRAJECTORY
B4: Period | C4: Y0 | D4: Y1 | E4: Y2 | F4: Y3 | G4: Y4 | H4: Y5
B6: Opening NAV | C6: 0 | D6: =C7 | E6: =D7 | F6: =E7 | G6: =F7 | H6: =G7
B7: Closing NAV | C7: =Sources_Uses!$C$28 | D7: =C7*(1+Assumptions!$D$74)-Revenue!D13+Activation!D10*5 | E7: =D7*(1+Assumptions!$D$74)-Revenue!E13+Activation!E10*5 | F7: =E7*(1+Assumptions!$D$74)-Revenue!F13+Activation!F10*5 | G7: =F7*(1+Assumptions!$D$74)-Revenue!G13+Activation!G10*5 | H7: =G7*(1+Assumptions!$D$74)-Revenue!H13+Activation!H10*5
B9: NAV growth (YoY) | D9: =IFERROR(D7/C7-1,0) | E9: =IFERROR(E7/D7-1,0) | F9: =IFERROR(F7/E7-1,0) | G9: =IFERROR(G7/F7-1,0) | H9: =IFERROR(H7/G7-1,0)

Sheet Waterfall
B2: DISTRIBUTION WATERFALL — European (LP-friendly)
B3: Tier 1: return of LP capital. Tier 2: 8% LP preferred return. Tier 3: GP catch-up to 20%. Tier 4: 80/20 split.
B5: Period | C5: Y0 | D5: Y1 | E5: Y2 | F5: Y3 | G5: Y4 | H5: Y5
B7: Cash available for distribution (from Fund_CF) | C7: 0 | D7: =Fund_CF!D27 | E7: =Fund_CF!E27 | F7: =Fund_CF!F27 | G7: =Fund_CF!G27 | H7: =Fund_CF!H27
B9: TIER 1: Return of LP capital
B10: Unreturned LP capital (period-start) | C10: =Assumptions!$D$17 | D10: =MAX(0,C10-C11) | E10: =MAX(0,D10-D11) | F10: =MAX(0,E10-E11) | G10: =MAX(0,F10-F11) | H10: =MAX(0,G10-G11)
B11: Capital returned this period | C11: 0
B12: Pref accrual on outstanding capital (8%) | C12: 0 | D12: =D10*Assumptions!$D$68 | E12: =E10*Assumptions!$D$68 | F12: =F10*Assumptions!$D$68 | G12: =G10*Assumptions!$D$68 | H12: =H10*Assumptions!$D$68
B13: Pref deficit carry-forward (cumulative) | C13: 0 | D13: =MAX(0,C13+D12-D14) | E13: =MAX(0,D13+E12-E14) | F13: =MAX(0,E13+F12-F14) | G13: =MAX(0,F13+G12-G14) | H13: =MAX(0,G13+H12-H14)
B14: Pref paid to LP this period | C14: 0 | D14: =MIN(D7,D12+C13) | E14: =MIN(E7,E12+D13) | F14: =MIN(F7,F12+E13) | G14: =MIN(G7,G12+F13) | H14: =MIN(H7,H12+G13)
B16: Cash remaining after pref | C16: 0 | D16: =MAX(0,D7-D14) | E16: =MAX(0,E7-E14) | F16: =MAX(0,F7-F14) | G16: =MAX(0,G7-G14) | H16: =MAX(0,H7-H14)
B18: TIER 3 (catch-up) + TIER 4 (80/20)
B19: GP catch-up + carry (20% of cash above pref + capital return) | C19: 0 | D19: =D16*Assumptions!$D$69 | E19: =E16*Assumptions!$D$69 | F19: =F16*Assumptions!$D$69 | G19: =G16*Assumptions!$D$69 | H19: =MAX(0,(H16-H10-Assumptions!$D$16)*Assumptions!$D$69)
B20: LP 80% of upside (after pref + carry) | C20: 0 | D20: =D16*(1-Assumptions!$D$69) | E20: =E16*(1-Assumptions!$D$69) | F20: =F16*(1-Assumptions!$D$69) | G20: =G16*(1-Assumptions!$D$69) | H20: =H10+MAX(0,(H16-H10-Assumptions!$D$16)*(1-Assumptions!$D$69))
B21: Sponsor capital returned (at exit) | D21: 0 | E21: 0 | F21: 0 | G21: 0 | H21: =MIN(MAX(0,H16-H10),Assumptions!$D$16)
B22: TOTAL TO LP THIS PERIOD | C22: =-Assumptions!$D$17 | D22: =D14+D20 | E22: =E14+E20 | F22: =F14+F20 | G22: =G14+G20 | H22: =H14+H20
B23: TOTAL TO GP THIS PERIOD | C23: 0 | D23: =D19+D21 | E23: =E19+E21 | F23: =F19+F21 | G23: =G19+G21 | H23: =H19+H21
B24: of which: sponsor capital recovery | D24: 0 | E24: 0 | F24: 0 | G24: 0 | H24: =H21
B25: of which: GP carry | C25: 0 | D25: =D19 | E25: =E19 | F25: =F19 | G25: =G19 | H25: =H19
B26: Tie-out (Cash − LP − GP/Sponsor) | D26: =D7-D22-D23 | E26: =E7-E22-E23 | F26: =F7-F22-F23 | G26: =G7-G22-G23 | H26: =H7-H22-H23

Sheet LP_Returns
B2: LP RETURN METRICS
B4: Year | C4: Y0 | D4: Y1 | E4: Y2 | F4: Y3 | G4: Y4 | H4: Y5
B5: LP cash flow (Y0 outflow, then distributions) | C5: =-Assumptions!$D$17 | D5: =Waterfall!D22 | E5: =Waterfall!E22 | F5: =Waterfall!F22 | G5: =Waterfall!G22 | H5: =Waterfall!H22
B6: Cumulative LP cash flow | C6: =C5 | D6: =C6+D5 | E6: =D6+E5 | F6: =E6+F5 | G6: =F6+G5 | H6: =G6+H5
B8: HEADLINE LP METRICS
B9: LP commitment (SAR) | C9: =Assumptions!$D$17
B10: Total LP distributions (cum.) | C10: =SUM(D5:H5)
B11: LP MOIC | C11: =C10/C9
B12: LP IRR (5-yr cash flow stream) | C12: =IFERROR(IRR(C5:H5),0)
B13: LP NPV @ Ke (13%) | C13: =C5+NPV(Assumptions!$D$84,D5:H5)
B14: Distributions ratio (cum. dist / LP capital) | C14: =(C10-C9)/C9
B15: Cash-on-Cash Y2 (LP dist Y2 / LP capital) | C15: =E5/C9
B16: Cash-on-Cash Y3 (LP dist Y3 / LP capital) | C16: =F5/C9
B18: VS TARGETS (per IM Table 4)
B19: IRR target 12–15% | C19: =IF(C12>=0.12,IF(C12>=0.15,"EXCEEDS TARGET","ON TARGET"),"BELOW TARGET")
B20: MOIC target 1.7–2.0x | C20: =IF(C11>=1.7,IF(C11>=2.0,"EXCEEDS TARGET","ON TARGET"),"BELOW TARGET")
B21: Cash-on-Cash target 6–8% (Y2+) | C21: =IF(AVERAGE(C15:C16)>=0.06,IF(AVERAGE(C15:C16)>=0.08,"EXCEEDS TARGET","ON TARGET"),"BELOW TARGET")

Sheet GP_Economics
B2: GP / SPONSOR ECONOMICS
B4: Year | C4: Y0 | D4: Y1 | E4: Y2 | F4: Y3 | G4: Y4 | H4: Y5
B5: Management fee (1.5% NAV) | C5: 0 | D5: =-OpEx_Fees!D6 | E5: =-OpEx_Fees!E6 | F5: =-OpEx_Fees!F6 | G5: =-OpEx_Fees!G6 | H5: =-OpEx_Fees!H6
B6: GP carry (from Waterfall) | C6: 0 | D6: =Waterfall!D23 | E6: =Waterfall!E23 | F6: =Waterfall!F23 | G6: =Waterfall!G23 | H6: =Waterfall!H23
B7: Sponsor in-kind contribution (initial) | C7: =Assumptions!$D$16
B9: Total GP cash earned (mgmt fees + carry) | C9: =SUM(C5:H5)+SUM(C6:H6)
B10: Sponsor exit recovery (in-kind capital + share of upside) | C10: =Waterfall!H21
B11: Sponsor MOIC | C11: =(C10+SUM(C5:H5)+SUM(C6:H6))/Assumptions!$D$16

Sheet Stress_Tests
B2: STRESS TESTS — 5-Case Sensitivity (analytic proxies)
B4: Metric | C4: Base | D4: Downside | E4: Severe | F4: Stress | G4: Upside
B6: SHOCK INPUTS
B7: Debt settlement haircut | C7: 0.3 | D7: 0.2 | E7: 0.15 | F7: 0.1 | G7: 0.35
B8: Hotel income loss (%) | C8: 0 | D8: 0.2 | E8: 0.5 | F8: 0.8 | G8: 0
B9: Mecca regulation/expropriation (%) | C9: 0 | D9: 0.1 | E9: 0.25 | F9: 0.5 | G9: 0
B10: Activation delay (years) | C10: 0 | D10: 1 | E10: 2 | F10: 3 | G10: 0
B11: Asset appreciation (% p.a.) | C11: 0.03 | D11: 0.01 | E11: -0.02 | F11: -0.05 | G11: 0.05
B12: Exit cap rate shift (bps) | C12: 0 | D12: 50 | E12: 150 | F12: 300 | G12: -25
B13: Operating cost overrun (%) | C13: 0 | D13: 0.1 | E13: 0.25 | F13: 0.5 | G13: -0.05
B15: STRESSED OUTPUTS (analytic)
B16: Stressed Y2 NOI (SAR M) | C16: =Revenue!E11*(1-C7*0.41)*(1-C12*0.2)/1000000 | D16: =Revenue!E11*(1-D7*0.41)*(1-D12*0.2)/1000000 | E16: =Revenue!E11*(1-E7*0.41)*(1-E12*0.2)/1000000 | F16: =Revenue!E11*(1-F7*0.41)*(1-F12*0.2)/1000000 | G16: =Revenue!E11*(1-G7*0.41)*(1-G12*0.2)/1000000
B17: Stressed LP IRR (proxy) | C17: =LP_Returns!$C$12*(1-C7*0.5-C8*0.7)+(C10-Assumptions!$D$74)-C11/10000 | D17: =LP_Returns!$C$12*(1-D7*0.5-D8*0.7)+(D10-Assumptions!$D$74)-D11/10000 | E17: =LP_Returns!$C$12*(1-E7*0.5-E8*0.7)+(E10-Assumptions!$D$74)-E11/10000 | F17: =LP_Returns!$C$12*(1-F7*0.5-F8*0.7)+(F10-Assumptions!$D$74)-F11/10000 | G17: =LP_Returns!$C$12*(1-G7*0.5-G8*0.7)+(G10-Assumptions!$D$74)-G11/10000
B18: Stressed LP MOIC (proxy) | C18: =LP_Returns!$C$11*(1-C7*0.4-C8*0.5)+(C10-Assumptions!$D$74)*5 | D18: =LP_Returns!$C$11*(1-D7*0.4-D8*0.5)+(D10-Assumptions!$D$74)*5 | E18: =LP_Returns!$C$11*(1-E7*0.4-E8*0.5)+(E10-Assumptions!$D$74)*5 | F18: =LP_Returns!$C$11*(1-F7*0.4-F8*0.5)+(F10-Assumptions!$D$74)*5 | G18: =LP_Returns!$C$11*(1-G7*0.4-G8*0.5)+(G10-Assumptions!$D$74)*5
B20: Investment verdict | C20: =IF(AND(C18>=0.12,C19>=1.7),"INVESTABLE",IF(C18>=0.08,"MARGINAL","REJECT")) | D20: =IF(AND(D18>=0.12,D19>=1.7),"INVESTABLE",IF(D18>=0.08,"MARGINAL","REJECT")) | E20: =IF(AND(E18>=0.12,E19>=1.7),"INVESTABLE",IF(E18>=0.08,"MARGINAL","REJECT")) | F20: =IF(AND(F18>=0.12,F19>=1.7),"INVESTABLE",IF(F18>=0.08,"MARGINAL","REJECT")) | G20: =IF(AND(G18>=0.12,G19>=1.7),"INVESTABLE",IF(G18>=0.08,"MARGINAL","REJECT"))

Sheet Sensitivity
B2: TWO-WAY SENSITIVITY MATRICES
B5: MATRIX 1: LP IRR vs (Debt haircut, LP commitment)
B7: Haircut \ LP commitment | C7: 100000000 | D7: 110000000 | E7: 115000000 | F7: 125000000 | G7: 130000000
B8: 0.2 | C8: =LP_Returns!$C$12*(1+(0.2-Assumptions!$D$31)*0.5)*Assumptions!$D$17/100000000 | D8: =LP_Returns!$C$12*(1+(0.2-Assumptions!$D$31)*0.5)*Assumptions!$D$17/110000000 | E8: =LP_Returns!$C$12*(1+(0.2-Assumptions!$D$31)*0.5)*Assumptions!$D$17/115000000 | F8: =LP_Returns!$C$12*(1+(0.2-Assumptions!$D$31)*0.5)*Assumptions!$D$17/125000000 | G8: =LP_Returns!$C$12*(1+(0.2-Assumptions!$D$31)*0.5)*Assumptions!$D$17/130000000
B9: 0.25 | C9: =LP_Returns!$C$12*(1+(0.25-Assumptions!$D$31)*0.5)*Assumptions!$D$17/100000000 | D9: =LP_Returns!$C$12*(1+(0.25-Assumptions!$D$31)*0.5)*Assumptions!$D$17/110000000 | E9: =LP_Returns!$C$12*(1+(0.25-Assumptions!$D$31)*0.5)*Assumptions!$D$17/115000000 | F9: =LP_Returns!$C$12*(1+(0.25-Assumptions!$D$31)*0.5)*Assumptions!$D$17/125000000 | G9: =LP_Returns!$C$12*(1+(0.25-Assumptions!$D$31)*0.5)*Assumptions!$D$17/130000000
B10: 0.3 | C10: =LP_Returns!$C$12*(1+(0.3-Assumptions!$D$31)*0.5)*Assumptions!$D$17/100000000 | D10: =LP_Returns!$C$12*(1+(0.3-Assumptions!$D$31)*0.5)*Assumptions!$D$17/110000000 | E10: =LP_Returns!$C$12*(1+(0.3-Assumptions!$D$31)*0.5)*Assumptions!$D$17/115000000 | F10: =LP_Returns!$C$12*(1+(0.3-Assumptions!$D$31)*0.5)*Assumptions!$D$17/125000000 | G10: =LP_Returns!$C$12*(1+(0.3-Assumptions!$D$31)*0.5)*Assumptions!$D$17/130000000
B11: 0.35 | C11: =LP_Returns!$C$12*(1+(0.35-Assumptions!$D$31)*0.5)*Assumptions!$D$17/100000000 | D11: =LP_Returns!$C$12*(1+(0.35-Assumptions!$D$31)*0.5)*Assumptions!$D$17/110000000 | E11: =LP_Returns!$C$12*(1+(0.35-Assumptions!$D$31)*0.5)*Assumptions!$D$17/115000000 | F11: =LP_Returns!$C$12*(1+(0.35-Assumptions!$D$31)*0.5)*Assumptions!$D$17/125000000 | G11: =LP_Returns!$C$12*(1+(0.35-Assumptions!$D$31)*0.5)*Assumptions!$D$17/130000000
B12: 0.4 | C12: =LP_Returns!$C$12*(1+(0.4-Assumptions!$D$31)*0.5)*Assumptions!$D$17/100000000 | D12: =LP_Returns!$C$12*(1+(0.4-Assumptions!$D$31)*0.5)*Assumptions!$D$17/110000000 | E12: =LP_Returns!$C$12*(1+(0.4-Assumptions!$D$31)*0.5)*Assumptions!$D$17/115000000 | F12: =LP_Returns!$C$12*(1+(0.4-Assumptions!$D$31)*0.5)*Assumptions!$D$17/125000000 | G12: =LP_Returns!$C$12*(1+(0.4-Assumptions!$D$31)*0.5)*Assumptions!$D$17/130000000
B16: MATRIX 2: LP MOIC vs (Activation success %, Exit cap)
B18: Activation \ Exit cap | C18: 0.06 | D18: 0.065 | E18: 0.07 | F18: 0.075 | G18: 0.08 | H18: 0.085
B19: 0.4 | C19: =LP_Returns!$C$11*(1+(0.4-1)*0.15)*Assumptions!$D$73/0.06 | D19: =LP_Returns!$C$11*(1+(0.4-1)*0.15)*Assumptions!$D$73/0.065 | E19: =LP_Returns!$C$11*(1+(0.4-1)*0.15)*Assumptions!$D$73/0.07 | F19: =LP_Returns!$C$11*(1+(0.4-1)*0.15)*Assumptions!$D$73/0.075 | G19: =LP_Returns!$C$11*(1+(0.4-1)*0.15)*Assumptions!$D$73/0.08 | H19: =LP_Returns!$C$11*(1+(0.4-1)*0.15)*Assumptions!$D$73/0.085
B20: 0.6 | C20: =LP_Returns!$C$11*(1+(0.6-1)*0.15)*Assumptions!$D$73/0.06 | D20: =LP_Returns!$C$11*(1+(0.6-1)*0.15)*Assumptions!$D$73/0.065 | E20: =LP_Returns!$C$11*(1+(0.6-1)*0.15)*Assumptions!$D$73/0.07 | F20: =LP_Returns!$C$11*(1+(0.6-1)*0.15)*Assumptions!$D$73/0.075 | G20: =LP_Returns!$C$11*(1+(0.6-1)*0.15)*Assumptions!$D$73/0.08 | H20: =LP_Returns!$C$11*(1+(0.6-1)*0.15)*Assumptions!$D$73/0.085
B21: 0.8 | C21: =LP_Returns!$C$11*(1+(0.8-1)*0.15)*Assumptions!$D$73/0.06 | D21: =LP_Returns!$C$11*(1+(0.8-1)*0.15)*Assumptions!$D$73/0.065 | E21: =LP_Returns!$C$11*(1+(0.8-1)*0.15)*Assumptions!$D$73/0.07 | F21: =LP_Returns!$C$11*(1+(0.8-1)*0.15)*Assumptions!$D$73/0.075 | G21: =LP_Returns!$C$11*(1+(0.8-1)*0.15)*Assumptions!$D$73/0.08 | H21: =LP_Returns!$C$11*(1+(0.8-1)*0.15)*Assumptions!$D$73/0.085
B22: 1 | C22: =LP_Returns!$C$11*(1+(1.0-1)*0.15)*Assumptions!$D$73/0.06 | D22: =LP_Returns!$C$11*(1+(1.0-1)*0.15)*Assumptions!$D$73/0.065 | E22: =LP_Returns!$C$11*(1+(1.0-1)*0.15)*Assumptions!$D$73/0.07 | F22: =LP_Returns!$C$11*(1+(1.0-1)*0.15)*Assumptions!$D$73/0.075 | G22: =LP_Returns!$C$11*(1+(1.0-1)*0.15)*Assumptions!$D$73/0.08 | H22: =LP_Returns!$C$11*(1+(1.0-1)*0.15)*Assumptions!$D$73/0.085
B23: 1.2 | C23: =LP_Returns!$C$11*(1+(1.2-1)*0.15)*Assumptions!$D$73/0.06 | D23: =LP_Returns!$C$11*(1+(1.2-1)*0.15)*Assumptions!$D$73/0.065 | E23: =LP_Returns!$C$11*(1+(1.2-1)*0.15)*Assumptions!$D$73/0.07 | F23: =LP_Returns!$C$11*(1+(1.2-1)*0.15)*Assumptions!$D$73/0.075 | G23: =LP_Returns!$C$11*(1+(1.2-1)*0.15)*Assumptions!$D$73/0.08 | H23: =LP_Returns!$C$11*(1+(1.2-1)*0.15)*Assumptions!$D$73/0.085

Sheet Risk_Disclosure
B2: RISK DISCLOSURES — Per Information Memorandum §8
B3: All risks below apply to LP investment in the fund. Read in conjunction with final fund documents and Sharia board pronouncement.
B5: 8.1 RESTRUCTURING RISKS
B6: • Settlement failure: if any creditor rejects the negotiated settlement, the debt-clearance mechanism breaks down. The fund will not close without binding LOIs / settlement agreements from all material creditors.
B7: • Concurrent enforcement: if any court issues an enforcement order before fund closing, assets earmarked for the fund may be frozen. The fund will only accept assets free of liens.
B8: • Personal guarantees: if the sponsor's personal guarantees are linked to portfolio assets, claims may arise during or after transfer. Full legal due diligence required.
B10: 8.2 ASSET-SPECIFIC RISKS
B11: • Geographic concentration: >60% of portfolio value sits in Mecca. Exposure to local regulatory changes, expansion of Holy Mosque area, expropriation for major projects.
B12: • Income concentration: Al-Hafayer Hotel generates 41% of total rental income. Any disruption (renewal terms, tenant default, hotel closure) materially impacts distributions.
B13: • Stale valuations: RE-001 (largest asset) valuation dates to 2017. Six properties lack updated appraisals.
B14: • Vacant land tax: white-land tax in Mecca may impose annual costs in the low millions of SAR.
B16: 8.3 MARKET & ECONOMIC RISKS
... B38: • Mixed income (where applicable) subject to annual purification per Sharia board.

Sheet IC_Memo
B2: INVESTMENT COMMITTEE MEMO — Bin Amer Real Estate Fund v6.0
B3: Prepared for: LP Investment Committee
B4: Status: For qualified-investor discussion only — non-binding
B6: 1. EXECUTIVE RECOMMENDATION
B7: PROCEED TO DUE DILIGENCE — subject to verification of the 7 conditions in §6.
B8: The proposed structure is institutionally credible: an unleveraged 5-year closed-end private RE fund, sponsor-aligned via in-kind contribution, with a clear use-of-proceeds (60% debt settle / 25% activation / 15% reserves & setup). Pre-DD targets (LP IRR 12–15%, MOIC 1.7–2.0x, Cash-on-Cash 6–8%) are achievable IF the 30% creditor haircut is binding and activation timeline holds.
B10: 2. DEAL HIGHLIGHTS
B11: • Fund size SAR 230–300M; sponsor contributes assets net of debt (SAR 130–170M); LPs commit SAR 100–130M cash.
B12: • 29-property portfolio includes income-stable anchors (hotel, warehouses, gas stations) + activation upside (4 idle assets, ~SAR 2.8M/yr potential).
B13: • Negotiated debt settlement at 30% haircut creates ~SAR 30M of equity value for the fund at closing.
B14: • Unleveraged at fund level — no refinancing risk; LLCR/PLCR not applicable.
B15: • European waterfall with 8% LP pref + GP catch-up + 80/20 carry.
... B52: Recommendation: PROCEED TO DUE DILIGENCE subject to the 7 conditions in §6. Conditional LP commitment subject to final fund documents and Sharia approval.

Sheet Audit
B2: MODEL INTEGRITY CHECKS
B3: All checks must return OK before model is used for IC.
B5: Check | C5: Expected | D5: Actual | E5: Status
B6: Sources = Uses (S&U tie-out) | C6: =Sources_Uses!$C$8 | D6: =Assumptions!$D$17+Assumptions!$D$16 | E6: =IF(ABS(D6-C6)<10,"OK","REVIEW")
B7: LP cash used = LP cash committed | C7: =Assumptions!$D$17 | D7: =Sources_Uses!$C$15 | E7: =IF(ABS(D7-C7)<10,"OK","REVIEW")
B8: Total use shares sum to 100% | C8: =1 | D8: =Assumptions!$D$27 | E8: =IF(ABS(D8-C8)<0.005,"OK","REVIEW")
B9: Debt settlement sufficient (LP earmark ≥ need) | C9: "OK" | D9: =IF(Assumptions!$D$35>=0,"OK","SHORTFALL") | E9: =D9
B10: Portfolio value matches IM (SAR 242.4M ± 1M) | C10: =242413692 | D10: =Assumptions!$D$10 | E10: =IF(ABS(D10-C10)<1000000,"OK","REVIEW")
B11: Current rental matches IM (SAR 9.82M ± 100K) | C11: =9817600 | D11: =Assumptions!$D$11 | E11: =IF(ABS(D11-C11)<100000,"OK","REVIEW")
B12: LP MOIC ≥ target 1.7x | C12: =1.7 | D12: =LP_Returns!$C$11 | E12: =IF(D12>=C12,"OK","BELOW TARGET")
B13: LP IRR ≥ target 12% | C13: =0.12 | D13: =LP_Returns!$C$12 | E13: =IF(D13>=C13,"OK","BELOW TARGET")
B14: Fund unleveraged at fund level (no senior debt) | C14: "NO DEBT" | D14: "NO DEBT" | E14: "OK"
B15: Waterfall ties (LP+GP = cash distributed) | C15: =Waterfall!$H$7 | D15: =Waterfall!$H$22+Waterfall!$H$23 | E15: =IF(ABS(D15-C15)<10,"OK","REVIEW")
B16: Hotel income concentration (≤ 50%) | C16: =0.50 | D16: =4000000/Assumptions!$D$11 | E16: =IF(D16<=C16,"OK","CONCENTRATION RISK")
B17: Mecca exposure (memo only) | C17: ≥ 60% | D17: ">60%" | E17: "NOTE"
B21: AUDIT SUMMARY
B22: Total OK | C22: =COUNTIF(E6:E20,"OK")
B23: Total REVIEW | C23: =COUNTIF(E6:E20,"REVIEW")+COUNTIF(E6:E20,"BELOW TARGET")+COUNTIF(E6:E20,"CONCENTRATION RISK")
B24: Total ERROR (shortfall) | C24: =COUNTIF(E6:E20,"SHORTFALL")
